2023-01-26 12:10:28,704 - log - ERROR - (sqlite3.IntegrityError) UNIQUE constraint failed: incoming_request.message_id
[SQL: INSERT INTO incoming_request (status, timestamp, recipient_id, conversation_id, message_id, expiration_timestamp, origin, billable, pricing_model, processed) VALUES (?, ?, ?, ?, ?, ?, ?, ?, ?, ?)]
[parameters: ('sent', '1674215955', '254741590330', '34802039ee38338fccfd79f9d0f235da', 'wamid.HBgMMjU0NzQxNTkwMzMwFQIAERgSN0U5MkMwNTcyMkY4MTlCMzU1AA==', None, 'user_initiated', True, 'CBP', 0)]
(Background on this error at: https://sqlalche.me/e/14/gkpj)
Traceback (most recent call last):
  File "/home/newton/elarian/virtual/lib/python3.8/site-packages/sqlalchemy/engine/base.py", line 1900, in _execute_context
    self.dialect.do_execute(
  File "/home/newton/elarian/virtual/lib/python3.8/site-packages/sqlalchemy/engine/default.py", line 736, in do_execute
    cursor.execute(statement, parameters)
sqlite3.IntegrityError: UNIQUE constraint failed: incoming_request.message_id

The above exception was the direct cause of the following exception:

Traceback (most recent call last):
  File "application.py", line 78, in save_request
    db.session.commit()
  File "<string>", line 2, in commit
  File "/home/newton/elarian/virtual/lib/python3.8/site-packages/sqlalchemy/orm/session.py", line 1451, in commit
    self._transaction.commit(_to_root=self.future)
  File "/home/newton/elarian/virtual/lib/python3.8/site-packages/sqlalchemy/orm/session.py", line 829, in commit
    self._prepare_impl()
  File "/home/newton/elarian/virtual/lib/python3.8/site-packages/sqlalchemy/orm/session.py", line 808, in _prepare_impl
    self.session.flush()
  File "/home/newton/elarian/virtual/lib/python3.8/site-packages/sqlalchemy/orm/session.py", line 3444, in flush
    self._flush(objects)
  File "/home/newton/elarian/virtual/lib/python3.8/site-packages/sqlalchemy/orm/session.py", line 3584, in _flush
    transaction.rollback(_capture_exception=True)
  File "/home/newton/elarian/virtual/lib/python3.8/site-packages/sqlalchemy/util/langhelpers.py", line 70, in __exit__
    compat.raise_(
  File "/home/newton/elarian/virtual/lib/python3.8/site-packages/sqlalchemy/util/compat.py", line 211, in raise_
    raise exception
  File "/home/newton/elarian/virtual/lib/python3.8/site-packages/sqlalchemy/orm/session.py", line 3544, in _flush
    flush_context.execute()
  File "/home/newton/elarian/virtual/lib/python3.8/site-packages/sqlalchemy/orm/unitofwork.py", line 456, in execute
    rec.execute(self)
  File "/home/newton/elarian/virtual/lib/python3.8/site-packages/sqlalchemy/orm/unitofwork.py", line 630, in execute
    util.preloaded.orm_persistence.save_obj(
  File "/home/newton/elarian/virtual/lib/python3.8/site-packages/sqlalchemy/orm/persistence.py", line 245, in save_obj
    _emit_insert_statements(
  File "/home/newton/elarian/virtual/lib/python3.8/site-packages/sqlalchemy/orm/persistence.py", line 1238, in _emit_insert_statements
    result = connection._execute_20(
  File "/home/newton/elarian/virtual/lib/python3.8/site-packages/sqlalchemy/engine/base.py", line 1705, in _execute_20
    return meth(self, args_10style, kwargs_10style, execution_options)
  File "/home/newton/elarian/virtual/lib/python3.8/site-packages/sqlalchemy/sql/elements.py", line 334, in _execute_on_connection
    return connection._execute_clauseelement(
  File "/home/newton/elarian/virtual/lib/python3.8/site-packages/sqlalchemy/engine/base.py", line 1572, in _execute_clauseelement
    ret = self._execute_context(
  File "/home/newton/elarian/virtual/lib/python3.8/site-packages/sqlalchemy/engine/base.py", line 1943, in _execute_context
    self._handle_dbapi_exception(
  File "/home/newton/elarian/virtual/lib/python3.8/site-packages/sqlalchemy/engine/base.py", line 2124, in _handle_dbapi_exception
    util.raise_(
  File "/home/newton/elarian/virtual/lib/python3.8/site-packages/sqlalchemy/util/compat.py", line 211, in raise_
    raise exception
  File "/home/newton/elarian/virtual/lib/python3.8/site-packages/sqlalchemy/engine/base.py", line 1900, in _execute_context
    self.dialect.do_execute(
  File "/home/newton/elarian/virtual/lib/python3.8/site-packages/sqlalchemy/engine/default.py", line 736, in do_execute
    cursor.execute(statement, parameters)
sqlalchemy.exc.IntegrityError: (sqlite3.IntegrityError) UNIQUE constraint failed: incoming_request.message_id
[SQL: INSERT INTO incoming_request (status, timestamp, recipient_id, conversation_id, message_id, expiration_timestamp, origin, billable, pricing_model, processed) VALUES (?, ?, ?, ?, ?, ?, ?, ?, ?, ?)]
[parameters: ('sent', '1674215955', '254741590330', '34802039ee38338fccfd79f9d0f235da', 'wamid.HBgMMjU0NzQxNTkwMzMwFQIAERgSN0U5MkMwNTcyMkY4MTlCMzU1AA==', None, 'user_initiated', True, 'CBP', 0)]
(Background on this error at: https://sqlalche.me/e/14/gkpj)
2023-01-26 12:24:32,404 - log - ERROR - 'NoneType' object has no attribute 'processed'
Traceback (most recent call last):
  File "application.py", line 173, in heyoo
    processed_message.processed = True
AttributeError: 'NoneType' object has no attribute 'processed'
2023-01-26 12:24:36,526 - log - ERROR - 'NoneType' object has no attribute 'processed'
Traceback (most recent call last):
  File "application.py", line 173, in heyoo
    processed_message.processed = True
AttributeError: 'NoneType' object has no attribute 'processed'
2023-01-26 12:25:01,301 - log - ERROR - 'NoneType' object has no attribute 'processed'
Traceback (most recent call last):
  File "application.py", line 173, in heyoo
    processed_message.processed = True
AttributeError: 'NoneType' object has no attribute 'processed'
2023-01-26 12:25:26,258 - log - ERROR - 'NoneType' object has no attribute 'processed'
Traceback (most recent call last):
  File "application.py", line 173, in heyoo
    processed_message = IncomingRequest.query.filter_by(message_id=message_id,  processed=False).first()
AttributeError: 'NoneType' object has no attribute 'processed'
2023-01-26 12:25:37,356 - log - ERROR - (sqlite3.IntegrityError) UNIQUE constraint failed: incoming_request.message_id
[SQL: INSERT INTO incoming_request (status, timestamp, recipient_id, conversation_id, message_id, expiration_timestamp, origin, billable, pricing_model, processed) VALUES (?, ?, ?, ?, ?, ?, ?, ?, ?, ?)]
[parameters: ('sent', '1674567598', '254741590330', '6ede77e9eb0eb7dbcf33dc6011e5ccf3', 'wamid.HBgMMjU0NzQxNTkwMzMwFQIAERgSMEEzQURBQzI2NTUwMjE2MjU3AA==', None, 'user_initiated', True, 'CBP', 0)]
(Background on this error at: https://sqlalche.me/e/14/gkpj)
Traceback (most recent call last):
  File "/home/newton/elarian/virtual/lib/python3.8/site-packages/sqlalchemy/engine/base.py", line 1900, in _execute_context
    self.dialect.do_execute(
  File "/home/newton/elarian/virtual/lib/python3.8/site-packages/sqlalchemy/engine/default.py", line 736, in do_execute
    cursor.execute(statement, parameters)
sqlite3.IntegrityError: UNIQUE constraint failed: incoming_request.message_id

The above exception was the direct cause of the following exception:

Traceback (most recent call last):
  File "application.py", line 78, in save_request
    db.session.commit()
  File "<string>", line 2, in commit
  File "/home/newton/elarian/virtual/lib/python3.8/site-packages/sqlalchemy/orm/session.py", line 1451, in commit
    self._transaction.commit(_to_root=self.future)
  File "/home/newton/elarian/virtual/lib/python3.8/site-packages/sqlalchemy/orm/session.py", line 829, in commit
    self._prepare_impl()
  File "/home/newton/elarian/virtual/lib/python3.8/site-packages/sqlalchemy/orm/session.py", line 808, in _prepare_impl
    self.session.flush()
  File "/home/newton/elarian/virtual/lib/python3.8/site-packages/sqlalchemy/orm/session.py", line 3444, in flush
    self._flush(objects)
  File "/home/newton/elarian/virtual/lib/python3.8/site-packages/sqlalchemy/orm/session.py", line 3584, in _flush
    transaction.rollback(_capture_exception=True)
  File "/home/newton/elarian/virtual/lib/python3.8/site-packages/sqlalchemy/util/langhelpers.py", line 70, in __exit__
    compat.raise_(
  File "/home/newton/elarian/virtual/lib/python3.8/site-packages/sqlalchemy/util/compat.py", line 211, in raise_
    raise exception
  File "/home/newton/elarian/virtual/lib/python3.8/site-packages/sqlalchemy/orm/session.py", line 3544, in _flush
    flush_context.execute()
  File "/home/newton/elarian/virtual/lib/python3.8/site-packages/sqlalchemy/orm/unitofwork.py", line 456, in execute
    rec.execute(self)
  File "/home/newton/elarian/virtual/lib/python3.8/site-packages/sqlalchemy/orm/unitofwork.py", line 630, in execute
    util.preloaded.orm_persistence.save_obj(
  File "/home/newton/elarian/virtual/lib/python3.8/site-packages/sqlalchemy/orm/persistence.py", line 245, in save_obj
    _emit_insert_statements(
  File "/home/newton/elarian/virtual/lib/python3.8/site-packages/sqlalchemy/orm/persistence.py", line 1238, in _emit_insert_statements
    result = connection._execute_20(
  File "/home/newton/elarian/virtual/lib/python3.8/site-packages/sqlalchemy/engine/base.py", line 1705, in _execute_20
    return meth(self, args_10style, kwargs_10style, execution_options)
  File "/home/newton/elarian/virtual/lib/python3.8/site-packages/sqlalchemy/sql/elements.py", line 334, in _execute_on_connection
    return connection._execute_clauseelement(
  File "/home/newton/elarian/virtual/lib/python3.8/site-packages/sqlalchemy/engine/base.py", line 1572, in _execute_clauseelement
    ret = self._execute_context(
  File "/home/newton/elarian/virtual/lib/python3.8/site-packages/sqlalchemy/engine/base.py", line 1943, in _execute_context
    self._handle_dbapi_exception(
  File "/home/newton/elarian/virtual/lib/python3.8/site-packages/sqlalchemy/engine/base.py", line 2124, in _handle_dbapi_exception
    util.raise_(
  File "/home/newton/elarian/virtual/lib/python3.8/site-packages/sqlalchemy/util/compat.py", line 211, in raise_
    raise exception
  File "/home/newton/elarian/virtual/lib/python3.8/site-packages/sqlalchemy/engine/base.py", line 1900, in _execute_context
    self.dialect.do_execute(
  File "/home/newton/elarian/virtual/lib/python3.8/site-packages/sqlalchemy/engine/default.py", line 736, in do_execute
    cursor.execute(statement, parameters)
sqlalchemy.exc.IntegrityError: (sqlite3.IntegrityError) UNIQUE constraint failed: incoming_request.message_id
[SQL: INSERT INTO incoming_request (status, timestamp, recipient_id, conversation_id, message_id, expiration_timestamp, origin, billable, pricing_model, processed) VALUES (?, ?, ?, ?, ?, ?, ?, ?, ?, ?)]
[parameters: ('sent', '1674567598', '254741590330', '6ede77e9eb0eb7dbcf33dc6011e5ccf3', 'wamid.HBgMMjU0NzQxNTkwMzMwFQIAERgSMEEzQURBQzI2NTUwMjE2MjU3AA==', None, 'user_initiated', True, 'CBP', 0)]
(Background on this error at: https://sqlalche.me/e/14/gkpj)
2023-01-26 12:26:22,048 - log - ERROR - 'NoneType' object has no attribute 'processed'
Traceback (most recent call last):
  File "application.py", line 173, in heyoo
    processed_message = IncomingRequest.query.filter_by(message_id=message_id,  processed=False).first()
AttributeError: 'NoneType' object has no attribute 'processed'
2023-01-26 12:26:46,857 - log - ERROR - (sqlite3.IntegrityError) UNIQUE constraint failed: incoming_request.message_id
[SQL: INSERT INTO incoming_request (status, timestamp, recipient_id, conversation_id, message_id, expiration_timestamp, origin, billable, pricing_model, processed) VALUES (?, ?, ?, ?, ?, ?, ?, ?, ?, ?)]
[parameters: ('read', '1674208259', '254741590330', '34802039ee38338fccfd79f9d0f235da', 'wamid.HBgMMjU0NzQxNTkwMzMwFQIAERgSOTgyQzdDNzlDN0YyMTc4QUFEAA==', None, 'user_initiated', True, 'CBP', 0)]
(Background on this error at: https://sqlalche.me/e/14/gkpj)
Traceback (most recent call last):
  File "/home/newton/elarian/virtual/lib/python3.8/site-packages/sqlalchemy/engine/base.py", line 1900, in _execute_context
    self.dialect.do_execute(
  File "/home/newton/elarian/virtual/lib/python3.8/site-packages/sqlalchemy/engine/default.py", line 736, in do_execute
    cursor.execute(statement, parameters)
sqlite3.IntegrityError: UNIQUE constraint failed: incoming_request.message_id

The above exception was the direct cause of the following exception:

Traceback (most recent call last):
  File "application.py", line 78, in save_request
    db.session.commit()
  File "<string>", line 2, in commit
  File "/home/newton/elarian/virtual/lib/python3.8/site-packages/sqlalchemy/orm/session.py", line 1451, in commit
    self._transaction.commit(_to_root=self.future)
  File "/home/newton/elarian/virtual/lib/python3.8/site-packages/sqlalchemy/orm/session.py", line 829, in commit
    self._prepare_impl()
  File "/home/newton/elarian/virtual/lib/python3.8/site-packages/sqlalchemy/orm/session.py", line 808, in _prepare_impl
    self.session.flush()
  File "/home/newton/elarian/virtual/lib/python3.8/site-packages/sqlalchemy/orm/session.py", line 3444, in flush
    self._flush(objects)
  File "/home/newton/elarian/virtual/lib/python3.8/site-packages/sqlalchemy/orm/session.py", line 3584, in _flush
    transaction.rollback(_capture_exception=True)
  File "/home/newton/elarian/virtual/lib/python3.8/site-packages/sqlalchemy/util/langhelpers.py", line 70, in __exit__
    compat.raise_(
  File "/home/newton/elarian/virtual/lib/python3.8/site-packages/sqlalchemy/util/compat.py", line 211, in raise_
    raise exception
  File "/home/newton/elarian/virtual/lib/python3.8/site-packages/sqlalchemy/orm/session.py", line 3544, in _flush
    flush_context.execute()
  File "/home/newton/elarian/virtual/lib/python3.8/site-packages/sqlalchemy/orm/unitofwork.py", line 456, in execute
    rec.execute(self)
  File "/home/newton/elarian/virtual/lib/python3.8/site-packages/sqlalchemy/orm/unitofwork.py", line 630, in execute
    util.preloaded.orm_persistence.save_obj(
  File "/home/newton/elarian/virtual/lib/python3.8/site-packages/sqlalchemy/orm/persistence.py", line 245, in save_obj
    _emit_insert_statements(
  File "/home/newton/elarian/virtual/lib/python3.8/site-packages/sqlalchemy/orm/persistence.py", line 1238, in _emit_insert_statements
    result = connection._execute_20(
  File "/home/newton/elarian/virtual/lib/python3.8/site-packages/sqlalchemy/engine/base.py", line 1705, in _execute_20
    return meth(self, args_10style, kwargs_10style, execution_options)
  File "/home/newton/elarian/virtual/lib/python3.8/site-packages/sqlalchemy/sql/elements.py", line 334, in _execute_on_connection
    return connection._execute_clauseelement(
  File "/home/newton/elarian/virtual/lib/python3.8/site-packages/sqlalchemy/engine/base.py", line 1572, in _execute_clauseelement
    ret = self._execute_context(
  File "/home/newton/elarian/virtual/lib/python3.8/site-packages/sqlalchemy/engine/base.py", line 1943, in _execute_context
    self._handle_dbapi_exception(
  File "/home/newton/elarian/virtual/lib/python3.8/site-packages/sqlalchemy/engine/base.py", line 2124, in _handle_dbapi_exception
    util.raise_(
  File "/home/newton/elarian/virtual/lib/python3.8/site-packages/sqlalchemy/util/compat.py", line 211, in raise_
    raise exception
  File "/home/newton/elarian/virtual/lib/python3.8/site-packages/sqlalchemy/engine/base.py", line 1900, in _execute_context
    self.dialect.do_execute(
  File "/home/newton/elarian/virtual/lib/python3.8/site-packages/sqlalchemy/engine/default.py", line 736, in do_execute
    cursor.execute(statement, parameters)
sqlalchemy.exc.IntegrityError: (sqlite3.IntegrityError) UNIQUE constraint failed: incoming_request.message_id
[SQL: INSERT INTO incoming_request (status, timestamp, recipient_id, conversation_id, message_id, expiration_timestamp, origin, billable, pricing_model, processed) VALUES (?, ?, ?, ?, ?, ?, ?, ?, ?, ?)]
[parameters: ('read', '1674208259', '254741590330', '34802039ee38338fccfd79f9d0f235da', 'wamid.HBgMMjU0NzQxNTkwMzMwFQIAERgSOTgyQzdDNzlDN0YyMTc4QUFEAA==', None, 'user_initiated', True, 'CBP', 0)]
(Background on this error at: https://sqlalche.me/e/14/gkpj)
2023-01-26 12:26:50,804 - log - ERROR - (sqlite3.IntegrityError) UNIQUE constraint failed: incoming_request.message_id
[SQL: INSERT INTO incoming_request (status, timestamp, recipient_id, conversation_id, message_id, expiration_timestamp, origin, billable, pricing_model, processed) VALUES (?, ?, ?, ?, ?, ?, ?, ?, ?, ?)]
[parameters: ('delivered', '1674653501', '254741590330', 'e8b7de634b650e9149030d9c6c01fe97', 'wamid.HBgMMjU0NzQxNTkwMzMwFQIAERgSNTA5MUU4Rjc4RUY3NTYzRDFCAA==', None, 'user_initiated', True, 'CBP', 0)]
(Background on this error at: https://sqlalche.me/e/14/gkpj)
Traceback (most recent call last):
  File "/home/newton/elarian/virtual/lib/python3.8/site-packages/sqlalchemy/engine/base.py", line 1900, in _execute_context
    self.dialect.do_execute(
  File "/home/newton/elarian/virtual/lib/python3.8/site-packages/sqlalchemy/engine/default.py", line 736, in do_execute
    cursor.execute(statement, parameters)
sqlite3.IntegrityError: UNIQUE constraint failed: incoming_request.message_id

The above exception was the direct cause of the following exception:

Traceback (most recent call last):
  File "application.py", line 78, in save_request
    db.session.commit()
  File "<string>", line 2, in commit
  File "/home/newton/elarian/virtual/lib/python3.8/site-packages/sqlalchemy/orm/session.py", line 1451, in commit
    self._transaction.commit(_to_root=self.future)
  File "/home/newton/elarian/virtual/lib/python3.8/site-packages/sqlalchemy/orm/session.py", line 829, in commit
    self._prepare_impl()
  File "/home/newton/elarian/virtual/lib/python3.8/site-packages/sqlalchemy/orm/session.py", line 808, in _prepare_impl
    self.session.flush()
  File "/home/newton/elarian/virtual/lib/python3.8/site-packages/sqlalchemy/orm/session.py", line 3444, in flush
    self._flush(objects)
  File "/home/newton/elarian/virtual/lib/python3.8/site-packages/sqlalchemy/orm/session.py", line 3584, in _flush
    transaction.rollback(_capture_exception=True)
  File "/home/newton/elarian/virtual/lib/python3.8/site-packages/sqlalchemy/util/langhelpers.py", line 70, in __exit__
    compat.raise_(
  File "/home/newton/elarian/virtual/lib/python3.8/site-packages/sqlalchemy/util/compat.py", line 211, in raise_
    raise exception
  File "/home/newton/elarian/virtual/lib/python3.8/site-packages/sqlalchemy/orm/session.py", line 3544, in _flush
    flush_context.execute()
  File "/home/newton/elarian/virtual/lib/python3.8/site-packages/sqlalchemy/orm/unitofwork.py", line 456, in execute
    rec.execute(self)
  File "/home/newton/elarian/virtual/lib/python3.8/site-packages/sqlalchemy/orm/unitofwork.py", line 630, in execute
    util.preloaded.orm_persistence.save_obj(
  File "/home/newton/elarian/virtual/lib/python3.8/site-packages/sqlalchemy/orm/persistence.py", line 245, in save_obj
    _emit_insert_statements(
  File "/home/newton/elarian/virtual/lib/python3.8/site-packages/sqlalchemy/orm/persistence.py", line 1238, in _emit_insert_statements
    result = connection._execute_20(
  File "/home/newton/elarian/virtual/lib/python3.8/site-packages/sqlalchemy/engine/base.py", line 1705, in _execute_20
    return meth(self, args_10style, kwargs_10style, execution_options)
  File "/home/newton/elarian/virtual/lib/python3.8/site-packages/sqlalchemy/sql/elements.py", line 334, in _execute_on_connection
    return connection._execute_clauseelement(
  File "/home/newton/elarian/virtual/lib/python3.8/site-packages/sqlalchemy/engine/base.py", line 1572, in _execute_clauseelement
    ret = self._execute_context(
  File "/home/newton/elarian/virtual/lib/python3.8/site-packages/sqlalchemy/engine/base.py", line 1943, in _execute_context
    self._handle_dbapi_exception(
  File "/home/newton/elarian/virtual/lib/python3.8/site-packages/sqlalchemy/engine/base.py", line 2124, in _handle_dbapi_exception
    util.raise_(
  File "/home/newton/elarian/virtual/lib/python3.8/site-packages/sqlalchemy/util/compat.py", line 211, in raise_
    raise exception
  File "/home/newton/elarian/virtual/lib/python3.8/site-packages/sqlalchemy/engine/base.py", line 1900, in _execute_context
    self.dialect.do_execute(
  File "/home/newton/elarian/virtual/lib/python3.8/site-packages/sqlalchemy/engine/default.py", line 736, in do_execute
    cursor.execute(statement, parameters)
sqlalchemy.exc.IntegrityError: (sqlite3.IntegrityError) UNIQUE constraint failed: incoming_request.message_id
[SQL: INSERT INTO incoming_request (status, timestamp, recipient_id, conversation_id, message_id, expiration_timestamp, origin, billable, pricing_model, processed) VALUES (?, ?, ?, ?, ?, ?, ?, ?, ?, ?)]
[parameters: ('delivered', '1674653501', '254741590330', 'e8b7de634b650e9149030d9c6c01fe97', 'wamid.HBgMMjU0NzQxNTkwMzMwFQIAERgSNTA5MUU4Rjc4RUY3NTYzRDFCAA==', None, 'user_initiated', True, 'CBP', 0)]
(Background on this error at: https://sqlalche.me/e/14/gkpj)
2023-01-26 12:26:58,960 - log - ERROR - (sqlite3.IntegrityError) UNIQUE constraint failed: incoming_request.message_id
[SQL: INSERT INTO incoming_request (status, timestamp, recipient_id, conversation_id, message_id, expiration_timestamp, origin, billable, pricing_model, processed) VALUES (?, ?, ?, ?, ?, ?, ?, ?, ?, ?)]
[parameters: ('sent', '1674204117', '254741590330', '34802039ee38338fccfd79f9d0f235da', 'wamid.HBgMMjU0NzQxNTkwMzMwFQIAERgSRTk3OUEwRUIwMTgyNzJCNDA4AA==', None, 'user_initiated', True, 'CBP', 0)]
(Background on this error at: https://sqlalche.me/e/14/gkpj)
Traceback (most recent call last):
  File "/home/newton/elarian/virtual/lib/python3.8/site-packages/sqlalchemy/engine/base.py", line 1900, in _execute_context
    self.dialect.do_execute(
  File "/home/newton/elarian/virtual/lib/python3.8/site-packages/sqlalchemy/engine/default.py", line 736, in do_execute
    cursor.execute(statement, parameters)
sqlite3.IntegrityError: UNIQUE constraint failed: incoming_request.message_id

The above exception was the direct cause of the following exception:

Traceback (most recent call last):
  File "application.py", line 78, in save_request
    db.session.commit()
  File "<string>", line 2, in commit
  File "/home/newton/elarian/virtual/lib/python3.8/site-packages/sqlalchemy/orm/session.py", line 1451, in commit
    self._transaction.commit(_to_root=self.future)
  File "/home/newton/elarian/virtual/lib/python3.8/site-packages/sqlalchemy/orm/session.py", line 829, in commit
    self._prepare_impl()
  File "/home/newton/elarian/virtual/lib/python3.8/site-packages/sqlalchemy/orm/session.py", line 808, in _prepare_impl
    self.session.flush()
  File "/home/newton/elarian/virtual/lib/python3.8/site-packages/sqlalchemy/orm/session.py", line 3444, in flush
    self._flush(objects)
  File "/home/newton/elarian/virtual/lib/python3.8/site-packages/sqlalchemy/orm/session.py", line 3584, in _flush
    transaction.rollback(_capture_exception=True)
  File "/home/newton/elarian/virtual/lib/python3.8/site-packages/sqlalchemy/util/langhelpers.py", line 70, in __exit__
    compat.raise_(
  File "/home/newton/elarian/virtual/lib/python3.8/site-packages/sqlalchemy/util/compat.py", line 211, in raise_
    raise exception
  File "/home/newton/elarian/virtual/lib/python3.8/site-packages/sqlalchemy/orm/session.py", line 3544, in _flush
    flush_context.execute()
  File "/home/newton/elarian/virtual/lib/python3.8/site-packages/sqlalchemy/orm/unitofwork.py", line 456, in execute
    rec.execute(self)
  File "/home/newton/elarian/virtual/lib/python3.8/site-packages/sqlalchemy/orm/unitofwork.py", line 630, in execute
    util.preloaded.orm_persistence.save_obj(
  File "/home/newton/elarian/virtual/lib/python3.8/site-packages/sqlalchemy/orm/persistence.py", line 245, in save_obj
    _emit_insert_statements(
  File "/home/newton/elarian/virtual/lib/python3.8/site-packages/sqlalchemy/orm/persistence.py", line 1238, in _emit_insert_statements
    result = connection._execute_20(
  File "/home/newton/elarian/virtual/lib/python3.8/site-packages/sqlalchemy/engine/base.py", line 1705, in _execute_20
    return meth(self, args_10style, kwargs_10style, execution_options)
  File "/home/newton/elarian/virtual/lib/python3.8/site-packages/sqlalchemy/sql/elements.py", line 334, in _execute_on_connection
    return connection._execute_clauseelement(
  File "/home/newton/elarian/virtual/lib/python3.8/site-packages/sqlalchemy/engine/base.py", line 1572, in _execute_clauseelement
    ret = self._execute_context(
  File "/home/newton/elarian/virtual/lib/python3.8/site-packages/sqlalchemy/engine/base.py", line 1943, in _execute_context
    self._handle_dbapi_exception(
  File "/home/newton/elarian/virtual/lib/python3.8/site-packages/sqlalchemy/engine/base.py", line 2124, in _handle_dbapi_exception
    util.raise_(
  File "/home/newton/elarian/virtual/lib/python3.8/site-packages/sqlalchemy/util/compat.py", line 211, in raise_
    raise exception
  File "/home/newton/elarian/virtual/lib/python3.8/site-packages/sqlalchemy/engine/base.py", line 1900, in _execute_context
    self.dialect.do_execute(
  File "/home/newton/elarian/virtual/lib/python3.8/site-packages/sqlalchemy/engine/default.py", line 736, in do_execute
    cursor.execute(statement, parameters)
sqlalchemy.exc.IntegrityError: (sqlite3.IntegrityError) UNIQUE constraint failed: incoming_request.message_id
[SQL: INSERT INTO incoming_request (status, timestamp, recipient_id, conversation_id, message_id, expiration_timestamp, origin, billable, pricing_model, processed) VALUES (?, ?, ?, ?, ?, ?, ?, ?, ?, ?)]
[parameters: ('sent', '1674204117', '254741590330', '34802039ee38338fccfd79f9d0f235da', 'wamid.HBgMMjU0NzQxNTkwMzMwFQIAERgSRTk3OUEwRUIwMTgyNzJCNDA4AA==', None, 'user_initiated', True, 'CBP', 0)]
(Background on this error at: https://sqlalche.me/e/14/gkpj)
2023-01-26 12:27:18,549 - log - ERROR - (sqlite3.IntegrityError) UNIQUE constraint failed: incoming_request.message_id
[SQL: INSERT INTO incoming_request (status, timestamp, recipient_id, conversation_id, message_id, expiration_timestamp, origin, billable, pricing_model, processed) VALUES (?, ?, ?, ?, ?, ?, ?, ?, ?, ?)]
[parameters: ('sent', '1674655748', '254741590330', 'e8b7de634b650e9149030d9c6c01fe97', 'wamid.HBgMMjU0NzQxNTkwMzMwFQIAERgSQjk5NzkzMkYzQzVDMkI2NDY0AA==', None, 'user_initiated', True, 'CBP', 0)]
(Background on this error at: https://sqlalche.me/e/14/gkpj)
Traceback (most recent call last):
  File "/home/newton/elarian/virtual/lib/python3.8/site-packages/sqlalchemy/engine/base.py", line 1900, in _execute_context
    self.dialect.do_execute(
  File "/home/newton/elarian/virtual/lib/python3.8/site-packages/sqlalchemy/engine/default.py", line 736, in do_execute
    cursor.execute(statement, parameters)
sqlite3.IntegrityError: UNIQUE constraint failed: incoming_request.message_id

The above exception was the direct cause of the following exception:

Traceback (most recent call last):
  File "application.py", line 78, in save_request
    db.session.commit()
  File "<string>", line 2, in commit
  File "/home/newton/elarian/virtual/lib/python3.8/site-packages/sqlalchemy/orm/session.py", line 1451, in commit
    self._transaction.commit(_to_root=self.future)
  File "/home/newton/elarian/virtual/lib/python3.8/site-packages/sqlalchemy/orm/session.py", line 829, in commit
    self._prepare_impl()
  File "/home/newton/elarian/virtual/lib/python3.8/site-packages/sqlalchemy/orm/session.py", line 808, in _prepare_impl
    self.session.flush()
  File "/home/newton/elarian/virtual/lib/python3.8/site-packages/sqlalchemy/orm/session.py", line 3444, in flush
    self._flush(objects)
  File "/home/newton/elarian/virtual/lib/python3.8/site-packages/sqlalchemy/orm/session.py", line 3584, in _flush
    transaction.rollback(_capture_exception=True)
  File "/home/newton/elarian/virtual/lib/python3.8/site-packages/sqlalchemy/util/langhelpers.py", line 70, in __exit__
    compat.raise_(
  File "/home/newton/elarian/virtual/lib/python3.8/site-packages/sqlalchemy/util/compat.py", line 211, in raise_
    raise exception
  File "/home/newton/elarian/virtual/lib/python3.8/site-packages/sqlalchemy/orm/session.py", line 3544, in _flush
    flush_context.execute()
  File "/home/newton/elarian/virtual/lib/python3.8/site-packages/sqlalchemy/orm/unitofwork.py", line 456, in execute
    rec.execute(self)
  File "/home/newton/elarian/virtual/lib/python3.8/site-packages/sqlalchemy/orm/unitofwork.py", line 630, in execute
    util.preloaded.orm_persistence.save_obj(
  File "/home/newton/elarian/virtual/lib/python3.8/site-packages/sqlalchemy/orm/persistence.py", line 245, in save_obj
    _emit_insert_statements(
  File "/home/newton/elarian/virtual/lib/python3.8/site-packages/sqlalchemy/orm/persistence.py", line 1238, in _emit_insert_statements
    result = connection._execute_20(
  File "/home/newton/elarian/virtual/lib/python3.8/site-packages/sqlalchemy/engine/base.py", line 1705, in _execute_20
    return meth(self, args_10style, kwargs_10style, execution_options)
  File "/home/newton/elarian/virtual/lib/python3.8/site-packages/sqlalchemy/sql/elements.py", line 334, in _execute_on_connection
    return connection._execute_clauseelement(
  File "/home/newton/elarian/virtual/lib/python3.8/site-packages/sqlalchemy/engine/base.py", line 1572, in _execute_clauseelement
    ret = self._execute_context(
  File "/home/newton/elarian/virtual/lib/python3.8/site-packages/sqlalchemy/engine/base.py", line 1943, in _execute_context
    self._handle_dbapi_exception(
  File "/home/newton/elarian/virtual/lib/python3.8/site-packages/sqlalchemy/engine/base.py", line 2124, in _handle_dbapi_exception
    util.raise_(
  File "/home/newton/elarian/virtual/lib/python3.8/site-packages/sqlalchemy/util/compat.py", line 211, in raise_
    raise exception
  File "/home/newton/elarian/virtual/lib/python3.8/site-packages/sqlalchemy/engine/base.py", line 1900, in _execute_context
    self.dialect.do_execute(
  File "/home/newton/elarian/virtual/lib/python3.8/site-packages/sqlalchemy/engine/default.py", line 736, in do_execute
    cursor.execute(statement, parameters)
sqlalchemy.exc.IntegrityError: (sqlite3.IntegrityError) UNIQUE constraint failed: incoming_request.message_id
[SQL: INSERT INTO incoming_request (status, timestamp, recipient_id, conversation_id, message_id, expiration_timestamp, origin, billable, pricing_model, processed) VALUES (?, ?, ?, ?, ?, ?, ?, ?, ?, ?)]
[parameters: ('sent', '1674655748', '254741590330', 'e8b7de634b650e9149030d9c6c01fe97', 'wamid.HBgMMjU0NzQxNTkwMzMwFQIAERgSQjk5NzkzMkYzQzVDMkI2NDY0AA==', None, 'user_initiated', True, 'CBP', 0)]
(Background on this error at: https://sqlalche.me/e/14/gkpj)
2023-01-26 12:27:22,367 - log - ERROR - 'NoneType' object has no attribute 'processed'
Traceback (most recent call last):
  File "application.py", line 173, in heyoo
    processed_message = IncomingRequest.query.filter_by(message_id=message_id,  processed=False).first()
AttributeError: 'NoneType' object has no attribute 'processed'
2023-01-26 12:27:43,082 - log - ERROR - 'NoneType' object has no attribute 'processed'
Traceback (most recent call last):
  File "application.py", line 173, in heyoo
    processed_message = IncomingRequest.query.filter_by(message_id=message_id,  processed=False).first()
AttributeError: 'NoneType' object has no attribute 'processed'
2023-01-26 12:27:45,094 - log - ERROR - (sqlite3.IntegrityError) UNIQUE constraint failed: incoming_request.message_id
[SQL: INSERT INTO incoming_request (status, timestamp, recipient_id, conversation_id, message_id, expiration_timestamp, origin, billable, pricing_model, processed) VALUES (?, ?, ?, ?, ?, ?, ?, ?, ?, ?)]
[parameters: ('delivered', '1674651488', '254716434058', 'c1b63a1655a036852a22a89da7fb908a', 'wamid.HBgMMjU0NzE2NDM0MDU4FQIAERgSMEQ0QTI5MDUwQURGQjhGQTQxAA==', None, 'user_initiated', True, 'CBP', 0)]
(Background on this error at: https://sqlalche.me/e/14/gkpj)
Traceback (most recent call last):
  File "/home/newton/elarian/virtual/lib/python3.8/site-packages/sqlalchemy/engine/base.py", line 1900, in _execute_context
    self.dialect.do_execute(
  File "/home/newton/elarian/virtual/lib/python3.8/site-packages/sqlalchemy/engine/default.py", line 736, in do_execute
    cursor.execute(statement, parameters)
sqlite3.IntegrityError: UNIQUE constraint failed: incoming_request.message_id

The above exception was the direct cause of the following exception:

Traceback (most recent call last):
  File "application.py", line 78, in save_request
    db.session.commit()
  File "<string>", line 2, in commit
  File "/home/newton/elarian/virtual/lib/python3.8/site-packages/sqlalchemy/orm/session.py", line 1451, in commit
    self._transaction.commit(_to_root=self.future)
  File "/home/newton/elarian/virtual/lib/python3.8/site-packages/sqlalchemy/orm/session.py", line 829, in commit
    self._prepare_impl()
  File "/home/newton/elarian/virtual/lib/python3.8/site-packages/sqlalchemy/orm/session.py", line 808, in _prepare_impl
    self.session.flush()
  File "/home/newton/elarian/virtual/lib/python3.8/site-packages/sqlalchemy/orm/session.py", line 3444, in flush
    self._flush(objects)
  File "/home/newton/elarian/virtual/lib/python3.8/site-packages/sqlalchemy/orm/session.py", line 3584, in _flush
    transaction.rollback(_capture_exception=True)
  File "/home/newton/elarian/virtual/lib/python3.8/site-packages/sqlalchemy/util/langhelpers.py", line 70, in __exit__
    compat.raise_(
  File "/home/newton/elarian/virtual/lib/python3.8/site-packages/sqlalchemy/util/compat.py", line 211, in raise_
    raise exception
  File "/home/newton/elarian/virtual/lib/python3.8/site-packages/sqlalchemy/orm/session.py", line 3544, in _flush
    flush_context.execute()
  File "/home/newton/elarian/virtual/lib/python3.8/site-packages/sqlalchemy/orm/unitofwork.py", line 456, in execute
    rec.execute(self)
  File "/home/newton/elarian/virtual/lib/python3.8/site-packages/sqlalchemy/orm/unitofwork.py", line 630, in execute
    util.preloaded.orm_persistence.save_obj(
  File "/home/newton/elarian/virtual/lib/python3.8/site-packages/sqlalchemy/orm/persistence.py", line 245, in save_obj
    _emit_insert_statements(
  File "/home/newton/elarian/virtual/lib/python3.8/site-packages/sqlalchemy/orm/persistence.py", line 1238, in _emit_insert_statements
    result = connection._execute_20(
  File "/home/newton/elarian/virtual/lib/python3.8/site-packages/sqlalchemy/engine/base.py", line 1705, in _execute_20
    return meth(self, args_10style, kwargs_10style, execution_options)
  File "/home/newton/elarian/virtual/lib/python3.8/site-packages/sqlalchemy/sql/elements.py", line 334, in _execute_on_connection
    return connection._execute_clauseelement(
  File "/home/newton/elarian/virtual/lib/python3.8/site-packages/sqlalchemy/engine/base.py", line 1572, in _execute_clauseelement
    ret = self._execute_context(
  File "/home/newton/elarian/virtual/lib/python3.8/site-packages/sqlalchemy/engine/base.py", line 1943, in _execute_context
    self._handle_dbapi_exception(
  File "/home/newton/elarian/virtual/lib/python3.8/site-packages/sqlalchemy/engine/base.py", line 2124, in _handle_dbapi_exception
    util.raise_(
  File "/home/newton/elarian/virtual/lib/python3.8/site-packages/sqlalchemy/util/compat.py", line 211, in raise_
    raise exception
  File "/home/newton/elarian/virtual/lib/python3.8/site-packages/sqlalchemy/engine/base.py", line 1900, in _execute_context
    self.dialect.do_execute(
  File "/home/newton/elarian/virtual/lib/python3.8/site-packages/sqlalchemy/engine/default.py", line 736, in do_execute
    cursor.execute(statement, parameters)
sqlalchemy.exc.IntegrityError: (sqlite3.IntegrityError) UNIQUE constraint failed: incoming_request.message_id
[SQL: INSERT INTO incoming_request (status, timestamp, recipient_id, conversation_id, message_id, expiration_timestamp, origin, billable, pricing_model, processed) VALUES (?, ?, ?, ?, ?, ?, ?, ?, ?, ?)]
[parameters: ('delivered', '1674651488', '254716434058', 'c1b63a1655a036852a22a89da7fb908a', 'wamid.HBgMMjU0NzE2NDM0MDU4FQIAERgSMEQ0QTI5MDUwQURGQjhGQTQxAA==', None, 'user_initiated', True, 'CBP', 0)]
(Background on this error at: https://sqlalche.me/e/14/gkpj)
2023-01-26 12:28:27,313 - log - ERROR - (sqlite3.IntegrityError) UNIQUE constraint failed: incoming_request.message_id
[SQL: INSERT INTO incoming_request (status, timestamp, recipient_id, conversation_id, message_id, expiration_timestamp, origin, billable, pricing_model, processed) VALUES (?, ?, ?, ?, ?, ?, ?, ?, ?, ?)]
[parameters: ('sent', '1674219092', '254741590330', '34802039ee38338fccfd79f9d0f235da', 'wamid.HBgMMjU0NzQxNTkwMzMwFQIAERgSMUYxODRBQzAwNEI2OEUzOEY3AA==', None, 'user_initiated', True, 'CBP', 0)]
(Background on this error at: https://sqlalche.me/e/14/gkpj)
Traceback (most recent call last):
  File "/home/newton/elarian/virtual/lib/python3.8/site-packages/sqlalchemy/engine/base.py", line 1900, in _execute_context
    self.dialect.do_execute(
  File "/home/newton/elarian/virtual/lib/python3.8/site-packages/sqlalchemy/engine/default.py", line 736, in do_execute
    cursor.execute(statement, parameters)
sqlite3.IntegrityError: UNIQUE constraint failed: incoming_request.message_id

The above exception was the direct cause of the following exception:

Traceback (most recent call last):
  File "application.py", line 78, in save_request
    db.session.commit()
  File "<string>", line 2, in commit
  File "/home/newton/elarian/virtual/lib/python3.8/site-packages/sqlalchemy/orm/session.py", line 1451, in commit
    self._transaction.commit(_to_root=self.future)
  File "/home/newton/elarian/virtual/lib/python3.8/site-packages/sqlalchemy/orm/session.py", line 829, in commit
    self._prepare_impl()
  File "/home/newton/elarian/virtual/lib/python3.8/site-packages/sqlalchemy/orm/session.py", line 808, in _prepare_impl
    self.session.flush()
  File "/home/newton/elarian/virtual/lib/python3.8/site-packages/sqlalchemy/orm/session.py", line 3444, in flush
    self._flush(objects)
  File "/home/newton/elarian/virtual/lib/python3.8/site-packages/sqlalchemy/orm/session.py", line 3584, in _flush
    transaction.rollback(_capture_exception=True)
  File "/home/newton/elarian/virtual/lib/python3.8/site-packages/sqlalchemy/util/langhelpers.py", line 70, in __exit__
    compat.raise_(
  File "/home/newton/elarian/virtual/lib/python3.8/site-packages/sqlalchemy/util/compat.py", line 211, in raise_
    raise exception
  File "/home/newton/elarian/virtual/lib/python3.8/site-packages/sqlalchemy/orm/session.py", line 3544, in _flush
    flush_context.execute()
  File "/home/newton/elarian/virtual/lib/python3.8/site-packages/sqlalchemy/orm/unitofwork.py", line 456, in execute
    rec.execute(self)
  File "/home/newton/elarian/virtual/lib/python3.8/site-packages/sqlalchemy/orm/unitofwork.py", line 630, in execute
    util.preloaded.orm_persistence.save_obj(
  File "/home/newton/elarian/virtual/lib/python3.8/site-packages/sqlalchemy/orm/persistence.py", line 245, in save_obj
    _emit_insert_statements(
  File "/home/newton/elarian/virtual/lib/python3.8/site-packages/sqlalchemy/orm/persistence.py", line 1238, in _emit_insert_statements
    result = connection._execute_20(
  File "/home/newton/elarian/virtual/lib/python3.8/site-packages/sqlalchemy/engine/base.py", line 1705, in _execute_20
    return meth(self, args_10style, kwargs_10style, execution_options)
  File "/home/newton/elarian/virtual/lib/python3.8/site-packages/sqlalchemy/sql/elements.py", line 334, in _execute_on_connection
    return connection._execute_clauseelement(
  File "/home/newton/elarian/virtual/lib/python3.8/site-packages/sqlalchemy/engine/base.py", line 1572, in _execute_clauseelement
    ret = self._execute_context(
  File "/home/newton/elarian/virtual/lib/python3.8/site-packages/sqlalchemy/engine/base.py", line 1943, in _execute_context
    self._handle_dbapi_exception(
  File "/home/newton/elarian/virtual/lib/python3.8/site-packages/sqlalchemy/engine/base.py", line 2124, in _handle_dbapi_exception
    util.raise_(
  File "/home/newton/elarian/virtual/lib/python3.8/site-packages/sqlalchemy/util/compat.py", line 211, in raise_
    raise exception
  File "/home/newton/elarian/virtual/lib/python3.8/site-packages/sqlalchemy/engine/base.py", line 1900, in _execute_context
    self.dialect.do_execute(
  File "/home/newton/elarian/virtual/lib/python3.8/site-packages/sqlalchemy/engine/default.py", line 736, in do_execute
    cursor.execute(statement, parameters)
sqlalchemy.exc.IntegrityError: (sqlite3.IntegrityError) UNIQUE constraint failed: incoming_request.message_id
[SQL: INSERT INTO incoming_request (status, timestamp, recipient_id, conversation_id, message_id, expiration_timestamp, origin, billable, pricing_model, processed) VALUES (?, ?, ?, ?, ?, ?, ?, ?, ?, ?)]
[parameters: ('sent', '1674219092', '254741590330', '34802039ee38338fccfd79f9d0f235da', 'wamid.HBgMMjU0NzQxNTkwMzMwFQIAERgSMUYxODRBQzAwNEI2OEUzOEY3AA==', None, 'user_initiated', True, 'CBP', 0)]
(Background on this error at: https://sqlalche.me/e/14/gkpj)
2023-01-26 12:28:28,931 - log - ERROR - (sqlite3.IntegrityError) UNIQUE constraint failed: incoming_request.message_id
[SQL: INSERT INTO incoming_request (status, timestamp, recipient_id, conversation_id, message_id, expiration_timestamp, origin, billable, pricing_model, processed) VALUES (?, ?, ?, ?, ?, ?, ?, ?, ?, ?)]
[parameters: ('read', '1674208561', '254741590330', '34802039ee38338fccfd79f9d0f235da', 'wamid.HBgMMjU0NzQxNTkwMzMwFQIAERgSRkNDQjY0NTQzMTRCNERERTNCAA==', None, 'user_initiated', True, 'CBP', 0)]
(Background on this error at: https://sqlalche.me/e/14/gkpj)
Traceback (most recent call last):
  File "/home/newton/elarian/virtual/lib/python3.8/site-packages/sqlalchemy/engine/base.py", line 1900, in _execute_context
    self.dialect.do_execute(
  File "/home/newton/elarian/virtual/lib/python3.8/site-packages/sqlalchemy/engine/default.py", line 736, in do_execute
    cursor.execute(statement, parameters)
sqlite3.IntegrityError: UNIQUE constraint failed: incoming_request.message_id

The above exception was the direct cause of the following exception:

Traceback (most recent call last):
  File "application.py", line 78, in save_request
    db.session.commit()
  File "<string>", line 2, in commit
  File "/home/newton/elarian/virtual/lib/python3.8/site-packages/sqlalchemy/orm/session.py", line 1451, in commit
    self._transaction.commit(_to_root=self.future)
  File "/home/newton/elarian/virtual/lib/python3.8/site-packages/sqlalchemy/orm/session.py", line 829, in commit
    self._prepare_impl()
  File "/home/newton/elarian/virtual/lib/python3.8/site-packages/sqlalchemy/orm/session.py", line 808, in _prepare_impl
    self.session.flush()
  File "/home/newton/elarian/virtual/lib/python3.8/site-packages/sqlalchemy/orm/session.py", line 3444, in flush
    self._flush(objects)
  File "/home/newton/elarian/virtual/lib/python3.8/site-packages/sqlalchemy/orm/session.py", line 3584, in _flush
    transaction.rollback(_capture_exception=True)
  File "/home/newton/elarian/virtual/lib/python3.8/site-packages/sqlalchemy/util/langhelpers.py", line 70, in __exit__
    compat.raise_(
  File "/home/newton/elarian/virtual/lib/python3.8/site-packages/sqlalchemy/util/compat.py", line 211, in raise_
    raise exception
  File "/home/newton/elarian/virtual/lib/python3.8/site-packages/sqlalchemy/orm/session.py", line 3544, in _flush
    flush_context.execute()
  File "/home/newton/elarian/virtual/lib/python3.8/site-packages/sqlalchemy/orm/unitofwork.py", line 456, in execute
    rec.execute(self)
  File "/home/newton/elarian/virtual/lib/python3.8/site-packages/sqlalchemy/orm/unitofwork.py", line 630, in execute
    util.preloaded.orm_persistence.save_obj(
  File "/home/newton/elarian/virtual/lib/python3.8/site-packages/sqlalchemy/orm/persistence.py", line 245, in save_obj
    _emit_insert_statements(
  File "/home/newton/elarian/virtual/lib/python3.8/site-packages/sqlalchemy/orm/persistence.py", line 1238, in _emit_insert_statements
    result = connection._execute_20(
  File "/home/newton/elarian/virtual/lib/python3.8/site-packages/sqlalchemy/engine/base.py", line 1705, in _execute_20
    return meth(self, args_10style, kwargs_10style, execution_options)
  File "/home/newton/elarian/virtual/lib/python3.8/site-packages/sqlalchemy/sql/elements.py", line 334, in _execute_on_connection
    return connection._execute_clauseelement(
  File "/home/newton/elarian/virtual/lib/python3.8/site-packages/sqlalchemy/engine/base.py", line 1572, in _execute_clauseelement
    ret = self._execute_context(
  File "/home/newton/elarian/virtual/lib/python3.8/site-packages/sqlalchemy/engine/base.py", line 1943, in _execute_context
    self._handle_dbapi_exception(
  File "/home/newton/elarian/virtual/lib/python3.8/site-packages/sqlalchemy/engine/base.py", line 2124, in _handle_dbapi_exception
    util.raise_(
  File "/home/newton/elarian/virtual/lib/python3.8/site-packages/sqlalchemy/util/compat.py", line 211, in raise_
    raise exception
  File "/home/newton/elarian/virtual/lib/python3.8/site-packages/sqlalchemy/engine/base.py", line 1900, in _execute_context
    self.dialect.do_execute(
  File "/home/newton/elarian/virtual/lib/python3.8/site-packages/sqlalchemy/engine/default.py", line 736, in do_execute
    cursor.execute(statement, parameters)
sqlalchemy.exc.IntegrityError: (sqlite3.IntegrityError) UNIQUE constraint failed: incoming_request.message_id
[SQL: INSERT INTO incoming_request (status, timestamp, recipient_id, conversation_id, message_id, expiration_timestamp, origin, billable, pricing_model, processed) VALUES (?, ?, ?, ?, ?, ?, ?, ?, ?, ?)]
[parameters: ('read', '1674208561', '254741590330', '34802039ee38338fccfd79f9d0f235da', 'wamid.HBgMMjU0NzQxNTkwMzMwFQIAERgSRkNDQjY0NTQzMTRCNERERTNCAA==', None, 'user_initiated', True, 'CBP', 0)]
(Background on this error at: https://sqlalche.me/e/14/gkpj)
2023-01-26 12:28:38,208 - log - ERROR - 'NoneType' object has no attribute 'processed'
Traceback (most recent call last):
  File "application.py", line 173, in heyoo
    processed_message = IncomingRequest.query.filter_by(message_id=message_id,  processed=False).first()
AttributeError: 'NoneType' object has no attribute 'processed'
2023-01-26 12:29:05,567 - log - ERROR - 'NoneType' object has no attribute 'processed'
Traceback (most recent call last):
  File "application.py", line 173, in heyoo
    processed_message = IncomingRequest.query.filter_by(message_id=message_id,  processed=False).first()
AttributeError: 'NoneType' object has no attribute 'processed'
2023-01-26 12:29:07,626 - log - ERROR - 'NoneType' object has no attribute 'processed'
Traceback (most recent call last):
  File "application.py", line 173, in heyoo
    processed_message = IncomingRequest.query.filter_by(message_id=message_id,  processed=False).first()
AttributeError: 'NoneType' object has no attribute 'processed'
2023-01-26 12:29:22,286 - log - ERROR - 'NoneType' object has no attribute 'processed'
Traceback (most recent call last):
  File "application.py", line 173, in heyoo
    processed_message = IncomingRequest.query.filter_by(message_id=message_id,  processed=False).first()
AttributeError: 'NoneType' object has no attribute 'processed'
2023-01-26 12:29:24,431 - log - ERROR - (sqlite3.IntegrityError) UNIQUE constraint failed: incoming_request.message_id
[SQL: INSERT INTO incoming_request (status, timestamp, recipient_id, conversation_id, message_id, expiration_timestamp, origin, billable, pricing_model, processed) VALUES (?, ?, ?, ?, ?, ?, ?, ?, ?, ?)]
[parameters: ('sent', '1674654855', '254741590330', 'e8b7de634b650e9149030d9c6c01fe97', 'wamid.HBgMMjU0NzQxNTkwMzMwFQIAERgSM0Q3NDkwNTA4MkNDNUFDMzIwAA==', None, 'user_initiated', True, 'CBP', 0)]
(Background on this error at: https://sqlalche.me/e/14/gkpj)
Traceback (most recent call last):
  File "/home/newton/elarian/virtual/lib/python3.8/site-packages/sqlalchemy/engine/base.py", line 1900, in _execute_context
    self.dialect.do_execute(
  File "/home/newton/elarian/virtual/lib/python3.8/site-packages/sqlalchemy/engine/default.py", line 736, in do_execute
    cursor.execute(statement, parameters)
sqlite3.IntegrityError: UNIQUE constraint failed: incoming_request.message_id

The above exception was the direct cause of the following exception:

Traceback (most recent call last):
  File "application.py", line 78, in save_request
    db.session.commit()
  File "<string>", line 2, in commit
  File "/home/newton/elarian/virtual/lib/python3.8/site-packages/sqlalchemy/orm/session.py", line 1451, in commit
    self._transaction.commit(_to_root=self.future)
  File "/home/newton/elarian/virtual/lib/python3.8/site-packages/sqlalchemy/orm/session.py", line 829, in commit
    self._prepare_impl()
  File "/home/newton/elarian/virtual/lib/python3.8/site-packages/sqlalchemy/orm/session.py", line 808, in _prepare_impl
    self.session.flush()
  File "/home/newton/elarian/virtual/lib/python3.8/site-packages/sqlalchemy/orm/session.py", line 3444, in flush
    self._flush(objects)
  File "/home/newton/elarian/virtual/lib/python3.8/site-packages/sqlalchemy/orm/session.py", line 3584, in _flush
    transaction.rollback(_capture_exception=True)
  File "/home/newton/elarian/virtual/lib/python3.8/site-packages/sqlalchemy/util/langhelpers.py", line 70, in __exit__
    compat.raise_(
  File "/home/newton/elarian/virtual/lib/python3.8/site-packages/sqlalchemy/util/compat.py", line 211, in raise_
    raise exception
  File "/home/newton/elarian/virtual/lib/python3.8/site-packages/sqlalchemy/orm/session.py", line 3544, in _flush
    flush_context.execute()
  File "/home/newton/elarian/virtual/lib/python3.8/site-packages/sqlalchemy/orm/unitofwork.py", line 456, in execute
    rec.execute(self)
  File "/home/newton/elarian/virtual/lib/python3.8/site-packages/sqlalchemy/orm/unitofwork.py", line 630, in execute
    util.preloaded.orm_persistence.save_obj(
  File "/home/newton/elarian/virtual/lib/python3.8/site-packages/sqlalchemy/orm/persistence.py", line 245, in save_obj
    _emit_insert_statements(
  File "/home/newton/elarian/virtual/lib/python3.8/site-packages/sqlalchemy/orm/persistence.py", line 1238, in _emit_insert_statements
    result = connection._execute_20(
  File "/home/newton/elarian/virtual/lib/python3.8/site-packages/sqlalchemy/engine/base.py", line 1705, in _execute_20
    return meth(self, args_10style, kwargs_10style, execution_options)
  File "/home/newton/elarian/virtual/lib/python3.8/site-packages/sqlalchemy/sql/elements.py", line 334, in _execute_on_connection
    return connection._execute_clauseelement(
  File "/home/newton/elarian/virtual/lib/python3.8/site-packages/sqlalchemy/engine/base.py", line 1572, in _execute_clauseelement
    ret = self._execute_context(
  File "/home/newton/elarian/virtual/lib/python3.8/site-packages/sqlalchemy/engine/base.py", line 1943, in _execute_context
    self._handle_dbapi_exception(
  File "/home/newton/elarian/virtual/lib/python3.8/site-packages/sqlalchemy/engine/base.py", line 2124, in _handle_dbapi_exception
    util.raise_(
  File "/home/newton/elarian/virtual/lib/python3.8/site-packages/sqlalchemy/util/compat.py", line 211, in raise_
    raise exception
  File "/home/newton/elarian/virtual/lib/python3.8/site-packages/sqlalchemy/engine/base.py", line 1900, in _execute_context
    self.dialect.do_execute(
  File "/home/newton/elarian/virtual/lib/python3.8/site-packages/sqlalchemy/engine/default.py", line 736, in do_execute
    cursor.execute(statement, parameters)
sqlalchemy.exc.IntegrityError: (sqlite3.IntegrityError) UNIQUE constraint failed: incoming_request.message_id
[SQL: INSERT INTO incoming_request (status, timestamp, recipient_id, conversation_id, message_id, expiration_timestamp, origin, billable, pricing_model, processed) VALUES (?, ?, ?, ?, ?, ?, ?, ?, ?, ?)]
[parameters: ('sent', '1674654855', '254741590330', 'e8b7de634b650e9149030d9c6c01fe97', 'wamid.HBgMMjU0NzQxNTkwMzMwFQIAERgSM0Q3NDkwNTA4MkNDNUFDMzIwAA==', None, 'user_initiated', True, 'CBP', 0)]
(Background on this error at: https://sqlalche.me/e/14/gkpj)
2023-01-26 12:29:54,852 - log - ERROR - 'NoneType' object has no attribute 'processed'
Traceback (most recent call last):
  File "application.py", line 173, in heyoo
    processed_message = IncomingRequest.query.filter_by(message_id=message_id,  processed=False).first()
AttributeError: 'NoneType' object has no attribute 'processed'
2023-01-26 12:30:17,986 - log - ERROR - (sqlite3.IntegrityError) UNIQUE constraint failed: incoming_request.message_id
[SQL: INSERT INTO incoming_request (status, timestamp, recipient_id, conversation_id, message_id, expiration_timestamp, origin, billable, pricing_model, processed) VALUES (?, ?, ?, ?, ?, ?, ?, ?, ?, ?)]
[parameters: ('delivered', '1674651893', '254741590330', 'e8b7de634b650e9149030d9c6c01fe97', 'wamid.HBgMMjU0NzQxNTkwMzMwFQIAERgSMEEyOTE5MzJENTQzRTFDODc5AA==', None, 'user_initiated', True, 'CBP', 0)]
(Background on this error at: https://sqlalche.me/e/14/gkpj)
Traceback (most recent call last):
  File "/home/newton/elarian/virtual/lib/python3.8/site-packages/sqlalchemy/engine/base.py", line 1900, in _execute_context
    self.dialect.do_execute(
  File "/home/newton/elarian/virtual/lib/python3.8/site-packages/sqlalchemy/engine/default.py", line 736, in do_execute
    cursor.execute(statement, parameters)
sqlite3.IntegrityError: UNIQUE constraint failed: incoming_request.message_id

The above exception was the direct cause of the following exception:

Traceback (most recent call last):
  File "application.py", line 78, in save_request
    db.session.commit()
  File "<string>", line 2, in commit
  File "/home/newton/elarian/virtual/lib/python3.8/site-packages/sqlalchemy/orm/session.py", line 1451, in commit
    self._transaction.commit(_to_root=self.future)
  File "/home/newton/elarian/virtual/lib/python3.8/site-packages/sqlalchemy/orm/session.py", line 829, in commit
    self._prepare_impl()
  File "/home/newton/elarian/virtual/lib/python3.8/site-packages/sqlalchemy/orm/session.py", line 808, in _prepare_impl
    self.session.flush()
  File "/home/newton/elarian/virtual/lib/python3.8/site-packages/sqlalchemy/orm/session.py", line 3444, in flush
    self._flush(objects)
  File "/home/newton/elarian/virtual/lib/python3.8/site-packages/sqlalchemy/orm/session.py", line 3584, in _flush
    transaction.rollback(_capture_exception=True)
  File "/home/newton/elarian/virtual/lib/python3.8/site-packages/sqlalchemy/util/langhelpers.py", line 70, in __exit__
    compat.raise_(
  File "/home/newton/elarian/virtual/lib/python3.8/site-packages/sqlalchemy/util/compat.py", line 211, in raise_
    raise exception
  File "/home/newton/elarian/virtual/lib/python3.8/site-packages/sqlalchemy/orm/session.py", line 3544, in _flush
    flush_context.execute()
  File "/home/newton/elarian/virtual/lib/python3.8/site-packages/sqlalchemy/orm/unitofwork.py", line 456, in execute
    rec.execute(self)
  File "/home/newton/elarian/virtual/lib/python3.8/site-packages/sqlalchemy/orm/unitofwork.py", line 630, in execute
    util.preloaded.orm_persistence.save_obj(
  File "/home/newton/elarian/virtual/lib/python3.8/site-packages/sqlalchemy/orm/persistence.py", line 245, in save_obj
    _emit_insert_statements(
  File "/home/newton/elarian/virtual/lib/python3.8/site-packages/sqlalchemy/orm/persistence.py", line 1238, in _emit_insert_statements
    result = connection._execute_20(
  File "/home/newton/elarian/virtual/lib/python3.8/site-packages/sqlalchemy/engine/base.py", line 1705, in _execute_20
    return meth(self, args_10style, kwargs_10style, execution_options)
  File "/home/newton/elarian/virtual/lib/python3.8/site-packages/sqlalchemy/sql/elements.py", line 334, in _execute_on_connection
    return connection._execute_clauseelement(
  File "/home/newton/elarian/virtual/lib/python3.8/site-packages/sqlalchemy/engine/base.py", line 1572, in _execute_clauseelement
    ret = self._execute_context(
  File "/home/newton/elarian/virtual/lib/python3.8/site-packages/sqlalchemy/engine/base.py", line 1943, in _execute_context
    self._handle_dbapi_exception(
  File "/home/newton/elarian/virtual/lib/python3.8/site-packages/sqlalchemy/engine/base.py", line 2124, in _handle_dbapi_exception
    util.raise_(
  File "/home/newton/elarian/virtual/lib/python3.8/site-packages/sqlalchemy/util/compat.py", line 211, in raise_
    raise exception
  File "/home/newton/elarian/virtual/lib/python3.8/site-packages/sqlalchemy/engine/base.py", line 1900, in _execute_context
    self.dialect.do_execute(
  File "/home/newton/elarian/virtual/lib/python3.8/site-packages/sqlalchemy/engine/default.py", line 736, in do_execute
    cursor.execute(statement, parameters)
sqlalchemy.exc.IntegrityError: (sqlite3.IntegrityError) UNIQUE constraint failed: incoming_request.message_id
[SQL: INSERT INTO incoming_request (status, timestamp, recipient_id, conversation_id, message_id, expiration_timestamp, origin, billable, pricing_model, processed) VALUES (?, ?, ?, ?, ?, ?, ?, ?, ?, ?)]
[parameters: ('delivered', '1674651893', '254741590330', 'e8b7de634b650e9149030d9c6c01fe97', 'wamid.HBgMMjU0NzQxNTkwMzMwFQIAERgSMEEyOTE5MzJENTQzRTFDODc5AA==', None, 'user_initiated', True, 'CBP', 0)]
(Background on this error at: https://sqlalche.me/e/14/gkpj)
2023-01-26 12:31:09,074 - log - ERROR - (sqlite3.IntegrityError) UNIQUE constraint failed: incoming_request.message_id
[SQL: INSERT INTO incoming_request (status, timestamp, recipient_id, conversation_id, message_id, expiration_timestamp, origin, billable, pricing_model, processed) VALUES (?, ?, ?, ?, ?, ?, ?, ?, ?, ?)]
[parameters: ('sent', '1674656622', '254741590330', 'e8b7de634b650e9149030d9c6c01fe97', 'wamid.HBgMMjU0NzQxNTkwMzMwFQIAERgSM0RDQzNFNDA1RTBBNzU4NzMzAA==', None, 'user_initiated', True, 'CBP', 0)]
(Background on this error at: https://sqlalche.me/e/14/gkpj)
Traceback (most recent call last):
  File "/home/newton/elarian/virtual/lib/python3.8/site-packages/sqlalchemy/engine/base.py", line 1900, in _execute_context
    self.dialect.do_execute(
  File "/home/newton/elarian/virtual/lib/python3.8/site-packages/sqlalchemy/engine/default.py", line 736, in do_execute
    cursor.execute(statement, parameters)
sqlite3.IntegrityError: UNIQUE constraint failed: incoming_request.message_id

The above exception was the direct cause of the following exception:

Traceback (most recent call last):
  File "application.py", line 78, in save_request
    db.session.commit()
  File "<string>", line 2, in commit
  File "/home/newton/elarian/virtual/lib/python3.8/site-packages/sqlalchemy/orm/session.py", line 1451, in commit
    self._transaction.commit(_to_root=self.future)
  File "/home/newton/elarian/virtual/lib/python3.8/site-packages/sqlalchemy/orm/session.py", line 829, in commit
    self._prepare_impl()
  File "/home/newton/elarian/virtual/lib/python3.8/site-packages/sqlalchemy/orm/session.py", line 808, in _prepare_impl
    self.session.flush()
  File "/home/newton/elarian/virtual/lib/python3.8/site-packages/sqlalchemy/orm/session.py", line 3444, in flush
    self._flush(objects)
  File "/home/newton/elarian/virtual/lib/python3.8/site-packages/sqlalchemy/orm/session.py", line 3584, in _flush
    transaction.rollback(_capture_exception=True)
  File "/home/newton/elarian/virtual/lib/python3.8/site-packages/sqlalchemy/util/langhelpers.py", line 70, in __exit__
    compat.raise_(
  File "/home/newton/elarian/virtual/lib/python3.8/site-packages/sqlalchemy/util/compat.py", line 211, in raise_
    raise exception
  File "/home/newton/elarian/virtual/lib/python3.8/site-packages/sqlalchemy/orm/session.py", line 3544, in _flush
    flush_context.execute()
  File "/home/newton/elarian/virtual/lib/python3.8/site-packages/sqlalchemy/orm/unitofwork.py", line 456, in execute
    rec.execute(self)
  File "/home/newton/elarian/virtual/lib/python3.8/site-packages/sqlalchemy/orm/unitofwork.py", line 630, in execute
    util.preloaded.orm_persistence.save_obj(
  File "/home/newton/elarian/virtual/lib/python3.8/site-packages/sqlalchemy/orm/persistence.py", line 245, in save_obj
    _emit_insert_statements(
  File "/home/newton/elarian/virtual/lib/python3.8/site-packages/sqlalchemy/orm/persistence.py", line 1238, in _emit_insert_statements
    result = connection._execute_20(
  File "/home/newton/elarian/virtual/lib/python3.8/site-packages/sqlalchemy/engine/base.py", line 1705, in _execute_20
    return meth(self, args_10style, kwargs_10style, execution_options)
  File "/home/newton/elarian/virtual/lib/python3.8/site-packages/sqlalchemy/sql/elements.py", line 334, in _execute_on_connection
    return connection._execute_clauseelement(
  File "/home/newton/elarian/virtual/lib/python3.8/site-packages/sqlalchemy/engine/base.py", line 1572, in _execute_clauseelement
    ret = self._execute_context(
  File "/home/newton/elarian/virtual/lib/python3.8/site-packages/sqlalchemy/engine/base.py", line 1943, in _execute_context
    self._handle_dbapi_exception(
  File "/home/newton/elarian/virtual/lib/python3.8/site-packages/sqlalchemy/engine/base.py", line 2124, in _handle_dbapi_exception
    util.raise_(
  File "/home/newton/elarian/virtual/lib/python3.8/site-packages/sqlalchemy/util/compat.py", line 211, in raise_
    raise exception
  File "/home/newton/elarian/virtual/lib/python3.8/site-packages/sqlalchemy/engine/base.py", line 1900, in _execute_context
    self.dialect.do_execute(
  File "/home/newton/elarian/virtual/lib/python3.8/site-packages/sqlalchemy/engine/default.py", line 736, in do_execute
    cursor.execute(statement, parameters)
sqlalchemy.exc.IntegrityError: (sqlite3.IntegrityError) UNIQUE constraint failed: incoming_request.message_id
[SQL: INSERT INTO incoming_request (status, timestamp, recipient_id, conversation_id, message_id, expiration_timestamp, origin, billable, pricing_model, processed) VALUES (?, ?, ?, ?, ?, ?, ?, ?, ?, ?)]
[parameters: ('sent', '1674656622', '254741590330', 'e8b7de634b650e9149030d9c6c01fe97', 'wamid.HBgMMjU0NzQxNTkwMzMwFQIAERgSM0RDQzNFNDA1RTBBNzU4NzMzAA==', None, 'user_initiated', True, 'CBP', 0)]
(Background on this error at: https://sqlalche.me/e/14/gkpj)
2023-01-26 12:31:26,528 - log - ERROR - (sqlite3.IntegrityError) UNIQUE constraint failed: incoming_request.message_id
[SQL: INSERT INTO incoming_request (status, timestamp, recipient_id, conversation_id, message_id, expiration_timestamp, origin, billable, pricing_model, processed) VALUES (?, ?, ?, ?, ?, ?, ?, ?, ?, ?)]
[parameters: ('sent', '1674656299', '254741590330', 'e8b7de634b650e9149030d9c6c01fe97', 'wamid.HBgMMjU0NzQxNTkwMzMwFQIAERgSQTcwN0IwODQxRDZDOTAzRUFBAA==', None, 'user_initiated', True, 'CBP', 0)]
(Background on this error at: https://sqlalche.me/e/14/gkpj)
Traceback (most recent call last):
  File "/home/newton/elarian/virtual/lib/python3.8/site-packages/sqlalchemy/engine/base.py", line 1900, in _execute_context
    self.dialect.do_execute(
  File "/home/newton/elarian/virtual/lib/python3.8/site-packages/sqlalchemy/engine/default.py", line 736, in do_execute
    cursor.execute(statement, parameters)
sqlite3.IntegrityError: UNIQUE constraint failed: incoming_request.message_id

The above exception was the direct cause of the following exception:

Traceback (most recent call last):
  File "application.py", line 78, in save_request
    db.session.commit()
  File "<string>", line 2, in commit
  File "/home/newton/elarian/virtual/lib/python3.8/site-packages/sqlalchemy/orm/session.py", line 1451, in commit
    self._transaction.commit(_to_root=self.future)
  File "/home/newton/elarian/virtual/lib/python3.8/site-packages/sqlalchemy/orm/session.py", line 829, in commit
    self._prepare_impl()
  File "/home/newton/elarian/virtual/lib/python3.8/site-packages/sqlalchemy/orm/session.py", line 808, in _prepare_impl
    self.session.flush()
  File "/home/newton/elarian/virtual/lib/python3.8/site-packages/sqlalchemy/orm/session.py", line 3444, in flush
    self._flush(objects)
  File "/home/newton/elarian/virtual/lib/python3.8/site-packages/sqlalchemy/orm/session.py", line 3584, in _flush
    transaction.rollback(_capture_exception=True)
  File "/home/newton/elarian/virtual/lib/python3.8/site-packages/sqlalchemy/util/langhelpers.py", line 70, in __exit__
    compat.raise_(
  File "/home/newton/elarian/virtual/lib/python3.8/site-packages/sqlalchemy/util/compat.py", line 211, in raise_
    raise exception
  File "/home/newton/elarian/virtual/lib/python3.8/site-packages/sqlalchemy/orm/session.py", line 3544, in _flush
    flush_context.execute()
  File "/home/newton/elarian/virtual/lib/python3.8/site-packages/sqlalchemy/orm/unitofwork.py", line 456, in execute
    rec.execute(self)
  File "/home/newton/elarian/virtual/lib/python3.8/site-packages/sqlalchemy/orm/unitofwork.py", line 630, in execute
    util.preloaded.orm_persistence.save_obj(
  File "/home/newton/elarian/virtual/lib/python3.8/site-packages/sqlalchemy/orm/persistence.py", line 245, in save_obj
    _emit_insert_statements(
  File "/home/newton/elarian/virtual/lib/python3.8/site-packages/sqlalchemy/orm/persistence.py", line 1238, in _emit_insert_statements
    result = connection._execute_20(
  File "/home/newton/elarian/virtual/lib/python3.8/site-packages/sqlalchemy/engine/base.py", line 1705, in _execute_20
    return meth(self, args_10style, kwargs_10style, execution_options)
  File "/home/newton/elarian/virtual/lib/python3.8/site-packages/sqlalchemy/sql/elements.py", line 334, in _execute_on_connection
    return connection._execute_clauseelement(
  File "/home/newton/elarian/virtual/lib/python3.8/site-packages/sqlalchemy/engine/base.py", line 1572, in _execute_clauseelement
    ret = self._execute_context(
  File "/home/newton/elarian/virtual/lib/python3.8/site-packages/sqlalchemy/engine/base.py", line 1943, in _execute_context
    self._handle_dbapi_exception(
  File "/home/newton/elarian/virtual/lib/python3.8/site-packages/sqlalchemy/engine/base.py", line 2124, in _handle_dbapi_exception
    util.raise_(
  File "/home/newton/elarian/virtual/lib/python3.8/site-packages/sqlalchemy/util/compat.py", line 211, in raise_
    raise exception
  File "/home/newton/elarian/virtual/lib/python3.8/site-packages/sqlalchemy/engine/base.py", line 1900, in _execute_context
    self.dialect.do_execute(
  File "/home/newton/elarian/virtual/lib/python3.8/site-packages/sqlalchemy/engine/default.py", line 736, in do_execute
    cursor.execute(statement, parameters)
sqlalchemy.exc.IntegrityError: (sqlite3.IntegrityError) UNIQUE constraint failed: incoming_request.message_id
[SQL: INSERT INTO incoming_request (status, timestamp, recipient_id, conversation_id, message_id, expiration_timestamp, origin, billable, pricing_model, processed) VALUES (?, ?, ?, ?, ?, ?, ?, ?, ?, ?)]
[parameters: ('sent', '1674656299', '254741590330', 'e8b7de634b650e9149030d9c6c01fe97', 'wamid.HBgMMjU0NzQxNTkwMzMwFQIAERgSQTcwN0IwODQxRDZDOTAzRUFBAA==', None, 'user_initiated', True, 'CBP', 0)]
(Background on this error at: https://sqlalche.me/e/14/gkpj)
2023-01-26 12:31:52,951 - log - ERROR - (sqlite3.IntegrityError) UNIQUE constraint failed: incoming_request.message_id
[SQL: INSERT INTO incoming_request (status, timestamp, recipient_id, conversation_id, message_id, expiration_timestamp, origin, billable, pricing_model, processed) VALUES (?, ?, ?, ?, ?, ?, ?, ?, ?, ?)]
[parameters: ('delivered', '1674653020', '254741590330', 'e8b7de634b650e9149030d9c6c01fe97', 'wamid.HBgMMjU0NzQxNTkwMzMwFQIAERgSRTI3MEUwNzBDNjEwOEI5RUZDAA==', None, 'user_initiated', True, 'CBP', 0)]
(Background on this error at: https://sqlalche.me/e/14/gkpj)
Traceback (most recent call last):
  File "/home/newton/elarian/virtual/lib/python3.8/site-packages/sqlalchemy/engine/base.py", line 1900, in _execute_context
    self.dialect.do_execute(
  File "/home/newton/elarian/virtual/lib/python3.8/site-packages/sqlalchemy/engine/default.py", line 736, in do_execute
    cursor.execute(statement, parameters)
sqlite3.IntegrityError: UNIQUE constraint failed: incoming_request.message_id

The above exception was the direct cause of the following exception:

Traceback (most recent call last):
  File "application.py", line 78, in save_request
    db.session.commit()
  File "<string>", line 2, in commit
  File "/home/newton/elarian/virtual/lib/python3.8/site-packages/sqlalchemy/orm/session.py", line 1451, in commit
    self._transaction.commit(_to_root=self.future)
  File "/home/newton/elarian/virtual/lib/python3.8/site-packages/sqlalchemy/orm/session.py", line 829, in commit
    self._prepare_impl()
  File "/home/newton/elarian/virtual/lib/python3.8/site-packages/sqlalchemy/orm/session.py", line 808, in _prepare_impl
    self.session.flush()
  File "/home/newton/elarian/virtual/lib/python3.8/site-packages/sqlalchemy/orm/session.py", line 3444, in flush
    self._flush(objects)
  File "/home/newton/elarian/virtual/lib/python3.8/site-packages/sqlalchemy/orm/session.py", line 3584, in _flush
    transaction.rollback(_capture_exception=True)
  File "/home/newton/elarian/virtual/lib/python3.8/site-packages/sqlalchemy/util/langhelpers.py", line 70, in __exit__
    compat.raise_(
  File "/home/newton/elarian/virtual/lib/python3.8/site-packages/sqlalchemy/util/compat.py", line 211, in raise_
    raise exception
  File "/home/newton/elarian/virtual/lib/python3.8/site-packages/sqlalchemy/orm/session.py", line 3544, in _flush
    flush_context.execute()
  File "/home/newton/elarian/virtual/lib/python3.8/site-packages/sqlalchemy/orm/unitofwork.py", line 456, in execute
    rec.execute(self)
  File "/home/newton/elarian/virtual/lib/python3.8/site-packages/sqlalchemy/orm/unitofwork.py", line 630, in execute
    util.preloaded.orm_persistence.save_obj(
  File "/home/newton/elarian/virtual/lib/python3.8/site-packages/sqlalchemy/orm/persistence.py", line 245, in save_obj
    _emit_insert_statements(
  File "/home/newton/elarian/virtual/lib/python3.8/site-packages/sqlalchemy/orm/persistence.py", line 1238, in _emit_insert_statements
    result = connection._execute_20(
  File "/home/newton/elarian/virtual/lib/python3.8/site-packages/sqlalchemy/engine/base.py", line 1705, in _execute_20
    return meth(self, args_10style, kwargs_10style, execution_options)
  File "/home/newton/elarian/virtual/lib/python3.8/site-packages/sqlalchemy/sql/elements.py", line 334, in _execute_on_connection
    return connection._execute_clauseelement(
  File "/home/newton/elarian/virtual/lib/python3.8/site-packages/sqlalchemy/engine/base.py", line 1572, in _execute_clauseelement
    ret = self._execute_context(
  File "/home/newton/elarian/virtual/lib/python3.8/site-packages/sqlalchemy/engine/base.py", line 1943, in _execute_context
    self._handle_dbapi_exception(
  File "/home/newton/elarian/virtual/lib/python3.8/site-packages/sqlalchemy/engine/base.py", line 2124, in _handle_dbapi_exception
    util.raise_(
  File "/home/newton/elarian/virtual/lib/python3.8/site-packages/sqlalchemy/util/compat.py", line 211, in raise_
    raise exception
  File "/home/newton/elarian/virtual/lib/python3.8/site-packages/sqlalchemy/engine/base.py", line 1900, in _execute_context
    self.dialect.do_execute(
  File "/home/newton/elarian/virtual/lib/python3.8/site-packages/sqlalchemy/engine/default.py", line 736, in do_execute
    cursor.execute(statement, parameters)
sqlalchemy.exc.IntegrityError: (sqlite3.IntegrityError) UNIQUE constraint failed: incoming_request.message_id
[SQL: INSERT INTO incoming_request (status, timestamp, recipient_id, conversation_id, message_id, expiration_timestamp, origin, billable, pricing_model, processed) VALUES (?, ?, ?, ?, ?, ?, ?, ?, ?, ?)]
[parameters: ('delivered', '1674653020', '254741590330', 'e8b7de634b650e9149030d9c6c01fe97', 'wamid.HBgMMjU0NzQxNTkwMzMwFQIAERgSRTI3MEUwNzBDNjEwOEI5RUZDAA==', None, 'user_initiated', True, 'CBP', 0)]
(Background on this error at: https://sqlalche.me/e/14/gkpj)
2023-01-26 12:32:18,539 - log - ERROR - (sqlite3.IntegrityError) UNIQUE constraint failed: incoming_request.message_id
[SQL: INSERT INTO incoming_request (status, timestamp, recipient_id, conversation_id, message_id, expiration_timestamp, origin, billable, pricing_model, processed) VALUES (?, ?, ?, ?, ?, ?, ?, ?, ?, ?)]
[parameters: ('delivered', '1674655608', '254741590330', 'e8b7de634b650e9149030d9c6c01fe97', 'wamid.HBgMMjU0NzQxNTkwMzMwFQIAERgSMTkyNkU2MDk1MkU5OUY1MDdCAA==', None, 'user_initiated', True, 'CBP', 0)]
(Background on this error at: https://sqlalche.me/e/14/gkpj)
Traceback (most recent call last):
  File "/home/newton/elarian/virtual/lib/python3.8/site-packages/sqlalchemy/engine/base.py", line 1900, in _execute_context
    self.dialect.do_execute(
  File "/home/newton/elarian/virtual/lib/python3.8/site-packages/sqlalchemy/engine/default.py", line 736, in do_execute
    cursor.execute(statement, parameters)
sqlite3.IntegrityError: UNIQUE constraint failed: incoming_request.message_id

The above exception was the direct cause of the following exception:

Traceback (most recent call last):
  File "application.py", line 78, in save_request
    db.session.commit()
  File "<string>", line 2, in commit
  File "/home/newton/elarian/virtual/lib/python3.8/site-packages/sqlalchemy/orm/session.py", line 1451, in commit
    self._transaction.commit(_to_root=self.future)
  File "/home/newton/elarian/virtual/lib/python3.8/site-packages/sqlalchemy/orm/session.py", line 829, in commit
    self._prepare_impl()
  File "/home/newton/elarian/virtual/lib/python3.8/site-packages/sqlalchemy/orm/session.py", line 808, in _prepare_impl
    self.session.flush()
  File "/home/newton/elarian/virtual/lib/python3.8/site-packages/sqlalchemy/orm/session.py", line 3444, in flush
    self._flush(objects)
  File "/home/newton/elarian/virtual/lib/python3.8/site-packages/sqlalchemy/orm/session.py", line 3584, in _flush
    transaction.rollback(_capture_exception=True)
  File "/home/newton/elarian/virtual/lib/python3.8/site-packages/sqlalchemy/util/langhelpers.py", line 70, in __exit__
    compat.raise_(
  File "/home/newton/elarian/virtual/lib/python3.8/site-packages/sqlalchemy/util/compat.py", line 211, in raise_
    raise exception
  File "/home/newton/elarian/virtual/lib/python3.8/site-packages/sqlalchemy/orm/session.py", line 3544, in _flush
    flush_context.execute()
  File "/home/newton/elarian/virtual/lib/python3.8/site-packages/sqlalchemy/orm/unitofwork.py", line 456, in execute
    rec.execute(self)
  File "/home/newton/elarian/virtual/lib/python3.8/site-packages/sqlalchemy/orm/unitofwork.py", line 630, in execute
    util.preloaded.orm_persistence.save_obj(
  File "/home/newton/elarian/virtual/lib/python3.8/site-packages/sqlalchemy/orm/persistence.py", line 245, in save_obj
    _emit_insert_statements(
  File "/home/newton/elarian/virtual/lib/python3.8/site-packages/sqlalchemy/orm/persistence.py", line 1238, in _emit_insert_statements
    result = connection._execute_20(
  File "/home/newton/elarian/virtual/lib/python3.8/site-packages/sqlalchemy/engine/base.py", line 1705, in _execute_20
    return meth(self, args_10style, kwargs_10style, execution_options)
  File "/home/newton/elarian/virtual/lib/python3.8/site-packages/sqlalchemy/sql/elements.py", line 334, in _execute_on_connection
    return connection._execute_clauseelement(
  File "/home/newton/elarian/virtual/lib/python3.8/site-packages/sqlalchemy/engine/base.py", line 1572, in _execute_clauseelement
    ret = self._execute_context(
  File "/home/newton/elarian/virtual/lib/python3.8/site-packages/sqlalchemy/engine/base.py", line 1943, in _execute_context
    self._handle_dbapi_exception(
  File "/home/newton/elarian/virtual/lib/python3.8/site-packages/sqlalchemy/engine/base.py", line 2124, in _handle_dbapi_exception
    util.raise_(
  File "/home/newton/elarian/virtual/lib/python3.8/site-packages/sqlalchemy/util/compat.py", line 211, in raise_
    raise exception
  File "/home/newton/elarian/virtual/lib/python3.8/site-packages/sqlalchemy/engine/base.py", line 1900, in _execute_context
    self.dialect.do_execute(
  File "/home/newton/elarian/virtual/lib/python3.8/site-packages/sqlalchemy/engine/default.py", line 736, in do_execute
    cursor.execute(statement, parameters)
sqlalchemy.exc.IntegrityError: (sqlite3.IntegrityError) UNIQUE constraint failed: incoming_request.message_id
[SQL: INSERT INTO incoming_request (status, timestamp, recipient_id, conversation_id, message_id, expiration_timestamp, origin, billable, pricing_model, processed) VALUES (?, ?, ?, ?, ?, ?, ?, ?, ?, ?)]
[parameters: ('delivered', '1674655608', '254741590330', 'e8b7de634b650e9149030d9c6c01fe97', 'wamid.HBgMMjU0NzQxNTkwMzMwFQIAERgSMTkyNkU2MDk1MkU5OUY1MDdCAA==', None, 'user_initiated', True, 'CBP', 0)]
(Background on this error at: https://sqlalche.me/e/14/gkpj)
2023-01-26 12:33:20,567 - log - ERROR - (sqlite3.IntegrityError) UNIQUE constraint failed: incoming_request.message_id
[SQL: INSERT INTO incoming_request (status, timestamp, recipient_id, conversation_id, message_id, expiration_timestamp, origin, billable, pricing_model, processed) VALUES (?, ?, ?, ?, ?, ?, ?, ?, ?, ?)]
[parameters: ('sent', '1674656186', '254741590330', 'e8b7de634b650e9149030d9c6c01fe97', 'wamid.HBgMMjU0NzQxNTkwMzMwFQIAERgSNEFDNjVDOTM1NTBDQjU0OTgzAA==', None, 'user_initiated', True, 'CBP', 0)]
(Background on this error at: https://sqlalche.me/e/14/gkpj)
Traceback (most recent call last):
  File "/home/newton/elarian/virtual/lib/python3.8/site-packages/sqlalchemy/engine/base.py", line 1900, in _execute_context
    self.dialect.do_execute(
  File "/home/newton/elarian/virtual/lib/python3.8/site-packages/sqlalchemy/engine/default.py", line 736, in do_execute
    cursor.execute(statement, parameters)
sqlite3.IntegrityError: UNIQUE constraint failed: incoming_request.message_id

The above exception was the direct cause of the following exception:

Traceback (most recent call last):
  File "application.py", line 78, in save_request
    db.session.commit()
  File "<string>", line 2, in commit
  File "/home/newton/elarian/virtual/lib/python3.8/site-packages/sqlalchemy/orm/session.py", line 1451, in commit
    self._transaction.commit(_to_root=self.future)
  File "/home/newton/elarian/virtual/lib/python3.8/site-packages/sqlalchemy/orm/session.py", line 829, in commit
    self._prepare_impl()
  File "/home/newton/elarian/virtual/lib/python3.8/site-packages/sqlalchemy/orm/session.py", line 808, in _prepare_impl
    self.session.flush()
  File "/home/newton/elarian/virtual/lib/python3.8/site-packages/sqlalchemy/orm/session.py", line 3444, in flush
    self._flush(objects)
  File "/home/newton/elarian/virtual/lib/python3.8/site-packages/sqlalchemy/orm/session.py", line 3584, in _flush
    transaction.rollback(_capture_exception=True)
  File "/home/newton/elarian/virtual/lib/python3.8/site-packages/sqlalchemy/util/langhelpers.py", line 70, in __exit__
    compat.raise_(
  File "/home/newton/elarian/virtual/lib/python3.8/site-packages/sqlalchemy/util/compat.py", line 211, in raise_
    raise exception
  File "/home/newton/elarian/virtual/lib/python3.8/site-packages/sqlalchemy/orm/session.py", line 3544, in _flush
    flush_context.execute()
  File "/home/newton/elarian/virtual/lib/python3.8/site-packages/sqlalchemy/orm/unitofwork.py", line 456, in execute
    rec.execute(self)
  File "/home/newton/elarian/virtual/lib/python3.8/site-packages/sqlalchemy/orm/unitofwork.py", line 630, in execute
    util.preloaded.orm_persistence.save_obj(
  File "/home/newton/elarian/virtual/lib/python3.8/site-packages/sqlalchemy/orm/persistence.py", line 245, in save_obj
    _emit_insert_statements(
  File "/home/newton/elarian/virtual/lib/python3.8/site-packages/sqlalchemy/orm/persistence.py", line 1238, in _emit_insert_statements
    result = connection._execute_20(
  File "/home/newton/elarian/virtual/lib/python3.8/site-packages/sqlalchemy/engine/base.py", line 1705, in _execute_20
    return meth(self, args_10style, kwargs_10style, execution_options)
  File "/home/newton/elarian/virtual/lib/python3.8/site-packages/sqlalchemy/sql/elements.py", line 334, in _execute_on_connection
    return connection._execute_clauseelement(
  File "/home/newton/elarian/virtual/lib/python3.8/site-packages/sqlalchemy/engine/base.py", line 1572, in _execute_clauseelement
    ret = self._execute_context(
  File "/home/newton/elarian/virtual/lib/python3.8/site-packages/sqlalchemy/engine/base.py", line 1943, in _execute_context
    self._handle_dbapi_exception(
  File "/home/newton/elarian/virtual/lib/python3.8/site-packages/sqlalchemy/engine/base.py", line 2124, in _handle_dbapi_exception
    util.raise_(
  File "/home/newton/elarian/virtual/lib/python3.8/site-packages/sqlalchemy/util/compat.py", line 211, in raise_
    raise exception
  File "/home/newton/elarian/virtual/lib/python3.8/site-packages/sqlalchemy/engine/base.py", line 1900, in _execute_context
    self.dialect.do_execute(
  File "/home/newton/elarian/virtual/lib/python3.8/site-packages/sqlalchemy/engine/default.py", line 736, in do_execute
    cursor.execute(statement, parameters)
sqlalchemy.exc.IntegrityError: (sqlite3.IntegrityError) UNIQUE constraint failed: incoming_request.message_id
[SQL: INSERT INTO incoming_request (status, timestamp, recipient_id, conversation_id, message_id, expiration_timestamp, origin, billable, pricing_model, processed) VALUES (?, ?, ?, ?, ?, ?, ?, ?, ?, ?)]
[parameters: ('sent', '1674656186', '254741590330', 'e8b7de634b650e9149030d9c6c01fe97', 'wamid.HBgMMjU0NzQxNTkwMzMwFQIAERgSNEFDNjVDOTM1NTBDQjU0OTgzAA==', None, 'user_initiated', True, 'CBP', 0)]
(Background on this error at: https://sqlalche.me/e/14/gkpj)
2023-01-26 12:34:24,654 - log - ERROR - (sqlite3.IntegrityError) UNIQUE constraint failed: incoming_request.message_id
[SQL: INSERT INTO incoming_request (status, timestamp, recipient_id, conversation_id, message_id, expiration_timestamp, origin, billable, pricing_model, processed) VALUES (?, ?, ?, ?, ?, ?, ?, ?, ?, ?)]
[parameters: ('sent', '1674653503', '254741590330', 'e8b7de634b650e9149030d9c6c01fe97', 'wamid.HBgMMjU0NzQxNTkwMzMwFQIAERgSNTA2QzkwRDU1NjREOEUzODEwAA==', None, 'user_initiated', True, 'CBP', 0)]
(Background on this error at: https://sqlalche.me/e/14/gkpj)
Traceback (most recent call last):
  File "/home/newton/elarian/virtual/lib/python3.8/site-packages/sqlalchemy/engine/base.py", line 1900, in _execute_context
    self.dialect.do_execute(
  File "/home/newton/elarian/virtual/lib/python3.8/site-packages/sqlalchemy/engine/default.py", line 736, in do_execute
    cursor.execute(statement, parameters)
sqlite3.IntegrityError: UNIQUE constraint failed: incoming_request.message_id

The above exception was the direct cause of the following exception:

Traceback (most recent call last):
  File "application.py", line 78, in save_request
    db.session.commit()
  File "<string>", line 2, in commit
  File "/home/newton/elarian/virtual/lib/python3.8/site-packages/sqlalchemy/orm/session.py", line 1451, in commit
    self._transaction.commit(_to_root=self.future)
  File "/home/newton/elarian/virtual/lib/python3.8/site-packages/sqlalchemy/orm/session.py", line 829, in commit
    self._prepare_impl()
  File "/home/newton/elarian/virtual/lib/python3.8/site-packages/sqlalchemy/orm/session.py", line 808, in _prepare_impl
    self.session.flush()
  File "/home/newton/elarian/virtual/lib/python3.8/site-packages/sqlalchemy/orm/session.py", line 3444, in flush
    self._flush(objects)
  File "/home/newton/elarian/virtual/lib/python3.8/site-packages/sqlalchemy/orm/session.py", line 3584, in _flush
    transaction.rollback(_capture_exception=True)
  File "/home/newton/elarian/virtual/lib/python3.8/site-packages/sqlalchemy/util/langhelpers.py", line 70, in __exit__
    compat.raise_(
  File "/home/newton/elarian/virtual/lib/python3.8/site-packages/sqlalchemy/util/compat.py", line 211, in raise_
    raise exception
  File "/home/newton/elarian/virtual/lib/python3.8/site-packages/sqlalchemy/orm/session.py", line 3544, in _flush
    flush_context.execute()
  File "/home/newton/elarian/virtual/lib/python3.8/site-packages/sqlalchemy/orm/unitofwork.py", line 456, in execute
    rec.execute(self)
  File "/home/newton/elarian/virtual/lib/python3.8/site-packages/sqlalchemy/orm/unitofwork.py", line 630, in execute
    util.preloaded.orm_persistence.save_obj(
  File "/home/newton/elarian/virtual/lib/python3.8/site-packages/sqlalchemy/orm/persistence.py", line 245, in save_obj
    _emit_insert_statements(
  File "/home/newton/elarian/virtual/lib/python3.8/site-packages/sqlalchemy/orm/persistence.py", line 1238, in _emit_insert_statements
    result = connection._execute_20(
  File "/home/newton/elarian/virtual/lib/python3.8/site-packages/sqlalchemy/engine/base.py", line 1705, in _execute_20
    return meth(self, args_10style, kwargs_10style, execution_options)
  File "/home/newton/elarian/virtual/lib/python3.8/site-packages/sqlalchemy/sql/elements.py", line 334, in _execute_on_connection
    return connection._execute_clauseelement(
  File "/home/newton/elarian/virtual/lib/python3.8/site-packages/sqlalchemy/engine/base.py", line 1572, in _execute_clauseelement
    ret = self._execute_context(
  File "/home/newton/elarian/virtual/lib/python3.8/site-packages/sqlalchemy/engine/base.py", line 1943, in _execute_context
    self._handle_dbapi_exception(
  File "/home/newton/elarian/virtual/lib/python3.8/site-packages/sqlalchemy/engine/base.py", line 2124, in _handle_dbapi_exception
    util.raise_(
  File "/home/newton/elarian/virtual/lib/python3.8/site-packages/sqlalchemy/util/compat.py", line 211, in raise_
    raise exception
  File "/home/newton/elarian/virtual/lib/python3.8/site-packages/sqlalchemy/engine/base.py", line 1900, in _execute_context
    self.dialect.do_execute(
  File "/home/newton/elarian/virtual/lib/python3.8/site-packages/sqlalchemy/engine/default.py", line 736, in do_execute
    cursor.execute(statement, parameters)
sqlalchemy.exc.IntegrityError: (sqlite3.IntegrityError) UNIQUE constraint failed: incoming_request.message_id
[SQL: INSERT INTO incoming_request (status, timestamp, recipient_id, conversation_id, message_id, expiration_timestamp, origin, billable, pricing_model, processed) VALUES (?, ?, ?, ?, ?, ?, ?, ?, ?, ?)]
[parameters: ('sent', '1674653503', '254741590330', 'e8b7de634b650e9149030d9c6c01fe97', 'wamid.HBgMMjU0NzQxNTkwMzMwFQIAERgSNTA2QzkwRDU1NjREOEUzODEwAA==', None, 'user_initiated', True, 'CBP', 0)]
(Background on this error at: https://sqlalche.me/e/14/gkpj)
2023-01-26 12:37:12,508 - log - ERROR - (sqlite3.IntegrityError) UNIQUE constraint failed: incoming_request.message_id
[SQL: INSERT INTO incoming_request (status, timestamp, recipient_id, conversation_id, message_id, expiration_timestamp, origin, billable, pricing_model, processed) VALUES (?, ?, ?, ?, ?, ?, ?, ?, ?, ?)]
[parameters: ('delivered', '1674656680', '254741590330', 'e8b7de634b650e9149030d9c6c01fe97', 'wamid.HBgMMjU0NzQxNTkwMzMwFQIAERgSREEzMEU5N0ZGOThDMzg1NEFEAA==', None, 'user_initiated', True, 'CBP', 0)]
(Background on this error at: https://sqlalche.me/e/14/gkpj)
Traceback (most recent call last):
  File "/home/newton/elarian/virtual/lib/python3.8/site-packages/sqlalchemy/engine/base.py", line 1900, in _execute_context
    self.dialect.do_execute(
  File "/home/newton/elarian/virtual/lib/python3.8/site-packages/sqlalchemy/engine/default.py", line 736, in do_execute
    cursor.execute(statement, parameters)
sqlite3.IntegrityError: UNIQUE constraint failed: incoming_request.message_id

The above exception was the direct cause of the following exception:

Traceback (most recent call last):
  File "application.py", line 78, in save_request
    db.session.commit()
  File "<string>", line 2, in commit
  File "/home/newton/elarian/virtual/lib/python3.8/site-packages/sqlalchemy/orm/session.py", line 1451, in commit
    self._transaction.commit(_to_root=self.future)
  File "/home/newton/elarian/virtual/lib/python3.8/site-packages/sqlalchemy/orm/session.py", line 829, in commit
    self._prepare_impl()
  File "/home/newton/elarian/virtual/lib/python3.8/site-packages/sqlalchemy/orm/session.py", line 808, in _prepare_impl
    self.session.flush()
  File "/home/newton/elarian/virtual/lib/python3.8/site-packages/sqlalchemy/orm/session.py", line 3444, in flush
    self._flush(objects)
  File "/home/newton/elarian/virtual/lib/python3.8/site-packages/sqlalchemy/orm/session.py", line 3584, in _flush
    transaction.rollback(_capture_exception=True)
  File "/home/newton/elarian/virtual/lib/python3.8/site-packages/sqlalchemy/util/langhelpers.py", line 70, in __exit__
    compat.raise_(
  File "/home/newton/elarian/virtual/lib/python3.8/site-packages/sqlalchemy/util/compat.py", line 211, in raise_
    raise exception
  File "/home/newton/elarian/virtual/lib/python3.8/site-packages/sqlalchemy/orm/session.py", line 3544, in _flush
    flush_context.execute()
  File "/home/newton/elarian/virtual/lib/python3.8/site-packages/sqlalchemy/orm/unitofwork.py", line 456, in execute
    rec.execute(self)
  File "/home/newton/elarian/virtual/lib/python3.8/site-packages/sqlalchemy/orm/unitofwork.py", line 630, in execute
    util.preloaded.orm_persistence.save_obj(
  File "/home/newton/elarian/virtual/lib/python3.8/site-packages/sqlalchemy/orm/persistence.py", line 245, in save_obj
    _emit_insert_statements(
  File "/home/newton/elarian/virtual/lib/python3.8/site-packages/sqlalchemy/orm/persistence.py", line 1238, in _emit_insert_statements
    result = connection._execute_20(
  File "/home/newton/elarian/virtual/lib/python3.8/site-packages/sqlalchemy/engine/base.py", line 1705, in _execute_20
    return meth(self, args_10style, kwargs_10style, execution_options)
  File "/home/newton/elarian/virtual/lib/python3.8/site-packages/sqlalchemy/sql/elements.py", line 334, in _execute_on_connection
    return connection._execute_clauseelement(
  File "/home/newton/elarian/virtual/lib/python3.8/site-packages/sqlalchemy/engine/base.py", line 1572, in _execute_clauseelement
    ret = self._execute_context(
  File "/home/newton/elarian/virtual/lib/python3.8/site-packages/sqlalchemy/engine/base.py", line 1943, in _execute_context
    self._handle_dbapi_exception(
  File "/home/newton/elarian/virtual/lib/python3.8/site-packages/sqlalchemy/engine/base.py", line 2124, in _handle_dbapi_exception
    util.raise_(
  File "/home/newton/elarian/virtual/lib/python3.8/site-packages/sqlalchemy/util/compat.py", line 211, in raise_
    raise exception
  File "/home/newton/elarian/virtual/lib/python3.8/site-packages/sqlalchemy/engine/base.py", line 1900, in _execute_context
    self.dialect.do_execute(
  File "/home/newton/elarian/virtual/lib/python3.8/site-packages/sqlalchemy/engine/default.py", line 736, in do_execute
    cursor.execute(statement, parameters)
sqlalchemy.exc.IntegrityError: (sqlite3.IntegrityError) UNIQUE constraint failed: incoming_request.message_id
[SQL: INSERT INTO incoming_request (status, timestamp, recipient_id, conversation_id, message_id, expiration_timestamp, origin, billable, pricing_model, processed) VALUES (?, ?, ?, ?, ?, ?, ?, ?, ?, ?)]
[parameters: ('delivered', '1674656680', '254741590330', 'e8b7de634b650e9149030d9c6c01fe97', 'wamid.HBgMMjU0NzQxNTkwMzMwFQIAERgSREEzMEU5N0ZGOThDMzg1NEFEAA==', None, 'user_initiated', True, 'CBP', 0)]
(Background on this error at: https://sqlalche.me/e/14/gkpj)
2023-01-26 12:37:14,176 - log - ERROR - (sqlite3.IntegrityError) UNIQUE constraint failed: incoming_request.message_id
[SQL: INSERT INTO incoming_request (status, timestamp, recipient_id, conversation_id, message_id, expiration_timestamp, origin, billable, pricing_model, processed) VALUES (?, ?, ?, ?, ?, ?, ?, ?, ?, ?)]
[parameters: ('delivered', '1674656515', '254741590330', 'e8b7de634b650e9149030d9c6c01fe97', 'wamid.HBgMMjU0NzQxNTkwMzMwFQIAERgSMjRFMEU0QzlCQ0MxRTc1RDJBAA==', None, 'user_initiated', True, 'CBP', 0)]
(Background on this error at: https://sqlalche.me/e/14/gkpj)
Traceback (most recent call last):
  File "/home/newton/elarian/virtual/lib/python3.8/site-packages/sqlalchemy/engine/base.py", line 1900, in _execute_context
    self.dialect.do_execute(
  File "/home/newton/elarian/virtual/lib/python3.8/site-packages/sqlalchemy/engine/default.py", line 736, in do_execute
    cursor.execute(statement, parameters)
sqlite3.IntegrityError: UNIQUE constraint failed: incoming_request.message_id

The above exception was the direct cause of the following exception:

Traceback (most recent call last):
  File "application.py", line 78, in save_request
    db.session.commit()
  File "<string>", line 2, in commit
  File "/home/newton/elarian/virtual/lib/python3.8/site-packages/sqlalchemy/orm/session.py", line 1451, in commit
    self._transaction.commit(_to_root=self.future)
  File "/home/newton/elarian/virtual/lib/python3.8/site-packages/sqlalchemy/orm/session.py", line 829, in commit
    self._prepare_impl()
  File "/home/newton/elarian/virtual/lib/python3.8/site-packages/sqlalchemy/orm/session.py", line 808, in _prepare_impl
    self.session.flush()
  File "/home/newton/elarian/virtual/lib/python3.8/site-packages/sqlalchemy/orm/session.py", line 3444, in flush
    self._flush(objects)
  File "/home/newton/elarian/virtual/lib/python3.8/site-packages/sqlalchemy/orm/session.py", line 3584, in _flush
    transaction.rollback(_capture_exception=True)
  File "/home/newton/elarian/virtual/lib/python3.8/site-packages/sqlalchemy/util/langhelpers.py", line 70, in __exit__
    compat.raise_(
  File "/home/newton/elarian/virtual/lib/python3.8/site-packages/sqlalchemy/util/compat.py", line 211, in raise_
    raise exception
  File "/home/newton/elarian/virtual/lib/python3.8/site-packages/sqlalchemy/orm/session.py", line 3544, in _flush
    flush_context.execute()
  File "/home/newton/elarian/virtual/lib/python3.8/site-packages/sqlalchemy/orm/unitofwork.py", line 456, in execute
    rec.execute(self)
  File "/home/newton/elarian/virtual/lib/python3.8/site-packages/sqlalchemy/orm/unitofwork.py", line 630, in execute
    util.preloaded.orm_persistence.save_obj(
  File "/home/newton/elarian/virtual/lib/python3.8/site-packages/sqlalchemy/orm/persistence.py", line 245, in save_obj
    _emit_insert_statements(
  File "/home/newton/elarian/virtual/lib/python3.8/site-packages/sqlalchemy/orm/persistence.py", line 1238, in _emit_insert_statements
    result = connection._execute_20(
  File "/home/newton/elarian/virtual/lib/python3.8/site-packages/sqlalchemy/engine/base.py", line 1705, in _execute_20
    return meth(self, args_10style, kwargs_10style, execution_options)
  File "/home/newton/elarian/virtual/lib/python3.8/site-packages/sqlalchemy/sql/elements.py", line 334, in _execute_on_connection
    return connection._execute_clauseelement(
  File "/home/newton/elarian/virtual/lib/python3.8/site-packages/sqlalchemy/engine/base.py", line 1572, in _execute_clauseelement
    ret = self._execute_context(
  File "/home/newton/elarian/virtual/lib/python3.8/site-packages/sqlalchemy/engine/base.py", line 1943, in _execute_context
    self._handle_dbapi_exception(
  File "/home/newton/elarian/virtual/lib/python3.8/site-packages/sqlalchemy/engine/base.py", line 2124, in _handle_dbapi_exception
    util.raise_(
  File "/home/newton/elarian/virtual/lib/python3.8/site-packages/sqlalchemy/util/compat.py", line 211, in raise_
    raise exception
  File "/home/newton/elarian/virtual/lib/python3.8/site-packages/sqlalchemy/engine/base.py", line 1900, in _execute_context
    self.dialect.do_execute(
  File "/home/newton/elarian/virtual/lib/python3.8/site-packages/sqlalchemy/engine/default.py", line 736, in do_execute
    cursor.execute(statement, parameters)
sqlalchemy.exc.IntegrityError: (sqlite3.IntegrityError) UNIQUE constraint failed: incoming_request.message_id
[SQL: INSERT INTO incoming_request (status, timestamp, recipient_id, conversation_id, message_id, expiration_timestamp, origin, billable, pricing_model, processed) VALUES (?, ?, ?, ?, ?, ?, ?, ?, ?, ?)]
[parameters: ('delivered', '1674656515', '254741590330', 'e8b7de634b650e9149030d9c6c01fe97', 'wamid.HBgMMjU0NzQxNTkwMzMwFQIAERgSMjRFMEU0QzlCQ0MxRTc1RDJBAA==', None, 'user_initiated', True, 'CBP', 0)]
(Background on this error at: https://sqlalche.me/e/14/gkpj)
2023-01-26 12:40:14,060 - log - ERROR - (sqlite3.IntegrityError) UNIQUE constraint failed: incoming_request.message_id
[SQL: INSERT INTO incoming_request (status, timestamp, recipient_id, conversation_id, message_id, expiration_timestamp, origin, billable, pricing_model, processed) VALUES (?, ?, ?, ?, ?, ?, ?, ?, ?, ?)]
[parameters: ('sent', '1674651901', '254741590330', 'e8b7de634b650e9149030d9c6c01fe97', 'wamid.HBgMMjU0NzQxNTkwMzMwFQIAERgSQzZBRkRBMEZCODRBMDVFQUQ3AA==', None, 'user_initiated', True, 'CBP', 0)]
(Background on this error at: https://sqlalche.me/e/14/gkpj)
Traceback (most recent call last):
  File "/home/newton/elarian/virtual/lib/python3.8/site-packages/sqlalchemy/engine/base.py", line 1900, in _execute_context
    self.dialect.do_execute(
  File "/home/newton/elarian/virtual/lib/python3.8/site-packages/sqlalchemy/engine/default.py", line 736, in do_execute
    cursor.execute(statement, parameters)
sqlite3.IntegrityError: UNIQUE constraint failed: incoming_request.message_id

The above exception was the direct cause of the following exception:

Traceback (most recent call last):
  File "application.py", line 78, in save_request
    db.session.commit()
  File "<string>", line 2, in commit
  File "/home/newton/elarian/virtual/lib/python3.8/site-packages/sqlalchemy/orm/session.py", line 1451, in commit
    self._transaction.commit(_to_root=self.future)
  File "/home/newton/elarian/virtual/lib/python3.8/site-packages/sqlalchemy/orm/session.py", line 829, in commit
    self._prepare_impl()
  File "/home/newton/elarian/virtual/lib/python3.8/site-packages/sqlalchemy/orm/session.py", line 808, in _prepare_impl
    self.session.flush()
  File "/home/newton/elarian/virtual/lib/python3.8/site-packages/sqlalchemy/orm/session.py", line 3444, in flush
    self._flush(objects)
  File "/home/newton/elarian/virtual/lib/python3.8/site-packages/sqlalchemy/orm/session.py", line 3584, in _flush
    transaction.rollback(_capture_exception=True)
  File "/home/newton/elarian/virtual/lib/python3.8/site-packages/sqlalchemy/util/langhelpers.py", line 70, in __exit__
    compat.raise_(
  File "/home/newton/elarian/virtual/lib/python3.8/site-packages/sqlalchemy/util/compat.py", line 211, in raise_
    raise exception
  File "/home/newton/elarian/virtual/lib/python3.8/site-packages/sqlalchemy/orm/session.py", line 3544, in _flush
    flush_context.execute()
  File "/home/newton/elarian/virtual/lib/python3.8/site-packages/sqlalchemy/orm/unitofwork.py", line 456, in execute
    rec.execute(self)
  File "/home/newton/elarian/virtual/lib/python3.8/site-packages/sqlalchemy/orm/unitofwork.py", line 630, in execute
    util.preloaded.orm_persistence.save_obj(
  File "/home/newton/elarian/virtual/lib/python3.8/site-packages/sqlalchemy/orm/persistence.py", line 245, in save_obj
    _emit_insert_statements(
  File "/home/newton/elarian/virtual/lib/python3.8/site-packages/sqlalchemy/orm/persistence.py", line 1238, in _emit_insert_statements
    result = connection._execute_20(
  File "/home/newton/elarian/virtual/lib/python3.8/site-packages/sqlalchemy/engine/base.py", line 1705, in _execute_20
    return meth(self, args_10style, kwargs_10style, execution_options)
  File "/home/newton/elarian/virtual/lib/python3.8/site-packages/sqlalchemy/sql/elements.py", line 334, in _execute_on_connection
    return connection._execute_clauseelement(
  File "/home/newton/elarian/virtual/lib/python3.8/site-packages/sqlalchemy/engine/base.py", line 1572, in _execute_clauseelement
    ret = self._execute_context(
  File "/home/newton/elarian/virtual/lib/python3.8/site-packages/sqlalchemy/engine/base.py", line 1943, in _execute_context
    self._handle_dbapi_exception(
  File "/home/newton/elarian/virtual/lib/python3.8/site-packages/sqlalchemy/engine/base.py", line 2124, in _handle_dbapi_exception
    util.raise_(
  File "/home/newton/elarian/virtual/lib/python3.8/site-packages/sqlalchemy/util/compat.py", line 211, in raise_
    raise exception
  File "/home/newton/elarian/virtual/lib/python3.8/site-packages/sqlalchemy/engine/base.py", line 1900, in _execute_context
    self.dialect.do_execute(
  File "/home/newton/elarian/virtual/lib/python3.8/site-packages/sqlalchemy/engine/default.py", line 736, in do_execute
    cursor.execute(statement, parameters)
sqlalchemy.exc.IntegrityError: (sqlite3.IntegrityError) UNIQUE constraint failed: incoming_request.message_id
[SQL: INSERT INTO incoming_request (status, timestamp, recipient_id, conversation_id, message_id, expiration_timestamp, origin, billable, pricing_model, processed) VALUES (?, ?, ?, ?, ?, ?, ?, ?, ?, ?)]
[parameters: ('sent', '1674651901', '254741590330', 'e8b7de634b650e9149030d9c6c01fe97', 'wamid.HBgMMjU0NzQxNTkwMzMwFQIAERgSQzZBRkRBMEZCODRBMDVFQUQ3AA==', None, 'user_initiated', True, 'CBP', 0)]
(Background on this error at: https://sqlalche.me/e/14/gkpj)
2023-01-26 12:41:18,512 - log - ERROR - 'NoneType' object has no attribute 'processed'
Traceback (most recent call last):
  File "application.py", line 173, in heyoo
    processed_message = IncomingRequest.query.filter_by(message_id=message_id,  processed=False).first()
AttributeError: 'NoneType' object has no attribute 'processed'
2023-01-26 12:41:43,872 - log - ERROR - (sqlite3.IntegrityError) UNIQUE constraint failed: incoming_request.message_id
[SQL: INSERT INTO incoming_request (status, timestamp, recipient_id, conversation_id, message_id, expiration_timestamp, origin, billable, pricing_model, processed) VALUES (?, ?, ?, ?, ?, ?, ?, ?, ?, ?)]
[parameters: ('sent', '1674652147', '254741590330', 'e8b7de634b650e9149030d9c6c01fe97', 'wamid.HBgMMjU0NzQxNTkwMzMwFQIAERgSNjc0NDNCQTdFMUVCNkExRjQyAA==', None, 'user_initiated', True, 'CBP', 0)]
(Background on this error at: https://sqlalche.me/e/14/gkpj)
Traceback (most recent call last):
  File "/home/newton/elarian/virtual/lib/python3.8/site-packages/sqlalchemy/engine/base.py", line 1900, in _execute_context
    self.dialect.do_execute(
  File "/home/newton/elarian/virtual/lib/python3.8/site-packages/sqlalchemy/engine/default.py", line 736, in do_execute
    cursor.execute(statement, parameters)
sqlite3.IntegrityError: UNIQUE constraint failed: incoming_request.message_id

The above exception was the direct cause of the following exception:

Traceback (most recent call last):
  File "application.py", line 78, in save_request
    db.session.commit()
  File "<string>", line 2, in commit
  File "/home/newton/elarian/virtual/lib/python3.8/site-packages/sqlalchemy/orm/session.py", line 1451, in commit
    self._transaction.commit(_to_root=self.future)
  File "/home/newton/elarian/virtual/lib/python3.8/site-packages/sqlalchemy/orm/session.py", line 829, in commit
    self._prepare_impl()
  File "/home/newton/elarian/virtual/lib/python3.8/site-packages/sqlalchemy/orm/session.py", line 808, in _prepare_impl
    self.session.flush()
  File "/home/newton/elarian/virtual/lib/python3.8/site-packages/sqlalchemy/orm/session.py", line 3444, in flush
    self._flush(objects)
  File "/home/newton/elarian/virtual/lib/python3.8/site-packages/sqlalchemy/orm/session.py", line 3584, in _flush
    transaction.rollback(_capture_exception=True)
  File "/home/newton/elarian/virtual/lib/python3.8/site-packages/sqlalchemy/util/langhelpers.py", line 70, in __exit__
    compat.raise_(
  File "/home/newton/elarian/virtual/lib/python3.8/site-packages/sqlalchemy/util/compat.py", line 211, in raise_
    raise exception
  File "/home/newton/elarian/virtual/lib/python3.8/site-packages/sqlalchemy/orm/session.py", line 3544, in _flush
    flush_context.execute()
  File "/home/newton/elarian/virtual/lib/python3.8/site-packages/sqlalchemy/orm/unitofwork.py", line 456, in execute
    rec.execute(self)
  File "/home/newton/elarian/virtual/lib/python3.8/site-packages/sqlalchemy/orm/unitofwork.py", line 630, in execute
    util.preloaded.orm_persistence.save_obj(
  File "/home/newton/elarian/virtual/lib/python3.8/site-packages/sqlalchemy/orm/persistence.py", line 245, in save_obj
    _emit_insert_statements(
  File "/home/newton/elarian/virtual/lib/python3.8/site-packages/sqlalchemy/orm/persistence.py", line 1238, in _emit_insert_statements
    result = connection._execute_20(
  File "/home/newton/elarian/virtual/lib/python3.8/site-packages/sqlalchemy/engine/base.py", line 1705, in _execute_20
    return meth(self, args_10style, kwargs_10style, execution_options)
  File "/home/newton/elarian/virtual/lib/python3.8/site-packages/sqlalchemy/sql/elements.py", line 334, in _execute_on_connection
    return connection._execute_clauseelement(
  File "/home/newton/elarian/virtual/lib/python3.8/site-packages/sqlalchemy/engine/base.py", line 1572, in _execute_clauseelement
    ret = self._execute_context(
  File "/home/newton/elarian/virtual/lib/python3.8/site-packages/sqlalchemy/engine/base.py", line 1943, in _execute_context
    self._handle_dbapi_exception(
  File "/home/newton/elarian/virtual/lib/python3.8/site-packages/sqlalchemy/engine/base.py", line 2124, in _handle_dbapi_exception
    util.raise_(
  File "/home/newton/elarian/virtual/lib/python3.8/site-packages/sqlalchemy/util/compat.py", line 211, in raise_
    raise exception
  File "/home/newton/elarian/virtual/lib/python3.8/site-packages/sqlalchemy/engine/base.py", line 1900, in _execute_context
    self.dialect.do_execute(
  File "/home/newton/elarian/virtual/lib/python3.8/site-packages/sqlalchemy/engine/default.py", line 736, in do_execute
    cursor.execute(statement, parameters)
sqlalchemy.exc.IntegrityError: (sqlite3.IntegrityError) UNIQUE constraint failed: incoming_request.message_id
[SQL: INSERT INTO incoming_request (status, timestamp, recipient_id, conversation_id, message_id, expiration_timestamp, origin, billable, pricing_model, processed) VALUES (?, ?, ?, ?, ?, ?, ?, ?, ?, ?)]
[parameters: ('sent', '1674652147', '254741590330', 'e8b7de634b650e9149030d9c6c01fe97', 'wamid.HBgMMjU0NzQxNTkwMzMwFQIAERgSNjc0NDNCQTdFMUVCNkExRjQyAA==', None, 'user_initiated', True, 'CBP', 0)]
(Background on this error at: https://sqlalche.me/e/14/gkpj)
2023-01-26 12:45:08,949 - log - ERROR - (sqlite3.IntegrityError) UNIQUE constraint failed: incoming_request.message_id
[SQL: INSERT INTO incoming_request (status, timestamp, recipient_id, conversation_id, message_id, expiration_timestamp, origin, billable, pricing_model, processed) VALUES (?, ?, ?, ?, ?, ?, ?, ?, ?, ?)]
[parameters: ('delivered', '1674657251', '254741590330', 'e8b7de634b650e9149030d9c6c01fe97', 'wamid.HBgMMjU0NzQxNTkwMzMwFQIAERgSNTQwMDkxMDdCN0I5QjUyRUE4AA==', None, 'user_initiated', True, 'CBP', 0)]
(Background on this error at: https://sqlalche.me/e/14/gkpj)
Traceback (most recent call last):
  File "/home/newton/elarian/virtual/lib/python3.8/site-packages/sqlalchemy/engine/base.py", line 1900, in _execute_context
    self.dialect.do_execute(
  File "/home/newton/elarian/virtual/lib/python3.8/site-packages/sqlalchemy/engine/default.py", line 736, in do_execute
    cursor.execute(statement, parameters)
sqlite3.IntegrityError: UNIQUE constraint failed: incoming_request.message_id

The above exception was the direct cause of the following exception:

Traceback (most recent call last):
  File "application.py", line 78, in save_request
    db.session.commit()
  File "<string>", line 2, in commit
  File "/home/newton/elarian/virtual/lib/python3.8/site-packages/sqlalchemy/orm/session.py", line 1451, in commit
    self._transaction.commit(_to_root=self.future)
  File "/home/newton/elarian/virtual/lib/python3.8/site-packages/sqlalchemy/orm/session.py", line 829, in commit
    self._prepare_impl()
  File "/home/newton/elarian/virtual/lib/python3.8/site-packages/sqlalchemy/orm/session.py", line 808, in _prepare_impl
    self.session.flush()
  File "/home/newton/elarian/virtual/lib/python3.8/site-packages/sqlalchemy/orm/session.py", line 3444, in flush
    self._flush(objects)
  File "/home/newton/elarian/virtual/lib/python3.8/site-packages/sqlalchemy/orm/session.py", line 3584, in _flush
    transaction.rollback(_capture_exception=True)
  File "/home/newton/elarian/virtual/lib/python3.8/site-packages/sqlalchemy/util/langhelpers.py", line 70, in __exit__
    compat.raise_(
  File "/home/newton/elarian/virtual/lib/python3.8/site-packages/sqlalchemy/util/compat.py", line 211, in raise_
    raise exception
  File "/home/newton/elarian/virtual/lib/python3.8/site-packages/sqlalchemy/orm/session.py", line 3544, in _flush
    flush_context.execute()
  File "/home/newton/elarian/virtual/lib/python3.8/site-packages/sqlalchemy/orm/unitofwork.py", line 456, in execute
    rec.execute(self)
  File "/home/newton/elarian/virtual/lib/python3.8/site-packages/sqlalchemy/orm/unitofwork.py", line 630, in execute
    util.preloaded.orm_persistence.save_obj(
  File "/home/newton/elarian/virtual/lib/python3.8/site-packages/sqlalchemy/orm/persistence.py", line 245, in save_obj
    _emit_insert_statements(
  File "/home/newton/elarian/virtual/lib/python3.8/site-packages/sqlalchemy/orm/persistence.py", line 1238, in _emit_insert_statements
    result = connection._execute_20(
  File "/home/newton/elarian/virtual/lib/python3.8/site-packages/sqlalchemy/engine/base.py", line 1705, in _execute_20
    return meth(self, args_10style, kwargs_10style, execution_options)
  File "/home/newton/elarian/virtual/lib/python3.8/site-packages/sqlalchemy/sql/elements.py", line 334, in _execute_on_connection
    return connection._execute_clauseelement(
  File "/home/newton/elarian/virtual/lib/python3.8/site-packages/sqlalchemy/engine/base.py", line 1572, in _execute_clauseelement
    ret = self._execute_context(
  File "/home/newton/elarian/virtual/lib/python3.8/site-packages/sqlalchemy/engine/base.py", line 1943, in _execute_context
    self._handle_dbapi_exception(
  File "/home/newton/elarian/virtual/lib/python3.8/site-packages/sqlalchemy/engine/base.py", line 2124, in _handle_dbapi_exception
    util.raise_(
  File "/home/newton/elarian/virtual/lib/python3.8/site-packages/sqlalchemy/util/compat.py", line 211, in raise_
    raise exception
  File "/home/newton/elarian/virtual/lib/python3.8/site-packages/sqlalchemy/engine/base.py", line 1900, in _execute_context
    self.dialect.do_execute(
  File "/home/newton/elarian/virtual/lib/python3.8/site-packages/sqlalchemy/engine/default.py", line 736, in do_execute
    cursor.execute(statement, parameters)
sqlalchemy.exc.IntegrityError: (sqlite3.IntegrityError) UNIQUE constraint failed: incoming_request.message_id
[SQL: INSERT INTO incoming_request (status, timestamp, recipient_id, conversation_id, message_id, expiration_timestamp, origin, billable, pricing_model, processed) VALUES (?, ?, ?, ?, ?, ?, ?, ?, ?, ?)]
[parameters: ('delivered', '1674657251', '254741590330', 'e8b7de634b650e9149030d9c6c01fe97', 'wamid.HBgMMjU0NzQxNTkwMzMwFQIAERgSNTQwMDkxMDdCN0I5QjUyRUE4AA==', None, 'user_initiated', True, 'CBP', 0)]
(Background on this error at: https://sqlalche.me/e/14/gkpj)
2023-01-26 12:46:23,720 - log - ERROR - 'NoneType' object has no attribute 'processed'
Traceback (most recent call last):
  File "application.py", line 173, in heyoo
    processed_message = IncomingRequest.query.filter_by(message_id=message_id,  processed=False).first()
AttributeError: 'NoneType' object has no attribute 'processed'
2023-01-26 12:46:32,294 - log - ERROR - 'NoneType' object has no attribute 'processed'
Traceback (most recent call last):
  File "application.py", line 173, in heyoo
    processed_message = IncomingRequest.query.filter_by(message_id=message_id,  processed=False).first()
AttributeError: 'NoneType' object has no attribute 'processed'
2023-01-26 12:47:16,950 - log - ERROR - 'NoneType' object has no attribute 'processed'
Traceback (most recent call last):
  File "application.py", line 173, in heyoo
    processed_message = IncomingRequest.query.filter_by(message_id=message_id,  processed=False).first()
AttributeError: 'NoneType' object has no attribute 'processed'
2023-01-26 12:48:09,696 - log - ERROR - (sqlite3.IntegrityError) UNIQUE constraint failed: incoming_request.message_id
[SQL: INSERT INTO incoming_request (status, timestamp, recipient_id, conversation_id, message_id, expiration_timestamp, origin, billable, pricing_model, processed) VALUES (?, ?, ?, ?, ?, ?, ?, ?, ?, ?)]
[parameters: ('sent', '1674672802', '254741590330', 'e8b7de634b650e9149030d9c6c01fe97', 'wamid.HBgMMjU0NzQxNTkwMzMwFQIAERgSRjcxRENDNEM1QjhFRTkwRjNFAA==', None, 'user_initiated', True, 'CBP', 0)]
(Background on this error at: https://sqlalche.me/e/14/gkpj)
Traceback (most recent call last):
  File "/home/newton/elarian/virtual/lib/python3.8/site-packages/sqlalchemy/engine/base.py", line 1900, in _execute_context
    self.dialect.do_execute(
  File "/home/newton/elarian/virtual/lib/python3.8/site-packages/sqlalchemy/engine/default.py", line 736, in do_execute
    cursor.execute(statement, parameters)
sqlite3.IntegrityError: UNIQUE constraint failed: incoming_request.message_id

The above exception was the direct cause of the following exception:

Traceback (most recent call last):
  File "application.py", line 78, in save_request
    db.session.commit()
  File "<string>", line 2, in commit
  File "/home/newton/elarian/virtual/lib/python3.8/site-packages/sqlalchemy/orm/session.py", line 1451, in commit
    self._transaction.commit(_to_root=self.future)
  File "/home/newton/elarian/virtual/lib/python3.8/site-packages/sqlalchemy/orm/session.py", line 829, in commit
    self._prepare_impl()
  File "/home/newton/elarian/virtual/lib/python3.8/site-packages/sqlalchemy/orm/session.py", line 808, in _prepare_impl
    self.session.flush()
  File "/home/newton/elarian/virtual/lib/python3.8/site-packages/sqlalchemy/orm/session.py", line 3444, in flush
    self._flush(objects)
  File "/home/newton/elarian/virtual/lib/python3.8/site-packages/sqlalchemy/orm/session.py", line 3584, in _flush
    transaction.rollback(_capture_exception=True)
  File "/home/newton/elarian/virtual/lib/python3.8/site-packages/sqlalchemy/util/langhelpers.py", line 70, in __exit__
    compat.raise_(
  File "/home/newton/elarian/virtual/lib/python3.8/site-packages/sqlalchemy/util/compat.py", line 211, in raise_
    raise exception
  File "/home/newton/elarian/virtual/lib/python3.8/site-packages/sqlalchemy/orm/session.py", line 3544, in _flush
    flush_context.execute()
  File "/home/newton/elarian/virtual/lib/python3.8/site-packages/sqlalchemy/orm/unitofwork.py", line 456, in execute
    rec.execute(self)
  File "/home/newton/elarian/virtual/lib/python3.8/site-packages/sqlalchemy/orm/unitofwork.py", line 630, in execute
    util.preloaded.orm_persistence.save_obj(
  File "/home/newton/elarian/virtual/lib/python3.8/site-packages/sqlalchemy/orm/persistence.py", line 245, in save_obj
    _emit_insert_statements(
  File "/home/newton/elarian/virtual/lib/python3.8/site-packages/sqlalchemy/orm/persistence.py", line 1238, in _emit_insert_statements
    result = connection._execute_20(
  File "/home/newton/elarian/virtual/lib/python3.8/site-packages/sqlalchemy/engine/base.py", line 1705, in _execute_20
    return meth(self, args_10style, kwargs_10style, execution_options)
  File "/home/newton/elarian/virtual/lib/python3.8/site-packages/sqlalchemy/sql/elements.py", line 334, in _execute_on_connection
    return connection._execute_clauseelement(
  File "/home/newton/elarian/virtual/lib/python3.8/site-packages/sqlalchemy/engine/base.py", line 1572, in _execute_clauseelement
    ret = self._execute_context(
  File "/home/newton/elarian/virtual/lib/python3.8/site-packages/sqlalchemy/engine/base.py", line 1943, in _execute_context
    self._handle_dbapi_exception(
  File "/home/newton/elarian/virtual/lib/python3.8/site-packages/sqlalchemy/engine/base.py", line 2124, in _handle_dbapi_exception
    util.raise_(
  File "/home/newton/elarian/virtual/lib/python3.8/site-packages/sqlalchemy/util/compat.py", line 211, in raise_
    raise exception
  File "/home/newton/elarian/virtual/lib/python3.8/site-packages/sqlalchemy/engine/base.py", line 1900, in _execute_context
    self.dialect.do_execute(
  File "/home/newton/elarian/virtual/lib/python3.8/site-packages/sqlalchemy/engine/default.py", line 736, in do_execute
    cursor.execute(statement, parameters)
sqlalchemy.exc.IntegrityError: (sqlite3.IntegrityError) UNIQUE constraint failed: incoming_request.message_id
[SQL: INSERT INTO incoming_request (status, timestamp, recipient_id, conversation_id, message_id, expiration_timestamp, origin, billable, pricing_model, processed) VALUES (?, ?, ?, ?, ?, ?, ?, ?, ?, ?)]
[parameters: ('sent', '1674672802', '254741590330', 'e8b7de634b650e9149030d9c6c01fe97', 'wamid.HBgMMjU0NzQxNTkwMzMwFQIAERgSRjcxRENDNEM1QjhFRTkwRjNFAA==', None, 'user_initiated', True, 'CBP', 0)]
(Background on this error at: https://sqlalche.me/e/14/gkpj)
2023-01-26 12:48:47,110 - log - ERROR - 'NoneType' object has no attribute 'processed'
Traceback (most recent call last):
  File "application.py", line 173, in heyoo
    processed_message = IncomingRequest.query.filter_by(message_id=message_id,  processed=False).first()
AttributeError: 'NoneType' object has no attribute 'processed'
2023-01-26 12:49:13,144 - log - ERROR - (sqlite3.IntegrityError) UNIQUE constraint failed: incoming_request.message_id
[SQL: INSERT INTO incoming_request (status, timestamp, recipient_id, conversation_id, message_id, expiration_timestamp, origin, billable, pricing_model, processed) VALUES (?, ?, ?, ?, ?, ?, ?, ?, ?, ?)]
[parameters: ('delivered', '1674658185', '254741590330', 'e8b7de634b650e9149030d9c6c01fe97', 'wamid.HBgMMjU0NzQxNTkwMzMwFQIAERgSOTI1MDJERkU0RjFFQjdENEM3AA==', None, 'user_initiated', True, 'CBP', 0)]
(Background on this error at: https://sqlalche.me/e/14/gkpj)
Traceback (most recent call last):
  File "/home/newton/elarian/virtual/lib/python3.8/site-packages/sqlalchemy/engine/base.py", line 1900, in _execute_context
    self.dialect.do_execute(
  File "/home/newton/elarian/virtual/lib/python3.8/site-packages/sqlalchemy/engine/default.py", line 736, in do_execute
    cursor.execute(statement, parameters)
sqlite3.IntegrityError: UNIQUE constraint failed: incoming_request.message_id

The above exception was the direct cause of the following exception:

Traceback (most recent call last):
  File "application.py", line 78, in save_request
    db.session.commit()
  File "<string>", line 2, in commit
  File "/home/newton/elarian/virtual/lib/python3.8/site-packages/sqlalchemy/orm/session.py", line 1451, in commit
    self._transaction.commit(_to_root=self.future)
  File "/home/newton/elarian/virtual/lib/python3.8/site-packages/sqlalchemy/orm/session.py", line 829, in commit
    self._prepare_impl()
  File "/home/newton/elarian/virtual/lib/python3.8/site-packages/sqlalchemy/orm/session.py", line 808, in _prepare_impl
    self.session.flush()
  File "/home/newton/elarian/virtual/lib/python3.8/site-packages/sqlalchemy/orm/session.py", line 3444, in flush
    self._flush(objects)
  File "/home/newton/elarian/virtual/lib/python3.8/site-packages/sqlalchemy/orm/session.py", line 3584, in _flush
    transaction.rollback(_capture_exception=True)
  File "/home/newton/elarian/virtual/lib/python3.8/site-packages/sqlalchemy/util/langhelpers.py", line 70, in __exit__
    compat.raise_(
  File "/home/newton/elarian/virtual/lib/python3.8/site-packages/sqlalchemy/util/compat.py", line 211, in raise_
    raise exception
  File "/home/newton/elarian/virtual/lib/python3.8/site-packages/sqlalchemy/orm/session.py", line 3544, in _flush
    flush_context.execute()
  File "/home/newton/elarian/virtual/lib/python3.8/site-packages/sqlalchemy/orm/unitofwork.py", line 456, in execute
    rec.execute(self)
  File "/home/newton/elarian/virtual/lib/python3.8/site-packages/sqlalchemy/orm/unitofwork.py", line 630, in execute
    util.preloaded.orm_persistence.save_obj(
  File "/home/newton/elarian/virtual/lib/python3.8/site-packages/sqlalchemy/orm/persistence.py", line 245, in save_obj
    _emit_insert_statements(
  File "/home/newton/elarian/virtual/lib/python3.8/site-packages/sqlalchemy/orm/persistence.py", line 1238, in _emit_insert_statements
    result = connection._execute_20(
  File "/home/newton/elarian/virtual/lib/python3.8/site-packages/sqlalchemy/engine/base.py", line 1705, in _execute_20
    return meth(self, args_10style, kwargs_10style, execution_options)
  File "/home/newton/elarian/virtual/lib/python3.8/site-packages/sqlalchemy/sql/elements.py", line 334, in _execute_on_connection
    return connection._execute_clauseelement(
  File "/home/newton/elarian/virtual/lib/python3.8/site-packages/sqlalchemy/engine/base.py", line 1572, in _execute_clauseelement
    ret = self._execute_context(
  File "/home/newton/elarian/virtual/lib/python3.8/site-packages/sqlalchemy/engine/base.py", line 1943, in _execute_context
    self._handle_dbapi_exception(
  File "/home/newton/elarian/virtual/lib/python3.8/site-packages/sqlalchemy/engine/base.py", line 2124, in _handle_dbapi_exception
    util.raise_(
  File "/home/newton/elarian/virtual/lib/python3.8/site-packages/sqlalchemy/util/compat.py", line 211, in raise_
    raise exception
  File "/home/newton/elarian/virtual/lib/python3.8/site-packages/sqlalchemy/engine/base.py", line 1900, in _execute_context
    self.dialect.do_execute(
  File "/home/newton/elarian/virtual/lib/python3.8/site-packages/sqlalchemy/engine/default.py", line 736, in do_execute
    cursor.execute(statement, parameters)
sqlalchemy.exc.IntegrityError: (sqlite3.IntegrityError) UNIQUE constraint failed: incoming_request.message_id
[SQL: INSERT INTO incoming_request (status, timestamp, recipient_id, conversation_id, message_id, expiration_timestamp, origin, billable, pricing_model, processed) VALUES (?, ?, ?, ?, ?, ?, ?, ?, ?, ?)]
[parameters: ('delivered', '1674658185', '254741590330', 'e8b7de634b650e9149030d9c6c01fe97', 'wamid.HBgMMjU0NzQxNTkwMzMwFQIAERgSOTI1MDJERkU0RjFFQjdENEM3AA==', None, 'user_initiated', True, 'CBP', 0)]
(Background on this error at: https://sqlalche.me/e/14/gkpj)
