2023-01-26 10:27:43,682 - log - ERROR - (sqlite3.IntegrityError) UNIQUE constraint failed: incoming_request.message_id
[SQL: INSERT INTO incoming_request (status, timestamp, recipient_id, conversation_id, message_id, expiration_timestamp, origin, billable, pricing_model, processed) VALUES (?, ?, ?, ?, ?, ?, ?, ?, ?, ?)]
[parameters: ('delivered', '1674651488', '254716434058', 'c1b63a1655a036852a22a89da7fb908a', 'wamid.HBgMMjU0NzE2NDM0MDU4FQIAERgSMEQ0QTI5MDUwQURGQjhGQTQxAA==', None, 'user_initiated', True, 'CBP', 0)]
(Background on this error at: https://sqlalche.me/e/14/gkpj)
Traceback (most recent call last):
  File "/home/newton/elarian/virtual/lib/python3.8/site-packages/sqlalchemy/engine/base.py", line 1900, in _execute_context
    self.dialect.do_execute(
  File "/home/newton/elarian/virtual/lib/python3.8/site-packages/sqlalchemy/engine/default.py", line 736, in do_execute
    cursor.execute(statement, parameters)
sqlite3.IntegrityError: UNIQUE constraint failed: incoming_request.message_id

The above exception was the direct cause of the following exception:

Traceback (most recent call last):
  File "application.py", line 76, in save_request
    db.session.commit()
  File "<string>", line 2, in commit
  File "/home/newton/elarian/virtual/lib/python3.8/site-packages/sqlalchemy/orm/session.py", line 1451, in commit
    self._transaction.commit(_to_root=self.future)
  File "/home/newton/elarian/virtual/lib/python3.8/site-packages/sqlalchemy/orm/session.py", line 829, in commit
    self._prepare_impl()
  File "/home/newton/elarian/virtual/lib/python3.8/site-packages/sqlalchemy/orm/session.py", line 808, in _prepare_impl
    self.session.flush()
  File "/home/newton/elarian/virtual/lib/python3.8/site-packages/sqlalchemy/orm/session.py", line 3444, in flush
    self._flush(objects)
  File "/home/newton/elarian/virtual/lib/python3.8/site-packages/sqlalchemy/orm/session.py", line 3584, in _flush
    transaction.rollback(_capture_exception=True)
  File "/home/newton/elarian/virtual/lib/python3.8/site-packages/sqlalchemy/util/langhelpers.py", line 70, in __exit__
    compat.raise_(
  File "/home/newton/elarian/virtual/lib/python3.8/site-packages/sqlalchemy/util/compat.py", line 211, in raise_
    raise exception
  File "/home/newton/elarian/virtual/lib/python3.8/site-packages/sqlalchemy/orm/session.py", line 3544, in _flush
    flush_context.execute()
  File "/home/newton/elarian/virtual/lib/python3.8/site-packages/sqlalchemy/orm/unitofwork.py", line 456, in execute
    rec.execute(self)
  File "/home/newton/elarian/virtual/lib/python3.8/site-packages/sqlalchemy/orm/unitofwork.py", line 630, in execute
    util.preloaded.orm_persistence.save_obj(
  File "/home/newton/elarian/virtual/lib/python3.8/site-packages/sqlalchemy/orm/persistence.py", line 245, in save_obj
    _emit_insert_statements(
  File "/home/newton/elarian/virtual/lib/python3.8/site-packages/sqlalchemy/orm/persistence.py", line 1238, in _emit_insert_statements
    result = connection._execute_20(
  File "/home/newton/elarian/virtual/lib/python3.8/site-packages/sqlalchemy/engine/base.py", line 1705, in _execute_20
    return meth(self, args_10style, kwargs_10style, execution_options)
  File "/home/newton/elarian/virtual/lib/python3.8/site-packages/sqlalchemy/sql/elements.py", line 334, in _execute_on_connection
    return connection._execute_clauseelement(
  File "/home/newton/elarian/virtual/lib/python3.8/site-packages/sqlalchemy/engine/base.py", line 1572, in _execute_clauseelement
    ret = self._execute_context(
  File "/home/newton/elarian/virtual/lib/python3.8/site-packages/sqlalchemy/engine/base.py", line 1943, in _execute_context
    self._handle_dbapi_exception(
  File "/home/newton/elarian/virtual/lib/python3.8/site-packages/sqlalchemy/engine/base.py", line 2124, in _handle_dbapi_exception
    util.raise_(
  File "/home/newton/elarian/virtual/lib/python3.8/site-packages/sqlalchemy/util/compat.py", line 211, in raise_
    raise exception
  File "/home/newton/elarian/virtual/lib/python3.8/site-packages/sqlalchemy/engine/base.py", line 1900, in _execute_context
    self.dialect.do_execute(
  File "/home/newton/elarian/virtual/lib/python3.8/site-packages/sqlalchemy/engine/default.py", line 736, in do_execute
    cursor.execute(statement, parameters)
sqlalchemy.exc.IntegrityError: (sqlite3.IntegrityError) UNIQUE constraint failed: incoming_request.message_id
[SQL: INSERT INTO incoming_request (status, timestamp, recipient_id, conversation_id, message_id, expiration_timestamp, origin, billable, pricing_model, processed) VALUES (?, ?, ?, ?, ?, ?, ?, ?, ?, ?)]
[parameters: ('delivered', '1674651488', '254716434058', 'c1b63a1655a036852a22a89da7fb908a', 'wamid.HBgMMjU0NzE2NDM0MDU4FQIAERgSMEQ0QTI5MDUwQURGQjhGQTQxAA==', None, 'user_initiated', True, 'CBP', 0)]
(Background on this error at: https://sqlalche.me/e/14/gkpj)
2023-01-26 10:29:23,293 - log - ERROR - (sqlite3.IntegrityError) UNIQUE constraint failed: incoming_request.message_id
[SQL: INSERT INTO incoming_request (status, timestamp, recipient_id, conversation_id, message_id, expiration_timestamp, origin, billable, pricing_model, processed) VALUES (?, ?, ?, ?, ?, ?, ?, ?, ?, ?)]
[parameters: ('sent', '1674654855', '254741590330', 'e8b7de634b650e9149030d9c6c01fe97', 'wamid.HBgMMjU0NzQxNTkwMzMwFQIAERgSM0Q3NDkwNTA4MkNDNUFDMzIwAA==', None, 'user_initiated', True, 'CBP', 0)]
(Background on this error at: https://sqlalche.me/e/14/gkpj)
Traceback (most recent call last):
  File "/home/newton/elarian/virtual/lib/python3.8/site-packages/sqlalchemy/engine/base.py", line 1900, in _execute_context
    self.dialect.do_execute(
  File "/home/newton/elarian/virtual/lib/python3.8/site-packages/sqlalchemy/engine/default.py", line 736, in do_execute
    cursor.execute(statement, parameters)
sqlite3.IntegrityError: UNIQUE constraint failed: incoming_request.message_id

The above exception was the direct cause of the following exception:

Traceback (most recent call last):
  File "application.py", line 76, in save_request
    db.session.commit()
  File "<string>", line 2, in commit
  File "/home/newton/elarian/virtual/lib/python3.8/site-packages/sqlalchemy/orm/session.py", line 1451, in commit
    self._transaction.commit(_to_root=self.future)
  File "/home/newton/elarian/virtual/lib/python3.8/site-packages/sqlalchemy/orm/session.py", line 829, in commit
    self._prepare_impl()
  File "/home/newton/elarian/virtual/lib/python3.8/site-packages/sqlalchemy/orm/session.py", line 808, in _prepare_impl
    self.session.flush()
  File "/home/newton/elarian/virtual/lib/python3.8/site-packages/sqlalchemy/orm/session.py", line 3444, in flush
    self._flush(objects)
  File "/home/newton/elarian/virtual/lib/python3.8/site-packages/sqlalchemy/orm/session.py", line 3584, in _flush
    transaction.rollback(_capture_exception=True)
  File "/home/newton/elarian/virtual/lib/python3.8/site-packages/sqlalchemy/util/langhelpers.py", line 70, in __exit__
    compat.raise_(
  File "/home/newton/elarian/virtual/lib/python3.8/site-packages/sqlalchemy/util/compat.py", line 211, in raise_
    raise exception
  File "/home/newton/elarian/virtual/lib/python3.8/site-packages/sqlalchemy/orm/session.py", line 3544, in _flush
    flush_context.execute()
  File "/home/newton/elarian/virtual/lib/python3.8/site-packages/sqlalchemy/orm/unitofwork.py", line 456, in execute
    rec.execute(self)
  File "/home/newton/elarian/virtual/lib/python3.8/site-packages/sqlalchemy/orm/unitofwork.py", line 630, in execute
    util.preloaded.orm_persistence.save_obj(
  File "/home/newton/elarian/virtual/lib/python3.8/site-packages/sqlalchemy/orm/persistence.py", line 245, in save_obj
    _emit_insert_statements(
  File "/home/newton/elarian/virtual/lib/python3.8/site-packages/sqlalchemy/orm/persistence.py", line 1238, in _emit_insert_statements
    result = connection._execute_20(
  File "/home/newton/elarian/virtual/lib/python3.8/site-packages/sqlalchemy/engine/base.py", line 1705, in _execute_20
    return meth(self, args_10style, kwargs_10style, execution_options)
  File "/home/newton/elarian/virtual/lib/python3.8/site-packages/sqlalchemy/sql/elements.py", line 334, in _execute_on_connection
    return connection._execute_clauseelement(
  File "/home/newton/elarian/virtual/lib/python3.8/site-packages/sqlalchemy/engine/base.py", line 1572, in _execute_clauseelement
    ret = self._execute_context(
  File "/home/newton/elarian/virtual/lib/python3.8/site-packages/sqlalchemy/engine/base.py", line 1943, in _execute_context
    self._handle_dbapi_exception(
  File "/home/newton/elarian/virtual/lib/python3.8/site-packages/sqlalchemy/engine/base.py", line 2124, in _handle_dbapi_exception
    util.raise_(
  File "/home/newton/elarian/virtual/lib/python3.8/site-packages/sqlalchemy/util/compat.py", line 211, in raise_
    raise exception
  File "/home/newton/elarian/virtual/lib/python3.8/site-packages/sqlalchemy/engine/base.py", line 1900, in _execute_context
    self.dialect.do_execute(
  File "/home/newton/elarian/virtual/lib/python3.8/site-packages/sqlalchemy/engine/default.py", line 736, in do_execute
    cursor.execute(statement, parameters)
sqlalchemy.exc.IntegrityError: (sqlite3.IntegrityError) UNIQUE constraint failed: incoming_request.message_id
[SQL: INSERT INTO incoming_request (status, timestamp, recipient_id, conversation_id, message_id, expiration_timestamp, origin, billable, pricing_model, processed) VALUES (?, ?, ?, ?, ?, ?, ?, ?, ?, ?)]
[parameters: ('sent', '1674654855', '254741590330', 'e8b7de634b650e9149030d9c6c01fe97', 'wamid.HBgMMjU0NzQxNTkwMzMwFQIAERgSM0Q3NDkwNTA4MkNDNUFDMzIwAA==', None, 'user_initiated', True, 'CBP', 0)]
(Background on this error at: https://sqlalche.me/e/14/gkpj)
2023-01-26 10:31:07,953 - log - ERROR - (sqlite3.IntegrityError) UNIQUE constraint failed: incoming_request.message_id
[SQL: INSERT INTO incoming_request (status, timestamp, recipient_id, conversation_id, message_id, expiration_timestamp, origin, billable, pricing_model, processed) VALUES (?, ?, ?, ?, ?, ?, ?, ?, ?, ?)]
[parameters: ('sent', '1674656622', '254741590330', 'e8b7de634b650e9149030d9c6c01fe97', 'wamid.HBgMMjU0NzQxNTkwMzMwFQIAERgSM0RDQzNFNDA1RTBBNzU4NzMzAA==', None, 'user_initiated', True, 'CBP', 0)]
(Background on this error at: https://sqlalche.me/e/14/gkpj)
Traceback (most recent call last):
  File "/home/newton/elarian/virtual/lib/python3.8/site-packages/sqlalchemy/engine/base.py", line 1900, in _execute_context
    self.dialect.do_execute(
  File "/home/newton/elarian/virtual/lib/python3.8/site-packages/sqlalchemy/engine/default.py", line 736, in do_execute
    cursor.execute(statement, parameters)
sqlite3.IntegrityError: UNIQUE constraint failed: incoming_request.message_id

The above exception was the direct cause of the following exception:

Traceback (most recent call last):
  File "application.py", line 76, in save_request
    db.session.commit()
  File "<string>", line 2, in commit
  File "/home/newton/elarian/virtual/lib/python3.8/site-packages/sqlalchemy/orm/session.py", line 1451, in commit
    self._transaction.commit(_to_root=self.future)
  File "/home/newton/elarian/virtual/lib/python3.8/site-packages/sqlalchemy/orm/session.py", line 829, in commit
    self._prepare_impl()
  File "/home/newton/elarian/virtual/lib/python3.8/site-packages/sqlalchemy/orm/session.py", line 808, in _prepare_impl
    self.session.flush()
  File "/home/newton/elarian/virtual/lib/python3.8/site-packages/sqlalchemy/orm/session.py", line 3444, in flush
    self._flush(objects)
  File "/home/newton/elarian/virtual/lib/python3.8/site-packages/sqlalchemy/orm/session.py", line 3584, in _flush
    transaction.rollback(_capture_exception=True)
  File "/home/newton/elarian/virtual/lib/python3.8/site-packages/sqlalchemy/util/langhelpers.py", line 70, in __exit__
    compat.raise_(
  File "/home/newton/elarian/virtual/lib/python3.8/site-packages/sqlalchemy/util/compat.py", line 211, in raise_
    raise exception
  File "/home/newton/elarian/virtual/lib/python3.8/site-packages/sqlalchemy/orm/session.py", line 3544, in _flush
    flush_context.execute()
  File "/home/newton/elarian/virtual/lib/python3.8/site-packages/sqlalchemy/orm/unitofwork.py", line 456, in execute
    rec.execute(self)
  File "/home/newton/elarian/virtual/lib/python3.8/site-packages/sqlalchemy/orm/unitofwork.py", line 630, in execute
    util.preloaded.orm_persistence.save_obj(
  File "/home/newton/elarian/virtual/lib/python3.8/site-packages/sqlalchemy/orm/persistence.py", line 245, in save_obj
    _emit_insert_statements(
  File "/home/newton/elarian/virtual/lib/python3.8/site-packages/sqlalchemy/orm/persistence.py", line 1238, in _emit_insert_statements
    result = connection._execute_20(
  File "/home/newton/elarian/virtual/lib/python3.8/site-packages/sqlalchemy/engine/base.py", line 1705, in _execute_20
    return meth(self, args_10style, kwargs_10style, execution_options)
  File "/home/newton/elarian/virtual/lib/python3.8/site-packages/sqlalchemy/sql/elements.py", line 334, in _execute_on_connection
    return connection._execute_clauseelement(
  File "/home/newton/elarian/virtual/lib/python3.8/site-packages/sqlalchemy/engine/base.py", line 1572, in _execute_clauseelement
    ret = self._execute_context(
  File "/home/newton/elarian/virtual/lib/python3.8/site-packages/sqlalchemy/engine/base.py", line 1943, in _execute_context
    self._handle_dbapi_exception(
  File "/home/newton/elarian/virtual/lib/python3.8/site-packages/sqlalchemy/engine/base.py", line 2124, in _handle_dbapi_exception
    util.raise_(
  File "/home/newton/elarian/virtual/lib/python3.8/site-packages/sqlalchemy/util/compat.py", line 211, in raise_
    raise exception
  File "/home/newton/elarian/virtual/lib/python3.8/site-packages/sqlalchemy/engine/base.py", line 1900, in _execute_context
    self.dialect.do_execute(
  File "/home/newton/elarian/virtual/lib/python3.8/site-packages/sqlalchemy/engine/default.py", line 736, in do_execute
    cursor.execute(statement, parameters)
sqlalchemy.exc.IntegrityError: (sqlite3.IntegrityError) UNIQUE constraint failed: incoming_request.message_id
[SQL: INSERT INTO incoming_request (status, timestamp, recipient_id, conversation_id, message_id, expiration_timestamp, origin, billable, pricing_model, processed) VALUES (?, ?, ?, ?, ?, ?, ?, ?, ?, ?)]
[parameters: ('sent', '1674656622', '254741590330', 'e8b7de634b650e9149030d9c6c01fe97', 'wamid.HBgMMjU0NzQxNTkwMzMwFQIAERgSM0RDQzNFNDA1RTBBNzU4NzMzAA==', None, 'user_initiated', True, 'CBP', 0)]
(Background on this error at: https://sqlalche.me/e/14/gkpj)
2023-01-26 10:31:25,320 - log - ERROR - (sqlite3.IntegrityError) UNIQUE constraint failed: incoming_request.message_id
[SQL: INSERT INTO incoming_request (status, timestamp, recipient_id, conversation_id, message_id, expiration_timestamp, origin, billable, pricing_model, processed) VALUES (?, ?, ?, ?, ?, ?, ?, ?, ?, ?)]
[parameters: ('sent', '1674656299', '254741590330', 'e8b7de634b650e9149030d9c6c01fe97', 'wamid.HBgMMjU0NzQxNTkwMzMwFQIAERgSQTcwN0IwODQxRDZDOTAzRUFBAA==', None, 'user_initiated', True, 'CBP', 0)]
(Background on this error at: https://sqlalche.me/e/14/gkpj)
Traceback (most recent call last):
  File "/home/newton/elarian/virtual/lib/python3.8/site-packages/sqlalchemy/engine/base.py", line 1900, in _execute_context
    self.dialect.do_execute(
  File "/home/newton/elarian/virtual/lib/python3.8/site-packages/sqlalchemy/engine/default.py", line 736, in do_execute
    cursor.execute(statement, parameters)
sqlite3.IntegrityError: UNIQUE constraint failed: incoming_request.message_id

The above exception was the direct cause of the following exception:

Traceback (most recent call last):
  File "application.py", line 76, in save_request
    db.session.commit()
  File "<string>", line 2, in commit
  File "/home/newton/elarian/virtual/lib/python3.8/site-packages/sqlalchemy/orm/session.py", line 1451, in commit
    self._transaction.commit(_to_root=self.future)
  File "/home/newton/elarian/virtual/lib/python3.8/site-packages/sqlalchemy/orm/session.py", line 829, in commit
    self._prepare_impl()
  File "/home/newton/elarian/virtual/lib/python3.8/site-packages/sqlalchemy/orm/session.py", line 808, in _prepare_impl
    self.session.flush()
  File "/home/newton/elarian/virtual/lib/python3.8/site-packages/sqlalchemy/orm/session.py", line 3444, in flush
    self._flush(objects)
  File "/home/newton/elarian/virtual/lib/python3.8/site-packages/sqlalchemy/orm/session.py", line 3584, in _flush
    transaction.rollback(_capture_exception=True)
  File "/home/newton/elarian/virtual/lib/python3.8/site-packages/sqlalchemy/util/langhelpers.py", line 70, in __exit__
    compat.raise_(
  File "/home/newton/elarian/virtual/lib/python3.8/site-packages/sqlalchemy/util/compat.py", line 211, in raise_
    raise exception
  File "/home/newton/elarian/virtual/lib/python3.8/site-packages/sqlalchemy/orm/session.py", line 3544, in _flush
    flush_context.execute()
  File "/home/newton/elarian/virtual/lib/python3.8/site-packages/sqlalchemy/orm/unitofwork.py", line 456, in execute
    rec.execute(self)
  File "/home/newton/elarian/virtual/lib/python3.8/site-packages/sqlalchemy/orm/unitofwork.py", line 630, in execute
    util.preloaded.orm_persistence.save_obj(
  File "/home/newton/elarian/virtual/lib/python3.8/site-packages/sqlalchemy/orm/persistence.py", line 245, in save_obj
    _emit_insert_statements(
  File "/home/newton/elarian/virtual/lib/python3.8/site-packages/sqlalchemy/orm/persistence.py", line 1238, in _emit_insert_statements
    result = connection._execute_20(
  File "/home/newton/elarian/virtual/lib/python3.8/site-packages/sqlalchemy/engine/base.py", line 1705, in _execute_20
    return meth(self, args_10style, kwargs_10style, execution_options)
  File "/home/newton/elarian/virtual/lib/python3.8/site-packages/sqlalchemy/sql/elements.py", line 334, in _execute_on_connection
    return connection._execute_clauseelement(
  File "/home/newton/elarian/virtual/lib/python3.8/site-packages/sqlalchemy/engine/base.py", line 1572, in _execute_clauseelement
    ret = self._execute_context(
  File "/home/newton/elarian/virtual/lib/python3.8/site-packages/sqlalchemy/engine/base.py", line 1943, in _execute_context
    self._handle_dbapi_exception(
  File "/home/newton/elarian/virtual/lib/python3.8/site-packages/sqlalchemy/engine/base.py", line 2124, in _handle_dbapi_exception
    util.raise_(
  File "/home/newton/elarian/virtual/lib/python3.8/site-packages/sqlalchemy/util/compat.py", line 211, in raise_
    raise exception
  File "/home/newton/elarian/virtual/lib/python3.8/site-packages/sqlalchemy/engine/base.py", line 1900, in _execute_context
    self.dialect.do_execute(
  File "/home/newton/elarian/virtual/lib/python3.8/site-packages/sqlalchemy/engine/default.py", line 736, in do_execute
    cursor.execute(statement, parameters)
sqlalchemy.exc.IntegrityError: (sqlite3.IntegrityError) UNIQUE constraint failed: incoming_request.message_id
[SQL: INSERT INTO incoming_request (status, timestamp, recipient_id, conversation_id, message_id, expiration_timestamp, origin, billable, pricing_model, processed) VALUES (?, ?, ?, ?, ?, ?, ?, ?, ?, ?)]
[parameters: ('sent', '1674656299', '254741590330', 'e8b7de634b650e9149030d9c6c01fe97', 'wamid.HBgMMjU0NzQxNTkwMzMwFQIAERgSQTcwN0IwODQxRDZDOTAzRUFBAA==', None, 'user_initiated', True, 'CBP', 0)]
(Background on this error at: https://sqlalche.me/e/14/gkpj)
2023-01-26 10:31:51,874 - log - ERROR - (sqlite3.IntegrityError) UNIQUE constraint failed: incoming_request.message_id
[SQL: INSERT INTO incoming_request (status, timestamp, recipient_id, conversation_id, message_id, expiration_timestamp, origin, billable, pricing_model, processed) VALUES (?, ?, ?, ?, ?, ?, ?, ?, ?, ?)]
[parameters: ('delivered', '1674653020', '254741590330', 'e8b7de634b650e9149030d9c6c01fe97', 'wamid.HBgMMjU0NzQxNTkwMzMwFQIAERgSRTI3MEUwNzBDNjEwOEI5RUZDAA==', None, 'user_initiated', True, 'CBP', 0)]
(Background on this error at: https://sqlalche.me/e/14/gkpj)
Traceback (most recent call last):
  File "/home/newton/elarian/virtual/lib/python3.8/site-packages/sqlalchemy/engine/base.py", line 1900, in _execute_context
    self.dialect.do_execute(
  File "/home/newton/elarian/virtual/lib/python3.8/site-packages/sqlalchemy/engine/default.py", line 736, in do_execute
    cursor.execute(statement, parameters)
sqlite3.IntegrityError: UNIQUE constraint failed: incoming_request.message_id

The above exception was the direct cause of the following exception:

Traceback (most recent call last):
  File "application.py", line 76, in save_request
    db.session.commit()
  File "<string>", line 2, in commit
  File "/home/newton/elarian/virtual/lib/python3.8/site-packages/sqlalchemy/orm/session.py", line 1451, in commit
    self._transaction.commit(_to_root=self.future)
  File "/home/newton/elarian/virtual/lib/python3.8/site-packages/sqlalchemy/orm/session.py", line 829, in commit
    self._prepare_impl()
  File "/home/newton/elarian/virtual/lib/python3.8/site-packages/sqlalchemy/orm/session.py", line 808, in _prepare_impl
    self.session.flush()
  File "/home/newton/elarian/virtual/lib/python3.8/site-packages/sqlalchemy/orm/session.py", line 3444, in flush
    self._flush(objects)
  File "/home/newton/elarian/virtual/lib/python3.8/site-packages/sqlalchemy/orm/session.py", line 3584, in _flush
    transaction.rollback(_capture_exception=True)
  File "/home/newton/elarian/virtual/lib/python3.8/site-packages/sqlalchemy/util/langhelpers.py", line 70, in __exit__
    compat.raise_(
  File "/home/newton/elarian/virtual/lib/python3.8/site-packages/sqlalchemy/util/compat.py", line 211, in raise_
    raise exception
  File "/home/newton/elarian/virtual/lib/python3.8/site-packages/sqlalchemy/orm/session.py", line 3544, in _flush
    flush_context.execute()
  File "/home/newton/elarian/virtual/lib/python3.8/site-packages/sqlalchemy/orm/unitofwork.py", line 456, in execute
    rec.execute(self)
  File "/home/newton/elarian/virtual/lib/python3.8/site-packages/sqlalchemy/orm/unitofwork.py", line 630, in execute
    util.preloaded.orm_persistence.save_obj(
  File "/home/newton/elarian/virtual/lib/python3.8/site-packages/sqlalchemy/orm/persistence.py", line 245, in save_obj
    _emit_insert_statements(
  File "/home/newton/elarian/virtual/lib/python3.8/site-packages/sqlalchemy/orm/persistence.py", line 1238, in _emit_insert_statements
    result = connection._execute_20(
  File "/home/newton/elarian/virtual/lib/python3.8/site-packages/sqlalchemy/engine/base.py", line 1705, in _execute_20
    return meth(self, args_10style, kwargs_10style, execution_options)
  File "/home/newton/elarian/virtual/lib/python3.8/site-packages/sqlalchemy/sql/elements.py", line 334, in _execute_on_connection
    return connection._execute_clauseelement(
  File "/home/newton/elarian/virtual/lib/python3.8/site-packages/sqlalchemy/engine/base.py", line 1572, in _execute_clauseelement
    ret = self._execute_context(
  File "/home/newton/elarian/virtual/lib/python3.8/site-packages/sqlalchemy/engine/base.py", line 1943, in _execute_context
    self._handle_dbapi_exception(
  File "/home/newton/elarian/virtual/lib/python3.8/site-packages/sqlalchemy/engine/base.py", line 2124, in _handle_dbapi_exception
    util.raise_(
  File "/home/newton/elarian/virtual/lib/python3.8/site-packages/sqlalchemy/util/compat.py", line 211, in raise_
    raise exception
  File "/home/newton/elarian/virtual/lib/python3.8/site-packages/sqlalchemy/engine/base.py", line 1900, in _execute_context
    self.dialect.do_execute(
  File "/home/newton/elarian/virtual/lib/python3.8/site-packages/sqlalchemy/engine/default.py", line 736, in do_execute
    cursor.execute(statement, parameters)
sqlalchemy.exc.IntegrityError: (sqlite3.IntegrityError) UNIQUE constraint failed: incoming_request.message_id
[SQL: INSERT INTO incoming_request (status, timestamp, recipient_id, conversation_id, message_id, expiration_timestamp, origin, billable, pricing_model, processed) VALUES (?, ?, ?, ?, ?, ?, ?, ?, ?, ?)]
[parameters: ('delivered', '1674653020', '254741590330', 'e8b7de634b650e9149030d9c6c01fe97', 'wamid.HBgMMjU0NzQxNTkwMzMwFQIAERgSRTI3MEUwNzBDNjEwOEI5RUZDAA==', None, 'user_initiated', True, 'CBP', 0)]
(Background on this error at: https://sqlalche.me/e/14/gkpj)
2023-01-26 10:33:19,437 - log - ERROR - (sqlite3.IntegrityError) UNIQUE constraint failed: incoming_request.message_id
[SQL: INSERT INTO incoming_request (status, timestamp, recipient_id, conversation_id, message_id, expiration_timestamp, origin, billable, pricing_model, processed) VALUES (?, ?, ?, ?, ?, ?, ?, ?, ?, ?)]
[parameters: ('sent', '1674656186', '254741590330', 'e8b7de634b650e9149030d9c6c01fe97', 'wamid.HBgMMjU0NzQxNTkwMzMwFQIAERgSNEFDNjVDOTM1NTBDQjU0OTgzAA==', None, 'user_initiated', True, 'CBP', 0)]
(Background on this error at: https://sqlalche.me/e/14/gkpj)
Traceback (most recent call last):
  File "/home/newton/elarian/virtual/lib/python3.8/site-packages/sqlalchemy/engine/base.py", line 1900, in _execute_context
    self.dialect.do_execute(
  File "/home/newton/elarian/virtual/lib/python3.8/site-packages/sqlalchemy/engine/default.py", line 736, in do_execute
    cursor.execute(statement, parameters)
sqlite3.IntegrityError: UNIQUE constraint failed: incoming_request.message_id

The above exception was the direct cause of the following exception:

Traceback (most recent call last):
  File "application.py", line 76, in save_request
    db.session.commit()
  File "<string>", line 2, in commit
  File "/home/newton/elarian/virtual/lib/python3.8/site-packages/sqlalchemy/orm/session.py", line 1451, in commit
    self._transaction.commit(_to_root=self.future)
  File "/home/newton/elarian/virtual/lib/python3.8/site-packages/sqlalchemy/orm/session.py", line 829, in commit
    self._prepare_impl()
  File "/home/newton/elarian/virtual/lib/python3.8/site-packages/sqlalchemy/orm/session.py", line 808, in _prepare_impl
    self.session.flush()
  File "/home/newton/elarian/virtual/lib/python3.8/site-packages/sqlalchemy/orm/session.py", line 3444, in flush
    self._flush(objects)
  File "/home/newton/elarian/virtual/lib/python3.8/site-packages/sqlalchemy/orm/session.py", line 3584, in _flush
    transaction.rollback(_capture_exception=True)
  File "/home/newton/elarian/virtual/lib/python3.8/site-packages/sqlalchemy/util/langhelpers.py", line 70, in __exit__
    compat.raise_(
  File "/home/newton/elarian/virtual/lib/python3.8/site-packages/sqlalchemy/util/compat.py", line 211, in raise_
    raise exception
  File "/home/newton/elarian/virtual/lib/python3.8/site-packages/sqlalchemy/orm/session.py", line 3544, in _flush
    flush_context.execute()
  File "/home/newton/elarian/virtual/lib/python3.8/site-packages/sqlalchemy/orm/unitofwork.py", line 456, in execute
    rec.execute(self)
  File "/home/newton/elarian/virtual/lib/python3.8/site-packages/sqlalchemy/orm/unitofwork.py", line 630, in execute
    util.preloaded.orm_persistence.save_obj(
  File "/home/newton/elarian/virtual/lib/python3.8/site-packages/sqlalchemy/orm/persistence.py", line 245, in save_obj
    _emit_insert_statements(
  File "/home/newton/elarian/virtual/lib/python3.8/site-packages/sqlalchemy/orm/persistence.py", line 1238, in _emit_insert_statements
    result = connection._execute_20(
  File "/home/newton/elarian/virtual/lib/python3.8/site-packages/sqlalchemy/engine/base.py", line 1705, in _execute_20
    return meth(self, args_10style, kwargs_10style, execution_options)
  File "/home/newton/elarian/virtual/lib/python3.8/site-packages/sqlalchemy/sql/elements.py", line 334, in _execute_on_connection
    return connection._execute_clauseelement(
  File "/home/newton/elarian/virtual/lib/python3.8/site-packages/sqlalchemy/engine/base.py", line 1572, in _execute_clauseelement
    ret = self._execute_context(
  File "/home/newton/elarian/virtual/lib/python3.8/site-packages/sqlalchemy/engine/base.py", line 1943, in _execute_context
    self._handle_dbapi_exception(
  File "/home/newton/elarian/virtual/lib/python3.8/site-packages/sqlalchemy/engine/base.py", line 2124, in _handle_dbapi_exception
    util.raise_(
  File "/home/newton/elarian/virtual/lib/python3.8/site-packages/sqlalchemy/util/compat.py", line 211, in raise_
    raise exception
  File "/home/newton/elarian/virtual/lib/python3.8/site-packages/sqlalchemy/engine/base.py", line 1900, in _execute_context
    self.dialect.do_execute(
  File "/home/newton/elarian/virtual/lib/python3.8/site-packages/sqlalchemy/engine/default.py", line 736, in do_execute
    cursor.execute(statement, parameters)
sqlalchemy.exc.IntegrityError: (sqlite3.IntegrityError) UNIQUE constraint failed: incoming_request.message_id
[SQL: INSERT INTO incoming_request (status, timestamp, recipient_id, conversation_id, message_id, expiration_timestamp, origin, billable, pricing_model, processed) VALUES (?, ?, ?, ?, ?, ?, ?, ?, ?, ?)]
[parameters: ('sent', '1674656186', '254741590330', 'e8b7de634b650e9149030d9c6c01fe97', 'wamid.HBgMMjU0NzQxNTkwMzMwFQIAERgSNEFDNjVDOTM1NTBDQjU0OTgzAA==', None, 'user_initiated', True, 'CBP', 0)]
(Background on this error at: https://sqlalche.me/e/14/gkpj)
2023-01-26 10:37:12,795 - log - ERROR - (sqlite3.IntegrityError) UNIQUE constraint failed: incoming_request.message_id
[SQL: INSERT INTO incoming_request (status, timestamp, recipient_id, conversation_id, message_id, expiration_timestamp, origin, billable, pricing_model, processed) VALUES (?, ?, ?, ?, ?, ?, ?, ?, ?, ?)]
[parameters: ('delivered', '1674656515', '254741590330', 'e8b7de634b650e9149030d9c6c01fe97', 'wamid.HBgMMjU0NzQxNTkwMzMwFQIAERgSMjRFMEU0QzlCQ0MxRTc1RDJBAA==', None, 'user_initiated', True, 'CBP', 0)]
(Background on this error at: https://sqlalche.me/e/14/gkpj)
Traceback (most recent call last):
  File "/home/newton/elarian/virtual/lib/python3.8/site-packages/sqlalchemy/engine/base.py", line 1900, in _execute_context
    self.dialect.do_execute(
  File "/home/newton/elarian/virtual/lib/python3.8/site-packages/sqlalchemy/engine/default.py", line 736, in do_execute
    cursor.execute(statement, parameters)
sqlite3.IntegrityError: UNIQUE constraint failed: incoming_request.message_id

The above exception was the direct cause of the following exception:

Traceback (most recent call last):
  File "application.py", line 76, in save_request
    db.session.commit()
  File "<string>", line 2, in commit
  File "/home/newton/elarian/virtual/lib/python3.8/site-packages/sqlalchemy/orm/session.py", line 1451, in commit
    self._transaction.commit(_to_root=self.future)
  File "/home/newton/elarian/virtual/lib/python3.8/site-packages/sqlalchemy/orm/session.py", line 829, in commit
    self._prepare_impl()
  File "/home/newton/elarian/virtual/lib/python3.8/site-packages/sqlalchemy/orm/session.py", line 808, in _prepare_impl
    self.session.flush()
  File "/home/newton/elarian/virtual/lib/python3.8/site-packages/sqlalchemy/orm/session.py", line 3444, in flush
    self._flush(objects)
  File "/home/newton/elarian/virtual/lib/python3.8/site-packages/sqlalchemy/orm/session.py", line 3584, in _flush
    transaction.rollback(_capture_exception=True)
  File "/home/newton/elarian/virtual/lib/python3.8/site-packages/sqlalchemy/util/langhelpers.py", line 70, in __exit__
    compat.raise_(
  File "/home/newton/elarian/virtual/lib/python3.8/site-packages/sqlalchemy/util/compat.py", line 211, in raise_
    raise exception
  File "/home/newton/elarian/virtual/lib/python3.8/site-packages/sqlalchemy/orm/session.py", line 3544, in _flush
    flush_context.execute()
  File "/home/newton/elarian/virtual/lib/python3.8/site-packages/sqlalchemy/orm/unitofwork.py", line 456, in execute
    rec.execute(self)
  File "/home/newton/elarian/virtual/lib/python3.8/site-packages/sqlalchemy/orm/unitofwork.py", line 630, in execute
    util.preloaded.orm_persistence.save_obj(
  File "/home/newton/elarian/virtual/lib/python3.8/site-packages/sqlalchemy/orm/persistence.py", line 245, in save_obj
    _emit_insert_statements(
  File "/home/newton/elarian/virtual/lib/python3.8/site-packages/sqlalchemy/orm/persistence.py", line 1238, in _emit_insert_statements
    result = connection._execute_20(
  File "/home/newton/elarian/virtual/lib/python3.8/site-packages/sqlalchemy/engine/base.py", line 1705, in _execute_20
    return meth(self, args_10style, kwargs_10style, execution_options)
  File "/home/newton/elarian/virtual/lib/python3.8/site-packages/sqlalchemy/sql/elements.py", line 334, in _execute_on_connection
    return connection._execute_clauseelement(
  File "/home/newton/elarian/virtual/lib/python3.8/site-packages/sqlalchemy/engine/base.py", line 1572, in _execute_clauseelement
    ret = self._execute_context(
  File "/home/newton/elarian/virtual/lib/python3.8/site-packages/sqlalchemy/engine/base.py", line 1943, in _execute_context
    self._handle_dbapi_exception(
  File "/home/newton/elarian/virtual/lib/python3.8/site-packages/sqlalchemy/engine/base.py", line 2124, in _handle_dbapi_exception
    util.raise_(
  File "/home/newton/elarian/virtual/lib/python3.8/site-packages/sqlalchemy/util/compat.py", line 211, in raise_
    raise exception
  File "/home/newton/elarian/virtual/lib/python3.8/site-packages/sqlalchemy/engine/base.py", line 1900, in _execute_context
    self.dialect.do_execute(
  File "/home/newton/elarian/virtual/lib/python3.8/site-packages/sqlalchemy/engine/default.py", line 736, in do_execute
    cursor.execute(statement, parameters)
sqlalchemy.exc.IntegrityError: (sqlite3.IntegrityError) UNIQUE constraint failed: incoming_request.message_id
[SQL: INSERT INTO incoming_request (status, timestamp, recipient_id, conversation_id, message_id, expiration_timestamp, origin, billable, pricing_model, processed) VALUES (?, ?, ?, ?, ?, ?, ?, ?, ?, ?)]
[parameters: ('delivered', '1674656515', '254741590330', 'e8b7de634b650e9149030d9c6c01fe97', 'wamid.HBgMMjU0NzQxNTkwMzMwFQIAERgSMjRFMEU0QzlCQ0MxRTc1RDJBAA==', None, 'user_initiated', True, 'CBP', 0)]
(Background on this error at: https://sqlalche.me/e/14/gkpj)
2023-01-26 10:45:07,671 - log - ERROR - (sqlite3.IntegrityError) UNIQUE constraint failed: incoming_request.message_id
[SQL: INSERT INTO incoming_request (status, timestamp, recipient_id, conversation_id, message_id, expiration_timestamp, origin, billable, pricing_model, processed) VALUES (?, ?, ?, ?, ?, ?, ?, ?, ?, ?)]
[parameters: ('delivered', '1674657251', '254741590330', 'e8b7de634b650e9149030d9c6c01fe97', 'wamid.HBgMMjU0NzQxNTkwMzMwFQIAERgSNTQwMDkxMDdCN0I5QjUyRUE4AA==', None, 'user_initiated', True, 'CBP', 0)]
(Background on this error at: https://sqlalche.me/e/14/gkpj)
Traceback (most recent call last):
  File "/home/newton/elarian/virtual/lib/python3.8/site-packages/sqlalchemy/engine/base.py", line 1900, in _execute_context
    self.dialect.do_execute(
  File "/home/newton/elarian/virtual/lib/python3.8/site-packages/sqlalchemy/engine/default.py", line 736, in do_execute
    cursor.execute(statement, parameters)
sqlite3.IntegrityError: UNIQUE constraint failed: incoming_request.message_id

The above exception was the direct cause of the following exception:

Traceback (most recent call last):
  File "application.py", line 76, in save_request
    db.session.commit()
  File "<string>", line 2, in commit
  File "/home/newton/elarian/virtual/lib/python3.8/site-packages/sqlalchemy/orm/session.py", line 1451, in commit
    self._transaction.commit(_to_root=self.future)
  File "/home/newton/elarian/virtual/lib/python3.8/site-packages/sqlalchemy/orm/session.py", line 829, in commit
    self._prepare_impl()
  File "/home/newton/elarian/virtual/lib/python3.8/site-packages/sqlalchemy/orm/session.py", line 808, in _prepare_impl
    self.session.flush()
  File "/home/newton/elarian/virtual/lib/python3.8/site-packages/sqlalchemy/orm/session.py", line 3444, in flush
    self._flush(objects)
  File "/home/newton/elarian/virtual/lib/python3.8/site-packages/sqlalchemy/orm/session.py", line 3584, in _flush
    transaction.rollback(_capture_exception=True)
  File "/home/newton/elarian/virtual/lib/python3.8/site-packages/sqlalchemy/util/langhelpers.py", line 70, in __exit__
    compat.raise_(
  File "/home/newton/elarian/virtual/lib/python3.8/site-packages/sqlalchemy/util/compat.py", line 211, in raise_
    raise exception
  File "/home/newton/elarian/virtual/lib/python3.8/site-packages/sqlalchemy/orm/session.py", line 3544, in _flush
    flush_context.execute()
  File "/home/newton/elarian/virtual/lib/python3.8/site-packages/sqlalchemy/orm/unitofwork.py", line 456, in execute
    rec.execute(self)
  File "/home/newton/elarian/virtual/lib/python3.8/site-packages/sqlalchemy/orm/unitofwork.py", line 630, in execute
    util.preloaded.orm_persistence.save_obj(
  File "/home/newton/elarian/virtual/lib/python3.8/site-packages/sqlalchemy/orm/persistence.py", line 245, in save_obj
    _emit_insert_statements(
  File "/home/newton/elarian/virtual/lib/python3.8/site-packages/sqlalchemy/orm/persistence.py", line 1238, in _emit_insert_statements
    result = connection._execute_20(
  File "/home/newton/elarian/virtual/lib/python3.8/site-packages/sqlalchemy/engine/base.py", line 1705, in _execute_20
    return meth(self, args_10style, kwargs_10style, execution_options)
  File "/home/newton/elarian/virtual/lib/python3.8/site-packages/sqlalchemy/sql/elements.py", line 334, in _execute_on_connection
    return connection._execute_clauseelement(
  File "/home/newton/elarian/virtual/lib/python3.8/site-packages/sqlalchemy/engine/base.py", line 1572, in _execute_clauseelement
    ret = self._execute_context(
  File "/home/newton/elarian/virtual/lib/python3.8/site-packages/sqlalchemy/engine/base.py", line 1943, in _execute_context
    self._handle_dbapi_exception(
  File "/home/newton/elarian/virtual/lib/python3.8/site-packages/sqlalchemy/engine/base.py", line 2124, in _handle_dbapi_exception
    util.raise_(
  File "/home/newton/elarian/virtual/lib/python3.8/site-packages/sqlalchemy/util/compat.py", line 211, in raise_
    raise exception
  File "/home/newton/elarian/virtual/lib/python3.8/site-packages/sqlalchemy/engine/base.py", line 1900, in _execute_context
    self.dialect.do_execute(
  File "/home/newton/elarian/virtual/lib/python3.8/site-packages/sqlalchemy/engine/default.py", line 736, in do_execute
    cursor.execute(statement, parameters)
sqlalchemy.exc.IntegrityError: (sqlite3.IntegrityError) UNIQUE constraint failed: incoming_request.message_id
[SQL: INSERT INTO incoming_request (status, timestamp, recipient_id, conversation_id, message_id, expiration_timestamp, origin, billable, pricing_model, processed) VALUES (?, ?, ?, ?, ?, ?, ?, ?, ?, ?)]
[parameters: ('delivered', '1674657251', '254741590330', 'e8b7de634b650e9149030d9c6c01fe97', 'wamid.HBgMMjU0NzQxNTkwMzMwFQIAERgSNTQwMDkxMDdCN0I5QjUyRUE4AA==', None, 'user_initiated', True, 'CBP', 0)]
(Background on this error at: https://sqlalche.me/e/14/gkpj)
2023-01-26 10:48:08,554 - log - ERROR - (sqlite3.IntegrityError) UNIQUE constraint failed: incoming_request.message_id
[SQL: INSERT INTO incoming_request (status, timestamp, recipient_id, conversation_id, message_id, expiration_timestamp, origin, billable, pricing_model, processed) VALUES (?, ?, ?, ?, ?, ?, ?, ?, ?, ?)]
[parameters: ('sent', '1674672802', '254741590330', 'e8b7de634b650e9149030d9c6c01fe97', 'wamid.HBgMMjU0NzQxNTkwMzMwFQIAERgSRjcxRENDNEM1QjhFRTkwRjNFAA==', None, 'user_initiated', True, 'CBP', 0)]
(Background on this error at: https://sqlalche.me/e/14/gkpj)
Traceback (most recent call last):
  File "/home/newton/elarian/virtual/lib/python3.8/site-packages/sqlalchemy/engine/base.py", line 1900, in _execute_context
    self.dialect.do_execute(
  File "/home/newton/elarian/virtual/lib/python3.8/site-packages/sqlalchemy/engine/default.py", line 736, in do_execute
    cursor.execute(statement, parameters)
sqlite3.IntegrityError: UNIQUE constraint failed: incoming_request.message_id

The above exception was the direct cause of the following exception:

Traceback (most recent call last):
  File "application.py", line 76, in save_request
    db.session.commit()
  File "<string>", line 2, in commit
  File "/home/newton/elarian/virtual/lib/python3.8/site-packages/sqlalchemy/orm/session.py", line 1451, in commit
    self._transaction.commit(_to_root=self.future)
  File "/home/newton/elarian/virtual/lib/python3.8/site-packages/sqlalchemy/orm/session.py", line 829, in commit
    self._prepare_impl()
  File "/home/newton/elarian/virtual/lib/python3.8/site-packages/sqlalchemy/orm/session.py", line 808, in _prepare_impl
    self.session.flush()
  File "/home/newton/elarian/virtual/lib/python3.8/site-packages/sqlalchemy/orm/session.py", line 3444, in flush
    self._flush(objects)
  File "/home/newton/elarian/virtual/lib/python3.8/site-packages/sqlalchemy/orm/session.py", line 3584, in _flush
    transaction.rollback(_capture_exception=True)
  File "/home/newton/elarian/virtual/lib/python3.8/site-packages/sqlalchemy/util/langhelpers.py", line 70, in __exit__
    compat.raise_(
  File "/home/newton/elarian/virtual/lib/python3.8/site-packages/sqlalchemy/util/compat.py", line 211, in raise_
    raise exception
  File "/home/newton/elarian/virtual/lib/python3.8/site-packages/sqlalchemy/orm/session.py", line 3544, in _flush
    flush_context.execute()
  File "/home/newton/elarian/virtual/lib/python3.8/site-packages/sqlalchemy/orm/unitofwork.py", line 456, in execute
    rec.execute(self)
  File "/home/newton/elarian/virtual/lib/python3.8/site-packages/sqlalchemy/orm/unitofwork.py", line 630, in execute
    util.preloaded.orm_persistence.save_obj(
  File "/home/newton/elarian/virtual/lib/python3.8/site-packages/sqlalchemy/orm/persistence.py", line 245, in save_obj
    _emit_insert_statements(
  File "/home/newton/elarian/virtual/lib/python3.8/site-packages/sqlalchemy/orm/persistence.py", line 1238, in _emit_insert_statements
    result = connection._execute_20(
  File "/home/newton/elarian/virtual/lib/python3.8/site-packages/sqlalchemy/engine/base.py", line 1705, in _execute_20
    return meth(self, args_10style, kwargs_10style, execution_options)
  File "/home/newton/elarian/virtual/lib/python3.8/site-packages/sqlalchemy/sql/elements.py", line 334, in _execute_on_connection
    return connection._execute_clauseelement(
  File "/home/newton/elarian/virtual/lib/python3.8/site-packages/sqlalchemy/engine/base.py", line 1572, in _execute_clauseelement
    ret = self._execute_context(
  File "/home/newton/elarian/virtual/lib/python3.8/site-packages/sqlalchemy/engine/base.py", line 1943, in _execute_context
    self._handle_dbapi_exception(
  File "/home/newton/elarian/virtual/lib/python3.8/site-packages/sqlalchemy/engine/base.py", line 2124, in _handle_dbapi_exception
    util.raise_(
  File "/home/newton/elarian/virtual/lib/python3.8/site-packages/sqlalchemy/util/compat.py", line 211, in raise_
    raise exception
  File "/home/newton/elarian/virtual/lib/python3.8/site-packages/sqlalchemy/engine/base.py", line 1900, in _execute_context
    self.dialect.do_execute(
  File "/home/newton/elarian/virtual/lib/python3.8/site-packages/sqlalchemy/engine/default.py", line 736, in do_execute
    cursor.execute(statement, parameters)
sqlalchemy.exc.IntegrityError: (sqlite3.IntegrityError) UNIQUE constraint failed: incoming_request.message_id
[SQL: INSERT INTO incoming_request (status, timestamp, recipient_id, conversation_id, message_id, expiration_timestamp, origin, billable, pricing_model, processed) VALUES (?, ?, ?, ?, ?, ?, ?, ?, ?, ?)]
[parameters: ('sent', '1674672802', '254741590330', 'e8b7de634b650e9149030d9c6c01fe97', 'wamid.HBgMMjU0NzQxNTkwMzMwFQIAERgSRjcxRENDNEM1QjhFRTkwRjNFAA==', None, 'user_initiated', True, 'CBP', 0)]
(Background on this error at: https://sqlalche.me/e/14/gkpj)
2023-01-26 10:49:12,026 - log - ERROR - (sqlite3.IntegrityError) UNIQUE constraint failed: incoming_request.message_id
[SQL: INSERT INTO incoming_request (status, timestamp, recipient_id, conversation_id, message_id, expiration_timestamp, origin, billable, pricing_model, processed) VALUES (?, ?, ?, ?, ?, ?, ?, ?, ?, ?)]
[parameters: ('delivered', '1674658185', '254741590330', 'e8b7de634b650e9149030d9c6c01fe97', 'wamid.HBgMMjU0NzQxNTkwMzMwFQIAERgSOTI1MDJERkU0RjFFQjdENEM3AA==', None, 'user_initiated', True, 'CBP', 0)]
(Background on this error at: https://sqlalche.me/e/14/gkpj)
Traceback (most recent call last):
  File "/home/newton/elarian/virtual/lib/python3.8/site-packages/sqlalchemy/engine/base.py", line 1900, in _execute_context
    self.dialect.do_execute(
  File "/home/newton/elarian/virtual/lib/python3.8/site-packages/sqlalchemy/engine/default.py", line 736, in do_execute
    cursor.execute(statement, parameters)
sqlite3.IntegrityError: UNIQUE constraint failed: incoming_request.message_id

The above exception was the direct cause of the following exception:

Traceback (most recent call last):
  File "application.py", line 76, in save_request
    db.session.commit()
  File "<string>", line 2, in commit
  File "/home/newton/elarian/virtual/lib/python3.8/site-packages/sqlalchemy/orm/session.py", line 1451, in commit
    self._transaction.commit(_to_root=self.future)
  File "/home/newton/elarian/virtual/lib/python3.8/site-packages/sqlalchemy/orm/session.py", line 829, in commit
    self._prepare_impl()
  File "/home/newton/elarian/virtual/lib/python3.8/site-packages/sqlalchemy/orm/session.py", line 808, in _prepare_impl
    self.session.flush()
  File "/home/newton/elarian/virtual/lib/python3.8/site-packages/sqlalchemy/orm/session.py", line 3444, in flush
    self._flush(objects)
  File "/home/newton/elarian/virtual/lib/python3.8/site-packages/sqlalchemy/orm/session.py", line 3584, in _flush
    transaction.rollback(_capture_exception=True)
  File "/home/newton/elarian/virtual/lib/python3.8/site-packages/sqlalchemy/util/langhelpers.py", line 70, in __exit__
    compat.raise_(
  File "/home/newton/elarian/virtual/lib/python3.8/site-packages/sqlalchemy/util/compat.py", line 211, in raise_
    raise exception
  File "/home/newton/elarian/virtual/lib/python3.8/site-packages/sqlalchemy/orm/session.py", line 3544, in _flush
    flush_context.execute()
  File "/home/newton/elarian/virtual/lib/python3.8/site-packages/sqlalchemy/orm/unitofwork.py", line 456, in execute
    rec.execute(self)
  File "/home/newton/elarian/virtual/lib/python3.8/site-packages/sqlalchemy/orm/unitofwork.py", line 630, in execute
    util.preloaded.orm_persistence.save_obj(
  File "/home/newton/elarian/virtual/lib/python3.8/site-packages/sqlalchemy/orm/persistence.py", line 245, in save_obj
    _emit_insert_statements(
  File "/home/newton/elarian/virtual/lib/python3.8/site-packages/sqlalchemy/orm/persistence.py", line 1238, in _emit_insert_statements
    result = connection._execute_20(
  File "/home/newton/elarian/virtual/lib/python3.8/site-packages/sqlalchemy/engine/base.py", line 1705, in _execute_20
    return meth(self, args_10style, kwargs_10style, execution_options)
  File "/home/newton/elarian/virtual/lib/python3.8/site-packages/sqlalchemy/sql/elements.py", line 334, in _execute_on_connection
    return connection._execute_clauseelement(
  File "/home/newton/elarian/virtual/lib/python3.8/site-packages/sqlalchemy/engine/base.py", line 1572, in _execute_clauseelement
    ret = self._execute_context(
  File "/home/newton/elarian/virtual/lib/python3.8/site-packages/sqlalchemy/engine/base.py", line 1943, in _execute_context
    self._handle_dbapi_exception(
  File "/home/newton/elarian/virtual/lib/python3.8/site-packages/sqlalchemy/engine/base.py", line 2124, in _handle_dbapi_exception
    util.raise_(
  File "/home/newton/elarian/virtual/lib/python3.8/site-packages/sqlalchemy/util/compat.py", line 211, in raise_
    raise exception
  File "/home/newton/elarian/virtual/lib/python3.8/site-packages/sqlalchemy/engine/base.py", line 1900, in _execute_context
    self.dialect.do_execute(
  File "/home/newton/elarian/virtual/lib/python3.8/site-packages/sqlalchemy/engine/default.py", line 736, in do_execute
    cursor.execute(statement, parameters)
sqlalchemy.exc.IntegrityError: (sqlite3.IntegrityError) UNIQUE constraint failed: incoming_request.message_id
[SQL: INSERT INTO incoming_request (status, timestamp, recipient_id, conversation_id, message_id, expiration_timestamp, origin, billable, pricing_model, processed) VALUES (?, ?, ?, ?, ?, ?, ?, ?, ?, ?)]
[parameters: ('delivered', '1674658185', '254741590330', 'e8b7de634b650e9149030d9c6c01fe97', 'wamid.HBgMMjU0NzQxNTkwMzMwFQIAERgSOTI1MDJERkU0RjFFQjdENEM3AA==', None, 'user_initiated', True, 'CBP', 0)]
(Background on this error at: https://sqlalche.me/e/14/gkpj)
2023-01-26 10:51:51,720 - log - ERROR - (sqlite3.IntegrityError) UNIQUE constraint failed: incoming_request.message_id
[SQL: INSERT INTO incoming_request (status, timestamp, recipient_id, conversation_id, message_id, expiration_timestamp, origin, billable, pricing_model, processed) VALUES (?, ?, ?, ?, ?, ?, ?, ?, ?, ?)]
[parameters: ('sent', '1674673505', '254741590330', 'e8b7de634b650e9149030d9c6c01fe97', 'wamid.HBgMMjU0NzQxNTkwMzMwFQIAERgSMTI1MEY0QTUyQzdGRjcyQzA4AA==', None, 'user_initiated', True, 'CBP', 0)]
(Background on this error at: https://sqlalche.me/e/14/gkpj)
Traceback (most recent call last):
  File "/home/newton/elarian/virtual/lib/python3.8/site-packages/sqlalchemy/engine/base.py", line 1900, in _execute_context
    self.dialect.do_execute(
  File "/home/newton/elarian/virtual/lib/python3.8/site-packages/sqlalchemy/engine/default.py", line 736, in do_execute
    cursor.execute(statement, parameters)
sqlite3.IntegrityError: UNIQUE constraint failed: incoming_request.message_id

The above exception was the direct cause of the following exception:

Traceback (most recent call last):
  File "application.py", line 76, in save_request
    db.session.commit()
  File "<string>", line 2, in commit
  File "/home/newton/elarian/virtual/lib/python3.8/site-packages/sqlalchemy/orm/session.py", line 1451, in commit
    self._transaction.commit(_to_root=self.future)
  File "/home/newton/elarian/virtual/lib/python3.8/site-packages/sqlalchemy/orm/session.py", line 829, in commit
    self._prepare_impl()
  File "/home/newton/elarian/virtual/lib/python3.8/site-packages/sqlalchemy/orm/session.py", line 808, in _prepare_impl
    self.session.flush()
  File "/home/newton/elarian/virtual/lib/python3.8/site-packages/sqlalchemy/orm/session.py", line 3444, in flush
    self._flush(objects)
  File "/home/newton/elarian/virtual/lib/python3.8/site-packages/sqlalchemy/orm/session.py", line 3584, in _flush
    transaction.rollback(_capture_exception=True)
  File "/home/newton/elarian/virtual/lib/python3.8/site-packages/sqlalchemy/util/langhelpers.py", line 70, in __exit__
    compat.raise_(
  File "/home/newton/elarian/virtual/lib/python3.8/site-packages/sqlalchemy/util/compat.py", line 211, in raise_
    raise exception
  File "/home/newton/elarian/virtual/lib/python3.8/site-packages/sqlalchemy/orm/session.py", line 3544, in _flush
    flush_context.execute()
  File "/home/newton/elarian/virtual/lib/python3.8/site-packages/sqlalchemy/orm/unitofwork.py", line 456, in execute
    rec.execute(self)
  File "/home/newton/elarian/virtual/lib/python3.8/site-packages/sqlalchemy/orm/unitofwork.py", line 630, in execute
    util.preloaded.orm_persistence.save_obj(
  File "/home/newton/elarian/virtual/lib/python3.8/site-packages/sqlalchemy/orm/persistence.py", line 245, in save_obj
    _emit_insert_statements(
  File "/home/newton/elarian/virtual/lib/python3.8/site-packages/sqlalchemy/orm/persistence.py", line 1238, in _emit_insert_statements
    result = connection._execute_20(
  File "/home/newton/elarian/virtual/lib/python3.8/site-packages/sqlalchemy/engine/base.py", line 1705, in _execute_20
    return meth(self, args_10style, kwargs_10style, execution_options)
  File "/home/newton/elarian/virtual/lib/python3.8/site-packages/sqlalchemy/sql/elements.py", line 334, in _execute_on_connection
    return connection._execute_clauseelement(
  File "/home/newton/elarian/virtual/lib/python3.8/site-packages/sqlalchemy/engine/base.py", line 1572, in _execute_clauseelement
    ret = self._execute_context(
  File "/home/newton/elarian/virtual/lib/python3.8/site-packages/sqlalchemy/engine/base.py", line 1943, in _execute_context
    self._handle_dbapi_exception(
  File "/home/newton/elarian/virtual/lib/python3.8/site-packages/sqlalchemy/engine/base.py", line 2124, in _handle_dbapi_exception
    util.raise_(
  File "/home/newton/elarian/virtual/lib/python3.8/site-packages/sqlalchemy/util/compat.py", line 211, in raise_
    raise exception
  File "/home/newton/elarian/virtual/lib/python3.8/site-packages/sqlalchemy/engine/base.py", line 1900, in _execute_context
    self.dialect.do_execute(
  File "/home/newton/elarian/virtual/lib/python3.8/site-packages/sqlalchemy/engine/default.py", line 736, in do_execute
    cursor.execute(statement, parameters)
sqlalchemy.exc.IntegrityError: (sqlite3.IntegrityError) UNIQUE constraint failed: incoming_request.message_id
[SQL: INSERT INTO incoming_request (status, timestamp, recipient_id, conversation_id, message_id, expiration_timestamp, origin, billable, pricing_model, processed) VALUES (?, ?, ?, ?, ?, ?, ?, ?, ?, ?)]
[parameters: ('sent', '1674673505', '254741590330', 'e8b7de634b650e9149030d9c6c01fe97', 'wamid.HBgMMjU0NzQxNTkwMzMwFQIAERgSMTI1MEY0QTUyQzdGRjcyQzA4AA==', None, 'user_initiated', True, 'CBP', 0)]
(Background on this error at: https://sqlalche.me/e/14/gkpj)
2023-01-26 10:52:27,410 - log - ERROR - (sqlite3.IntegrityError) UNIQUE constraint failed: incoming_request.message_id
[SQL: INSERT INTO incoming_request (status, timestamp, recipient_id, conversation_id, message_id, expiration_timestamp, origin, billable, pricing_model, processed) VALUES (?, ?, ?, ?, ?, ?, ?, ?, ?, ?)]
[parameters: ('sent', '1674673188', '254741590330', 'e8b7de634b650e9149030d9c6c01fe97', 'wamid.HBgMMjU0NzQxNTkwMzMwFQIAERgSM0NCMTdEQkFBQzgxREQxRDZDAA==', None, 'user_initiated', True, 'CBP', 0)]
(Background on this error at: https://sqlalche.me/e/14/gkpj)
Traceback (most recent call last):
  File "/home/newton/elarian/virtual/lib/python3.8/site-packages/sqlalchemy/engine/base.py", line 1900, in _execute_context
    self.dialect.do_execute(
  File "/home/newton/elarian/virtual/lib/python3.8/site-packages/sqlalchemy/engine/default.py", line 736, in do_execute
    cursor.execute(statement, parameters)
sqlite3.IntegrityError: UNIQUE constraint failed: incoming_request.message_id

The above exception was the direct cause of the following exception:

Traceback (most recent call last):
  File "application.py", line 76, in save_request
    db.session.commit()
  File "<string>", line 2, in commit
  File "/home/newton/elarian/virtual/lib/python3.8/site-packages/sqlalchemy/orm/session.py", line 1451, in commit
    self._transaction.commit(_to_root=self.future)
  File "/home/newton/elarian/virtual/lib/python3.8/site-packages/sqlalchemy/orm/session.py", line 829, in commit
    self._prepare_impl()
  File "/home/newton/elarian/virtual/lib/python3.8/site-packages/sqlalchemy/orm/session.py", line 808, in _prepare_impl
    self.session.flush()
  File "/home/newton/elarian/virtual/lib/python3.8/site-packages/sqlalchemy/orm/session.py", line 3444, in flush
    self._flush(objects)
  File "/home/newton/elarian/virtual/lib/python3.8/site-packages/sqlalchemy/orm/session.py", line 3584, in _flush
    transaction.rollback(_capture_exception=True)
  File "/home/newton/elarian/virtual/lib/python3.8/site-packages/sqlalchemy/util/langhelpers.py", line 70, in __exit__
    compat.raise_(
  File "/home/newton/elarian/virtual/lib/python3.8/site-packages/sqlalchemy/util/compat.py", line 211, in raise_
    raise exception
  File "/home/newton/elarian/virtual/lib/python3.8/site-packages/sqlalchemy/orm/session.py", line 3544, in _flush
    flush_context.execute()
  File "/home/newton/elarian/virtual/lib/python3.8/site-packages/sqlalchemy/orm/unitofwork.py", line 456, in execute
    rec.execute(self)
  File "/home/newton/elarian/virtual/lib/python3.8/site-packages/sqlalchemy/orm/unitofwork.py", line 630, in execute
    util.preloaded.orm_persistence.save_obj(
  File "/home/newton/elarian/virtual/lib/python3.8/site-packages/sqlalchemy/orm/persistence.py", line 245, in save_obj
    _emit_insert_statements(
  File "/home/newton/elarian/virtual/lib/python3.8/site-packages/sqlalchemy/orm/persistence.py", line 1238, in _emit_insert_statements
    result = connection._execute_20(
  File "/home/newton/elarian/virtual/lib/python3.8/site-packages/sqlalchemy/engine/base.py", line 1705, in _execute_20
    return meth(self, args_10style, kwargs_10style, execution_options)
  File "/home/newton/elarian/virtual/lib/python3.8/site-packages/sqlalchemy/sql/elements.py", line 334, in _execute_on_connection
    return connection._execute_clauseelement(
  File "/home/newton/elarian/virtual/lib/python3.8/site-packages/sqlalchemy/engine/base.py", line 1572, in _execute_clauseelement
    ret = self._execute_context(
  File "/home/newton/elarian/virtual/lib/python3.8/site-packages/sqlalchemy/engine/base.py", line 1943, in _execute_context
    self._handle_dbapi_exception(
  File "/home/newton/elarian/virtual/lib/python3.8/site-packages/sqlalchemy/engine/base.py", line 2124, in _handle_dbapi_exception
    util.raise_(
  File "/home/newton/elarian/virtual/lib/python3.8/site-packages/sqlalchemy/util/compat.py", line 211, in raise_
    raise exception
  File "/home/newton/elarian/virtual/lib/python3.8/site-packages/sqlalchemy/engine/base.py", line 1900, in _execute_context
    self.dialect.do_execute(
  File "/home/newton/elarian/virtual/lib/python3.8/site-packages/sqlalchemy/engine/default.py", line 736, in do_execute
    cursor.execute(statement, parameters)
sqlalchemy.exc.IntegrityError: (sqlite3.IntegrityError) UNIQUE constraint failed: incoming_request.message_id
[SQL: INSERT INTO incoming_request (status, timestamp, recipient_id, conversation_id, message_id, expiration_timestamp, origin, billable, pricing_model, processed) VALUES (?, ?, ?, ?, ?, ?, ?, ?, ?, ?)]
[parameters: ('sent', '1674673188', '254741590330', 'e8b7de634b650e9149030d9c6c01fe97', 'wamid.HBgMMjU0NzQxNTkwMzMwFQIAERgSM0NCMTdEQkFBQzgxREQxRDZDAA==', None, 'user_initiated', True, 'CBP', 0)]
(Background on this error at: https://sqlalche.me/e/14/gkpj)
2023-01-26 10:52:30,542 - log - ERROR - (sqlite3.IntegrityError) UNIQUE constraint failed: incoming_request.message_id
[SQL: INSERT INTO incoming_request (status, timestamp, recipient_id, conversation_id, message_id, expiration_timestamp, origin, billable, pricing_model, processed) VALUES (?, ?, ?, ?, ?, ?, ?, ?, ?, ?)]
[parameters: ('delivered', '1674673186', '254741590330', 'e8b7de634b650e9149030d9c6c01fe97', 'wamid.HBgMMjU0NzQxNTkwMzMwFQIAERgSMDUzRDUzNzgxQTQyQ0Q1OTQ2AA==', None, 'user_initiated', True, 'CBP', 0)]
(Background on this error at: https://sqlalche.me/e/14/gkpj)
Traceback (most recent call last):
  File "/home/newton/elarian/virtual/lib/python3.8/site-packages/sqlalchemy/engine/base.py", line 1900, in _execute_context
    self.dialect.do_execute(
  File "/home/newton/elarian/virtual/lib/python3.8/site-packages/sqlalchemy/engine/default.py", line 736, in do_execute
    cursor.execute(statement, parameters)
sqlite3.IntegrityError: UNIQUE constraint failed: incoming_request.message_id

The above exception was the direct cause of the following exception:

Traceback (most recent call last):
  File "application.py", line 76, in save_request
    db.session.commit()
  File "<string>", line 2, in commit
  File "/home/newton/elarian/virtual/lib/python3.8/site-packages/sqlalchemy/orm/session.py", line 1451, in commit
    self._transaction.commit(_to_root=self.future)
  File "/home/newton/elarian/virtual/lib/python3.8/site-packages/sqlalchemy/orm/session.py", line 829, in commit
    self._prepare_impl()
  File "/home/newton/elarian/virtual/lib/python3.8/site-packages/sqlalchemy/orm/session.py", line 808, in _prepare_impl
    self.session.flush()
  File "/home/newton/elarian/virtual/lib/python3.8/site-packages/sqlalchemy/orm/session.py", line 3444, in flush
    self._flush(objects)
  File "/home/newton/elarian/virtual/lib/python3.8/site-packages/sqlalchemy/orm/session.py", line 3584, in _flush
    transaction.rollback(_capture_exception=True)
  File "/home/newton/elarian/virtual/lib/python3.8/site-packages/sqlalchemy/util/langhelpers.py", line 70, in __exit__
    compat.raise_(
  File "/home/newton/elarian/virtual/lib/python3.8/site-packages/sqlalchemy/util/compat.py", line 211, in raise_
    raise exception
  File "/home/newton/elarian/virtual/lib/python3.8/site-packages/sqlalchemy/orm/session.py", line 3544, in _flush
    flush_context.execute()
  File "/home/newton/elarian/virtual/lib/python3.8/site-packages/sqlalchemy/orm/unitofwork.py", line 456, in execute
    rec.execute(self)
  File "/home/newton/elarian/virtual/lib/python3.8/site-packages/sqlalchemy/orm/unitofwork.py", line 630, in execute
    util.preloaded.orm_persistence.save_obj(
  File "/home/newton/elarian/virtual/lib/python3.8/site-packages/sqlalchemy/orm/persistence.py", line 245, in save_obj
    _emit_insert_statements(
  File "/home/newton/elarian/virtual/lib/python3.8/site-packages/sqlalchemy/orm/persistence.py", line 1238, in _emit_insert_statements
    result = connection._execute_20(
  File "/home/newton/elarian/virtual/lib/python3.8/site-packages/sqlalchemy/engine/base.py", line 1705, in _execute_20
    return meth(self, args_10style, kwargs_10style, execution_options)
  File "/home/newton/elarian/virtual/lib/python3.8/site-packages/sqlalchemy/sql/elements.py", line 334, in _execute_on_connection
    return connection._execute_clauseelement(
  File "/home/newton/elarian/virtual/lib/python3.8/site-packages/sqlalchemy/engine/base.py", line 1572, in _execute_clauseelement
    ret = self._execute_context(
  File "/home/newton/elarian/virtual/lib/python3.8/site-packages/sqlalchemy/engine/base.py", line 1943, in _execute_context
    self._handle_dbapi_exception(
  File "/home/newton/elarian/virtual/lib/python3.8/site-packages/sqlalchemy/engine/base.py", line 2124, in _handle_dbapi_exception
    util.raise_(
  File "/home/newton/elarian/virtual/lib/python3.8/site-packages/sqlalchemy/util/compat.py", line 211, in raise_
    raise exception
  File "/home/newton/elarian/virtual/lib/python3.8/site-packages/sqlalchemy/engine/base.py", line 1900, in _execute_context
    self.dialect.do_execute(
  File "/home/newton/elarian/virtual/lib/python3.8/site-packages/sqlalchemy/engine/default.py", line 736, in do_execute
    cursor.execute(statement, parameters)
sqlalchemy.exc.IntegrityError: (sqlite3.IntegrityError) UNIQUE constraint failed: incoming_request.message_id
[SQL: INSERT INTO incoming_request (status, timestamp, recipient_id, conversation_id, message_id, expiration_timestamp, origin, billable, pricing_model, processed) VALUES (?, ?, ?, ?, ?, ?, ?, ?, ?, ?)]
[parameters: ('delivered', '1674673186', '254741590330', 'e8b7de634b650e9149030d9c6c01fe97', 'wamid.HBgMMjU0NzQxNTkwMzMwFQIAERgSMDUzRDUzNzgxQTQyQ0Q1OTQ2AA==', None, 'user_initiated', True, 'CBP', 0)]
(Background on this error at: https://sqlalche.me/e/14/gkpj)
2023-01-26 10:52:55,624 - log - ERROR - (sqlite3.IntegrityError) UNIQUE constraint failed: incoming_request.message_id
[SQL: INSERT INTO incoming_request (status, timestamp, recipient_id, conversation_id, message_id, expiration_timestamp, origin, billable, pricing_model, processed) VALUES (?, ?, ?, ?, ?, ?, ?, ?, ?, ?)]
[parameters: ('delivered', '1674672775', '254741590330', 'e8b7de634b650e9149030d9c6c01fe97', 'wamid.HBgMMjU0NzQxNTkwMzMwFQIAERgSNEI2QTdBQjA2NEE2QzhGQzYwAA==', None, 'user_initiated', True, 'CBP', 0)]
(Background on this error at: https://sqlalche.me/e/14/gkpj)
Traceback (most recent call last):
  File "/home/newton/elarian/virtual/lib/python3.8/site-packages/sqlalchemy/engine/base.py", line 1900, in _execute_context
    self.dialect.do_execute(
  File "/home/newton/elarian/virtual/lib/python3.8/site-packages/sqlalchemy/engine/default.py", line 736, in do_execute
    cursor.execute(statement, parameters)
sqlite3.IntegrityError: UNIQUE constraint failed: incoming_request.message_id

The above exception was the direct cause of the following exception:

Traceback (most recent call last):
  File "application.py", line 76, in save_request
    db.session.commit()
  File "<string>", line 2, in commit
  File "/home/newton/elarian/virtual/lib/python3.8/site-packages/sqlalchemy/orm/session.py", line 1451, in commit
    self._transaction.commit(_to_root=self.future)
  File "/home/newton/elarian/virtual/lib/python3.8/site-packages/sqlalchemy/orm/session.py", line 829, in commit
    self._prepare_impl()
  File "/home/newton/elarian/virtual/lib/python3.8/site-packages/sqlalchemy/orm/session.py", line 808, in _prepare_impl
    self.session.flush()
  File "/home/newton/elarian/virtual/lib/python3.8/site-packages/sqlalchemy/orm/session.py", line 3444, in flush
    self._flush(objects)
  File "/home/newton/elarian/virtual/lib/python3.8/site-packages/sqlalchemy/orm/session.py", line 3584, in _flush
    transaction.rollback(_capture_exception=True)
  File "/home/newton/elarian/virtual/lib/python3.8/site-packages/sqlalchemy/util/langhelpers.py", line 70, in __exit__
    compat.raise_(
  File "/home/newton/elarian/virtual/lib/python3.8/site-packages/sqlalchemy/util/compat.py", line 211, in raise_
    raise exception
  File "/home/newton/elarian/virtual/lib/python3.8/site-packages/sqlalchemy/orm/session.py", line 3544, in _flush
    flush_context.execute()
  File "/home/newton/elarian/virtual/lib/python3.8/site-packages/sqlalchemy/orm/unitofwork.py", line 456, in execute
    rec.execute(self)
  File "/home/newton/elarian/virtual/lib/python3.8/site-packages/sqlalchemy/orm/unitofwork.py", line 630, in execute
    util.preloaded.orm_persistence.save_obj(
  File "/home/newton/elarian/virtual/lib/python3.8/site-packages/sqlalchemy/orm/persistence.py", line 245, in save_obj
    _emit_insert_statements(
  File "/home/newton/elarian/virtual/lib/python3.8/site-packages/sqlalchemy/orm/persistence.py", line 1238, in _emit_insert_statements
    result = connection._execute_20(
  File "/home/newton/elarian/virtual/lib/python3.8/site-packages/sqlalchemy/engine/base.py", line 1705, in _execute_20
    return meth(self, args_10style, kwargs_10style, execution_options)
  File "/home/newton/elarian/virtual/lib/python3.8/site-packages/sqlalchemy/sql/elements.py", line 334, in _execute_on_connection
    return connection._execute_clauseelement(
  File "/home/newton/elarian/virtual/lib/python3.8/site-packages/sqlalchemy/engine/base.py", line 1572, in _execute_clauseelement
    ret = self._execute_context(
  File "/home/newton/elarian/virtual/lib/python3.8/site-packages/sqlalchemy/engine/base.py", line 1943, in _execute_context
    self._handle_dbapi_exception(
  File "/home/newton/elarian/virtual/lib/python3.8/site-packages/sqlalchemy/engine/base.py", line 2124, in _handle_dbapi_exception
    util.raise_(
  File "/home/newton/elarian/virtual/lib/python3.8/site-packages/sqlalchemy/util/compat.py", line 211, in raise_
    raise exception
  File "/home/newton/elarian/virtual/lib/python3.8/site-packages/sqlalchemy/engine/base.py", line 1900, in _execute_context
    self.dialect.do_execute(
  File "/home/newton/elarian/virtual/lib/python3.8/site-packages/sqlalchemy/engine/default.py", line 736, in do_execute
    cursor.execute(statement, parameters)
sqlalchemy.exc.IntegrityError: (sqlite3.IntegrityError) UNIQUE constraint failed: incoming_request.message_id
[SQL: INSERT INTO incoming_request (status, timestamp, recipient_id, conversation_id, message_id, expiration_timestamp, origin, billable, pricing_model, processed) VALUES (?, ?, ?, ?, ?, ?, ?, ?, ?, ?)]
[parameters: ('delivered', '1674672775', '254741590330', 'e8b7de634b650e9149030d9c6c01fe97', 'wamid.HBgMMjU0NzQxNTkwMzMwFQIAERgSNEI2QTdBQjA2NEE2QzhGQzYwAA==', None, 'user_initiated', True, 'CBP', 0)]
(Background on this error at: https://sqlalche.me/e/14/gkpj)
2023-01-26 10:53:08,997 - log - ERROR - (sqlite3.IntegrityError) UNIQUE constraint failed: incoming_request.message_id
[SQL: INSERT INTO incoming_request (status, timestamp, recipient_id, conversation_id, message_id, expiration_timestamp, origin, billable, pricing_model, processed) VALUES (?, ?, ?, ?, ?, ?, ?, ?, ?, ?)]
[parameters: ('delivered', '1674673663', '254741590330', 'e8b7de634b650e9149030d9c6c01fe97', 'wamid.HBgMMjU0NzQxNTkwMzMwFQIAERgSQzBBNkFCRTBDNzE0NTE3QkU1AA==', None, 'user_initiated', True, 'CBP', 0)]
(Background on this error at: https://sqlalche.me/e/14/gkpj)
Traceback (most recent call last):
  File "/home/newton/elarian/virtual/lib/python3.8/site-packages/sqlalchemy/engine/base.py", line 1900, in _execute_context
    self.dialect.do_execute(
  File "/home/newton/elarian/virtual/lib/python3.8/site-packages/sqlalchemy/engine/default.py", line 736, in do_execute
    cursor.execute(statement, parameters)
sqlite3.IntegrityError: UNIQUE constraint failed: incoming_request.message_id

The above exception was the direct cause of the following exception:

Traceback (most recent call last):
  File "application.py", line 76, in save_request
    db.session.commit()
  File "<string>", line 2, in commit
  File "/home/newton/elarian/virtual/lib/python3.8/site-packages/sqlalchemy/orm/session.py", line 1451, in commit
    self._transaction.commit(_to_root=self.future)
  File "/home/newton/elarian/virtual/lib/python3.8/site-packages/sqlalchemy/orm/session.py", line 829, in commit
    self._prepare_impl()
  File "/home/newton/elarian/virtual/lib/python3.8/site-packages/sqlalchemy/orm/session.py", line 808, in _prepare_impl
    self.session.flush()
  File "/home/newton/elarian/virtual/lib/python3.8/site-packages/sqlalchemy/orm/session.py", line 3444, in flush
    self._flush(objects)
  File "/home/newton/elarian/virtual/lib/python3.8/site-packages/sqlalchemy/orm/session.py", line 3584, in _flush
    transaction.rollback(_capture_exception=True)
  File "/home/newton/elarian/virtual/lib/python3.8/site-packages/sqlalchemy/util/langhelpers.py", line 70, in __exit__
    compat.raise_(
  File "/home/newton/elarian/virtual/lib/python3.8/site-packages/sqlalchemy/util/compat.py", line 211, in raise_
    raise exception
  File "/home/newton/elarian/virtual/lib/python3.8/site-packages/sqlalchemy/orm/session.py", line 3544, in _flush
    flush_context.execute()
  File "/home/newton/elarian/virtual/lib/python3.8/site-packages/sqlalchemy/orm/unitofwork.py", line 456, in execute
    rec.execute(self)
  File "/home/newton/elarian/virtual/lib/python3.8/site-packages/sqlalchemy/orm/unitofwork.py", line 630, in execute
    util.preloaded.orm_persistence.save_obj(
  File "/home/newton/elarian/virtual/lib/python3.8/site-packages/sqlalchemy/orm/persistence.py", line 245, in save_obj
    _emit_insert_statements(
  File "/home/newton/elarian/virtual/lib/python3.8/site-packages/sqlalchemy/orm/persistence.py", line 1238, in _emit_insert_statements
    result = connection._execute_20(
  File "/home/newton/elarian/virtual/lib/python3.8/site-packages/sqlalchemy/engine/base.py", line 1705, in _execute_20
    return meth(self, args_10style, kwargs_10style, execution_options)
  File "/home/newton/elarian/virtual/lib/python3.8/site-packages/sqlalchemy/sql/elements.py", line 334, in _execute_on_connection
    return connection._execute_clauseelement(
  File "/home/newton/elarian/virtual/lib/python3.8/site-packages/sqlalchemy/engine/base.py", line 1572, in _execute_clauseelement
    ret = self._execute_context(
  File "/home/newton/elarian/virtual/lib/python3.8/site-packages/sqlalchemy/engine/base.py", line 1943, in _execute_context
    self._handle_dbapi_exception(
  File "/home/newton/elarian/virtual/lib/python3.8/site-packages/sqlalchemy/engine/base.py", line 2124, in _handle_dbapi_exception
    util.raise_(
  File "/home/newton/elarian/virtual/lib/python3.8/site-packages/sqlalchemy/util/compat.py", line 211, in raise_
    raise exception
  File "/home/newton/elarian/virtual/lib/python3.8/site-packages/sqlalchemy/engine/base.py", line 1900, in _execute_context
    self.dialect.do_execute(
  File "/home/newton/elarian/virtual/lib/python3.8/site-packages/sqlalchemy/engine/default.py", line 736, in do_execute
    cursor.execute(statement, parameters)
sqlalchemy.exc.IntegrityError: (sqlite3.IntegrityError) UNIQUE constraint failed: incoming_request.message_id
[SQL: INSERT INTO incoming_request (status, timestamp, recipient_id, conversation_id, message_id, expiration_timestamp, origin, billable, pricing_model, processed) VALUES (?, ?, ?, ?, ?, ?, ?, ?, ?, ?)]
[parameters: ('delivered', '1674673663', '254741590330', 'e8b7de634b650e9149030d9c6c01fe97', 'wamid.HBgMMjU0NzQxNTkwMzMwFQIAERgSQzBBNkFCRTBDNzE0NTE3QkU1AA==', None, 'user_initiated', True, 'CBP', 0)]
(Background on this error at: https://sqlalche.me/e/14/gkpj)
2023-01-26 10:53:34,488 - log - ERROR - (sqlite3.IntegrityError) UNIQUE constraint failed: incoming_request.message_id
[SQL: INSERT INTO incoming_request (status, timestamp, recipient_id, conversation_id, message_id, expiration_timestamp, origin, billable, pricing_model, processed) VALUES (?, ?, ?, ?, ?, ?, ?, ?, ?, ?)]
[parameters: ('delivered', '1674673681', '254741590330', 'e8b7de634b650e9149030d9c6c01fe97', 'wamid.HBgMMjU0NzQxNTkwMzMwFQIAERgSRDJCRUM5N0ZDQzY0RTJGODEzAA==', None, 'user_initiated', True, 'CBP', 0)]
(Background on this error at: https://sqlalche.me/e/14/gkpj)
Traceback (most recent call last):
  File "/home/newton/elarian/virtual/lib/python3.8/site-packages/sqlalchemy/engine/base.py", line 1900, in _execute_context
    self.dialect.do_execute(
  File "/home/newton/elarian/virtual/lib/python3.8/site-packages/sqlalchemy/engine/default.py", line 736, in do_execute
    cursor.execute(statement, parameters)
sqlite3.IntegrityError: UNIQUE constraint failed: incoming_request.message_id

The above exception was the direct cause of the following exception:

Traceback (most recent call last):
  File "application.py", line 76, in save_request
    db.session.commit()
  File "<string>", line 2, in commit
  File "/home/newton/elarian/virtual/lib/python3.8/site-packages/sqlalchemy/orm/session.py", line 1451, in commit
    self._transaction.commit(_to_root=self.future)
  File "/home/newton/elarian/virtual/lib/python3.8/site-packages/sqlalchemy/orm/session.py", line 829, in commit
    self._prepare_impl()
  File "/home/newton/elarian/virtual/lib/python3.8/site-packages/sqlalchemy/orm/session.py", line 808, in _prepare_impl
    self.session.flush()
  File "/home/newton/elarian/virtual/lib/python3.8/site-packages/sqlalchemy/orm/session.py", line 3444, in flush
    self._flush(objects)
  File "/home/newton/elarian/virtual/lib/python3.8/site-packages/sqlalchemy/orm/session.py", line 3584, in _flush
    transaction.rollback(_capture_exception=True)
  File "/home/newton/elarian/virtual/lib/python3.8/site-packages/sqlalchemy/util/langhelpers.py", line 70, in __exit__
    compat.raise_(
  File "/home/newton/elarian/virtual/lib/python3.8/site-packages/sqlalchemy/util/compat.py", line 211, in raise_
    raise exception
  File "/home/newton/elarian/virtual/lib/python3.8/site-packages/sqlalchemy/orm/session.py", line 3544, in _flush
    flush_context.execute()
  File "/home/newton/elarian/virtual/lib/python3.8/site-packages/sqlalchemy/orm/unitofwork.py", line 456, in execute
    rec.execute(self)
  File "/home/newton/elarian/virtual/lib/python3.8/site-packages/sqlalchemy/orm/unitofwork.py", line 630, in execute
    util.preloaded.orm_persistence.save_obj(
  File "/home/newton/elarian/virtual/lib/python3.8/site-packages/sqlalchemy/orm/persistence.py", line 245, in save_obj
    _emit_insert_statements(
  File "/home/newton/elarian/virtual/lib/python3.8/site-packages/sqlalchemy/orm/persistence.py", line 1238, in _emit_insert_statements
    result = connection._execute_20(
  File "/home/newton/elarian/virtual/lib/python3.8/site-packages/sqlalchemy/engine/base.py", line 1705, in _execute_20
    return meth(self, args_10style, kwargs_10style, execution_options)
  File "/home/newton/elarian/virtual/lib/python3.8/site-packages/sqlalchemy/sql/elements.py", line 334, in _execute_on_connection
    return connection._execute_clauseelement(
  File "/home/newton/elarian/virtual/lib/python3.8/site-packages/sqlalchemy/engine/base.py", line 1572, in _execute_clauseelement
    ret = self._execute_context(
  File "/home/newton/elarian/virtual/lib/python3.8/site-packages/sqlalchemy/engine/base.py", line 1943, in _execute_context
    self._handle_dbapi_exception(
  File "/home/newton/elarian/virtual/lib/python3.8/site-packages/sqlalchemy/engine/base.py", line 2124, in _handle_dbapi_exception
    util.raise_(
  File "/home/newton/elarian/virtual/lib/python3.8/site-packages/sqlalchemy/util/compat.py", line 211, in raise_
    raise exception
  File "/home/newton/elarian/virtual/lib/python3.8/site-packages/sqlalchemy/engine/base.py", line 1900, in _execute_context
    self.dialect.do_execute(
  File "/home/newton/elarian/virtual/lib/python3.8/site-packages/sqlalchemy/engine/default.py", line 736, in do_execute
    cursor.execute(statement, parameters)
sqlalchemy.exc.IntegrityError: (sqlite3.IntegrityError) UNIQUE constraint failed: incoming_request.message_id
[SQL: INSERT INTO incoming_request (status, timestamp, recipient_id, conversation_id, message_id, expiration_timestamp, origin, billable, pricing_model, processed) VALUES (?, ?, ?, ?, ?, ?, ?, ?, ?, ?)]
[parameters: ('delivered', '1674673681', '254741590330', 'e8b7de634b650e9149030d9c6c01fe97', 'wamid.HBgMMjU0NzQxNTkwMzMwFQIAERgSRDJCRUM5N0ZDQzY0RTJGODEzAA==', None, 'user_initiated', True, 'CBP', 0)]
(Background on this error at: https://sqlalche.me/e/14/gkpj)
2023-01-26 10:53:52,816 - log - ERROR - (sqlite3.IntegrityError) UNIQUE constraint failed: incoming_request.message_id
[SQL: INSERT INTO incoming_request (status, timestamp, recipient_id, conversation_id, message_id, expiration_timestamp, origin, billable, pricing_model, processed) VALUES (?, ?, ?, ?, ?, ?, ?, ?, ?, ?)]
[parameters: ('delivered', '1674657105', '254741590330', 'e8b7de634b650e9149030d9c6c01fe97', 'wamid.HBgMMjU0NzQxNTkwMzMwFQIAERgSRjYyQUU2QTg4QTI2RkMxRjU0AA==', None, 'user_initiated', True, 'CBP', 0)]
(Background on this error at: https://sqlalche.me/e/14/gkpj)
Traceback (most recent call last):
  File "/home/newton/elarian/virtual/lib/python3.8/site-packages/sqlalchemy/engine/base.py", line 1900, in _execute_context
    self.dialect.do_execute(
  File "/home/newton/elarian/virtual/lib/python3.8/site-packages/sqlalchemy/engine/default.py", line 736, in do_execute
    cursor.execute(statement, parameters)
sqlite3.IntegrityError: UNIQUE constraint failed: incoming_request.message_id

The above exception was the direct cause of the following exception:

Traceback (most recent call last):
  File "application.py", line 76, in save_request
    db.session.commit()
  File "<string>", line 2, in commit
  File "/home/newton/elarian/virtual/lib/python3.8/site-packages/sqlalchemy/orm/session.py", line 1451, in commit
    self._transaction.commit(_to_root=self.future)
  File "/home/newton/elarian/virtual/lib/python3.8/site-packages/sqlalchemy/orm/session.py", line 829, in commit
    self._prepare_impl()
  File "/home/newton/elarian/virtual/lib/python3.8/site-packages/sqlalchemy/orm/session.py", line 808, in _prepare_impl
    self.session.flush()
  File "/home/newton/elarian/virtual/lib/python3.8/site-packages/sqlalchemy/orm/session.py", line 3444, in flush
    self._flush(objects)
  File "/home/newton/elarian/virtual/lib/python3.8/site-packages/sqlalchemy/orm/session.py", line 3584, in _flush
    transaction.rollback(_capture_exception=True)
  File "/home/newton/elarian/virtual/lib/python3.8/site-packages/sqlalchemy/util/langhelpers.py", line 70, in __exit__
    compat.raise_(
  File "/home/newton/elarian/virtual/lib/python3.8/site-packages/sqlalchemy/util/compat.py", line 211, in raise_
    raise exception
  File "/home/newton/elarian/virtual/lib/python3.8/site-packages/sqlalchemy/orm/session.py", line 3544, in _flush
    flush_context.execute()
  File "/home/newton/elarian/virtual/lib/python3.8/site-packages/sqlalchemy/orm/unitofwork.py", line 456, in execute
    rec.execute(self)
  File "/home/newton/elarian/virtual/lib/python3.8/site-packages/sqlalchemy/orm/unitofwork.py", line 630, in execute
    util.preloaded.orm_persistence.save_obj(
  File "/home/newton/elarian/virtual/lib/python3.8/site-packages/sqlalchemy/orm/persistence.py", line 245, in save_obj
    _emit_insert_statements(
  File "/home/newton/elarian/virtual/lib/python3.8/site-packages/sqlalchemy/orm/persistence.py", line 1238, in _emit_insert_statements
    result = connection._execute_20(
  File "/home/newton/elarian/virtual/lib/python3.8/site-packages/sqlalchemy/engine/base.py", line 1705, in _execute_20
    return meth(self, args_10style, kwargs_10style, execution_options)
  File "/home/newton/elarian/virtual/lib/python3.8/site-packages/sqlalchemy/sql/elements.py", line 334, in _execute_on_connection
    return connection._execute_clauseelement(
  File "/home/newton/elarian/virtual/lib/python3.8/site-packages/sqlalchemy/engine/base.py", line 1572, in _execute_clauseelement
    ret = self._execute_context(
  File "/home/newton/elarian/virtual/lib/python3.8/site-packages/sqlalchemy/engine/base.py", line 1943, in _execute_context
    self._handle_dbapi_exception(
  File "/home/newton/elarian/virtual/lib/python3.8/site-packages/sqlalchemy/engine/base.py", line 2124, in _handle_dbapi_exception
    util.raise_(
  File "/home/newton/elarian/virtual/lib/python3.8/site-packages/sqlalchemy/util/compat.py", line 211, in raise_
    raise exception
  File "/home/newton/elarian/virtual/lib/python3.8/site-packages/sqlalchemy/engine/base.py", line 1900, in _execute_context
    self.dialect.do_execute(
  File "/home/newton/elarian/virtual/lib/python3.8/site-packages/sqlalchemy/engine/default.py", line 736, in do_execute
    cursor.execute(statement, parameters)
sqlalchemy.exc.IntegrityError: (sqlite3.IntegrityError) UNIQUE constraint failed: incoming_request.message_id
[SQL: INSERT INTO incoming_request (status, timestamp, recipient_id, conversation_id, message_id, expiration_timestamp, origin, billable, pricing_model, processed) VALUES (?, ?, ?, ?, ?, ?, ?, ?, ?, ?)]
[parameters: ('delivered', '1674657105', '254741590330', 'e8b7de634b650e9149030d9c6c01fe97', 'wamid.HBgMMjU0NzQxNTkwMzMwFQIAERgSRjYyQUU2QTg4QTI2RkMxRjU0AA==', None, 'user_initiated', True, 'CBP', 0)]
(Background on this error at: https://sqlalche.me/e/14/gkpj)
2023-01-26 10:53:53,815 - log - ERROR - (sqlite3.IntegrityError) UNIQUE constraint failed: incoming_request.message_id
[SQL: INSERT INTO incoming_request (status, timestamp, recipient_id, conversation_id, message_id, expiration_timestamp, origin, billable, pricing_model, processed) VALUES (?, ?, ?, ?, ?, ?, ?, ?, ?, ?)]
[parameters: ('sent', '1674673496', '254741590330', 'e8b7de634b650e9149030d9c6c01fe97', 'wamid.HBgMMjU0NzQxNTkwMzMwFQIAERgSRkQyRDJCQTREMkNBODMyQTJGAA==', None, 'user_initiated', True, 'CBP', 0)]
(Background on this error at: https://sqlalche.me/e/14/gkpj)
Traceback (most recent call last):
  File "/home/newton/elarian/virtual/lib/python3.8/site-packages/sqlalchemy/engine/base.py", line 1900, in _execute_context
    self.dialect.do_execute(
  File "/home/newton/elarian/virtual/lib/python3.8/site-packages/sqlalchemy/engine/default.py", line 736, in do_execute
    cursor.execute(statement, parameters)
sqlite3.IntegrityError: UNIQUE constraint failed: incoming_request.message_id

The above exception was the direct cause of the following exception:

Traceback (most recent call last):
  File "application.py", line 76, in save_request
    db.session.commit()
  File "<string>", line 2, in commit
  File "/home/newton/elarian/virtual/lib/python3.8/site-packages/sqlalchemy/orm/session.py", line 1451, in commit
    self._transaction.commit(_to_root=self.future)
  File "/home/newton/elarian/virtual/lib/python3.8/site-packages/sqlalchemy/orm/session.py", line 829, in commit
    self._prepare_impl()
  File "/home/newton/elarian/virtual/lib/python3.8/site-packages/sqlalchemy/orm/session.py", line 808, in _prepare_impl
    self.session.flush()
  File "/home/newton/elarian/virtual/lib/python3.8/site-packages/sqlalchemy/orm/session.py", line 3444, in flush
    self._flush(objects)
  File "/home/newton/elarian/virtual/lib/python3.8/site-packages/sqlalchemy/orm/session.py", line 3584, in _flush
    transaction.rollback(_capture_exception=True)
  File "/home/newton/elarian/virtual/lib/python3.8/site-packages/sqlalchemy/util/langhelpers.py", line 70, in __exit__
    compat.raise_(
  File "/home/newton/elarian/virtual/lib/python3.8/site-packages/sqlalchemy/util/compat.py", line 211, in raise_
    raise exception
  File "/home/newton/elarian/virtual/lib/python3.8/site-packages/sqlalchemy/orm/session.py", line 3544, in _flush
    flush_context.execute()
  File "/home/newton/elarian/virtual/lib/python3.8/site-packages/sqlalchemy/orm/unitofwork.py", line 456, in execute
    rec.execute(self)
  File "/home/newton/elarian/virtual/lib/python3.8/site-packages/sqlalchemy/orm/unitofwork.py", line 630, in execute
    util.preloaded.orm_persistence.save_obj(
  File "/home/newton/elarian/virtual/lib/python3.8/site-packages/sqlalchemy/orm/persistence.py", line 245, in save_obj
    _emit_insert_statements(
  File "/home/newton/elarian/virtual/lib/python3.8/site-packages/sqlalchemy/orm/persistence.py", line 1238, in _emit_insert_statements
    result = connection._execute_20(
  File "/home/newton/elarian/virtual/lib/python3.8/site-packages/sqlalchemy/engine/base.py", line 1705, in _execute_20
    return meth(self, args_10style, kwargs_10style, execution_options)
  File "/home/newton/elarian/virtual/lib/python3.8/site-packages/sqlalchemy/sql/elements.py", line 334, in _execute_on_connection
    return connection._execute_clauseelement(
  File "/home/newton/elarian/virtual/lib/python3.8/site-packages/sqlalchemy/engine/base.py", line 1572, in _execute_clauseelement
    ret = self._execute_context(
  File "/home/newton/elarian/virtual/lib/python3.8/site-packages/sqlalchemy/engine/base.py", line 1943, in _execute_context
    self._handle_dbapi_exception(
  File "/home/newton/elarian/virtual/lib/python3.8/site-packages/sqlalchemy/engine/base.py", line 2124, in _handle_dbapi_exception
    util.raise_(
  File "/home/newton/elarian/virtual/lib/python3.8/site-packages/sqlalchemy/util/compat.py", line 211, in raise_
    raise exception
  File "/home/newton/elarian/virtual/lib/python3.8/site-packages/sqlalchemy/engine/base.py", line 1900, in _execute_context
    self.dialect.do_execute(
  File "/home/newton/elarian/virtual/lib/python3.8/site-packages/sqlalchemy/engine/default.py", line 736, in do_execute
    cursor.execute(statement, parameters)
sqlalchemy.exc.IntegrityError: (sqlite3.IntegrityError) UNIQUE constraint failed: incoming_request.message_id
[SQL: INSERT INTO incoming_request (status, timestamp, recipient_id, conversation_id, message_id, expiration_timestamp, origin, billable, pricing_model, processed) VALUES (?, ?, ?, ?, ?, ?, ?, ?, ?, ?)]
[parameters: ('sent', '1674673496', '254741590330', 'e8b7de634b650e9149030d9c6c01fe97', 'wamid.HBgMMjU0NzQxNTkwMzMwFQIAERgSRkQyRDJCQTREMkNBODMyQTJGAA==', None, 'user_initiated', True, 'CBP', 0)]
(Background on this error at: https://sqlalche.me/e/14/gkpj)
2023-01-26 10:54:10,773 - log - ERROR - (sqlite3.IntegrityError) UNIQUE constraint failed: incoming_request.message_id
[SQL: INSERT INTO incoming_request (status, timestamp, recipient_id, conversation_id, message_id, expiration_timestamp, origin, billable, pricing_model, processed) VALUES (?, ?, ?, ?, ?, ?, ?, ?, ?, ?)]
[parameters: ('read', '1674673207', '254741590330', 'e8b7de634b650e9149030d9c6c01fe97', 'wamid.HBgMMjU0NzQxNTkwMzMwFQIAERgSNUI0QjlCMUQ3NzFDMjdEMzFBAA==', None, 'user_initiated', True, 'CBP', 0)]
(Background on this error at: https://sqlalche.me/e/14/gkpj)
Traceback (most recent call last):
  File "/home/newton/elarian/virtual/lib/python3.8/site-packages/sqlalchemy/engine/base.py", line 1900, in _execute_context
    self.dialect.do_execute(
  File "/home/newton/elarian/virtual/lib/python3.8/site-packages/sqlalchemy/engine/default.py", line 736, in do_execute
    cursor.execute(statement, parameters)
sqlite3.IntegrityError: UNIQUE constraint failed: incoming_request.message_id

The above exception was the direct cause of the following exception:

Traceback (most recent call last):
  File "application.py", line 76, in save_request
    db.session.commit()
  File "<string>", line 2, in commit
  File "/home/newton/elarian/virtual/lib/python3.8/site-packages/sqlalchemy/orm/session.py", line 1451, in commit
    self._transaction.commit(_to_root=self.future)
  File "/home/newton/elarian/virtual/lib/python3.8/site-packages/sqlalchemy/orm/session.py", line 829, in commit
    self._prepare_impl()
  File "/home/newton/elarian/virtual/lib/python3.8/site-packages/sqlalchemy/orm/session.py", line 808, in _prepare_impl
    self.session.flush()
  File "/home/newton/elarian/virtual/lib/python3.8/site-packages/sqlalchemy/orm/session.py", line 3444, in flush
    self._flush(objects)
  File "/home/newton/elarian/virtual/lib/python3.8/site-packages/sqlalchemy/orm/session.py", line 3584, in _flush
    transaction.rollback(_capture_exception=True)
  File "/home/newton/elarian/virtual/lib/python3.8/site-packages/sqlalchemy/util/langhelpers.py", line 70, in __exit__
    compat.raise_(
  File "/home/newton/elarian/virtual/lib/python3.8/site-packages/sqlalchemy/util/compat.py", line 211, in raise_
    raise exception
  File "/home/newton/elarian/virtual/lib/python3.8/site-packages/sqlalchemy/orm/session.py", line 3544, in _flush
    flush_context.execute()
  File "/home/newton/elarian/virtual/lib/python3.8/site-packages/sqlalchemy/orm/unitofwork.py", line 456, in execute
    rec.execute(self)
  File "/home/newton/elarian/virtual/lib/python3.8/site-packages/sqlalchemy/orm/unitofwork.py", line 630, in execute
    util.preloaded.orm_persistence.save_obj(
  File "/home/newton/elarian/virtual/lib/python3.8/site-packages/sqlalchemy/orm/persistence.py", line 245, in save_obj
    _emit_insert_statements(
  File "/home/newton/elarian/virtual/lib/python3.8/site-packages/sqlalchemy/orm/persistence.py", line 1238, in _emit_insert_statements
    result = connection._execute_20(
  File "/home/newton/elarian/virtual/lib/python3.8/site-packages/sqlalchemy/engine/base.py", line 1705, in _execute_20
    return meth(self, args_10style, kwargs_10style, execution_options)
  File "/home/newton/elarian/virtual/lib/python3.8/site-packages/sqlalchemy/sql/elements.py", line 334, in _execute_on_connection
    return connection._execute_clauseelement(
  File "/home/newton/elarian/virtual/lib/python3.8/site-packages/sqlalchemy/engine/base.py", line 1572, in _execute_clauseelement
    ret = self._execute_context(
  File "/home/newton/elarian/virtual/lib/python3.8/site-packages/sqlalchemy/engine/base.py", line 1943, in _execute_context
    self._handle_dbapi_exception(
  File "/home/newton/elarian/virtual/lib/python3.8/site-packages/sqlalchemy/engine/base.py", line 2124, in _handle_dbapi_exception
    util.raise_(
  File "/home/newton/elarian/virtual/lib/python3.8/site-packages/sqlalchemy/util/compat.py", line 211, in raise_
    raise exception
  File "/home/newton/elarian/virtual/lib/python3.8/site-packages/sqlalchemy/engine/base.py", line 1900, in _execute_context
    self.dialect.do_execute(
  File "/home/newton/elarian/virtual/lib/python3.8/site-packages/sqlalchemy/engine/default.py", line 736, in do_execute
    cursor.execute(statement, parameters)
sqlalchemy.exc.IntegrityError: (sqlite3.IntegrityError) UNIQUE constraint failed: incoming_request.message_id
[SQL: INSERT INTO incoming_request (status, timestamp, recipient_id, conversation_id, message_id, expiration_timestamp, origin, billable, pricing_model, processed) VALUES (?, ?, ?, ?, ?, ?, ?, ?, ?, ?)]
[parameters: ('read', '1674673207', '254741590330', 'e8b7de634b650e9149030d9c6c01fe97', 'wamid.HBgMMjU0NzQxNTkwMzMwFQIAERgSNUI0QjlCMUQ3NzFDMjdEMzFBAA==', None, 'user_initiated', True, 'CBP', 0)]
(Background on this error at: https://sqlalche.me/e/14/gkpj)
2023-01-26 10:54:40,816 - log - ERROR - (sqlite3.IntegrityError) UNIQUE constraint failed: incoming_request.message_id
[SQL: INSERT INTO incoming_request (status, timestamp, recipient_id, conversation_id, message_id, expiration_timestamp, origin, billable, pricing_model, processed) VALUES (?, ?, ?, ?, ?, ?, ?, ?, ?, ?)]
[parameters: ('sent', '1674657102', '254741590330', 'e8b7de634b650e9149030d9c6c01fe97', 'wamid.HBgMMjU0NzQxNTkwMzMwFQIAERgSNjNGRUNDNThFRDQyMUM1NDRFAA==', None, 'user_initiated', True, 'CBP', 0)]
(Background on this error at: https://sqlalche.me/e/14/gkpj)
Traceback (most recent call last):
  File "/home/newton/elarian/virtual/lib/python3.8/site-packages/sqlalchemy/engine/base.py", line 1900, in _execute_context
    self.dialect.do_execute(
  File "/home/newton/elarian/virtual/lib/python3.8/site-packages/sqlalchemy/engine/default.py", line 736, in do_execute
    cursor.execute(statement, parameters)
sqlite3.IntegrityError: UNIQUE constraint failed: incoming_request.message_id

The above exception was the direct cause of the following exception:

Traceback (most recent call last):
  File "application.py", line 76, in save_request
    db.session.commit()
  File "<string>", line 2, in commit
  File "/home/newton/elarian/virtual/lib/python3.8/site-packages/sqlalchemy/orm/session.py", line 1451, in commit
    self._transaction.commit(_to_root=self.future)
  File "/home/newton/elarian/virtual/lib/python3.8/site-packages/sqlalchemy/orm/session.py", line 829, in commit
    self._prepare_impl()
  File "/home/newton/elarian/virtual/lib/python3.8/site-packages/sqlalchemy/orm/session.py", line 808, in _prepare_impl
    self.session.flush()
  File "/home/newton/elarian/virtual/lib/python3.8/site-packages/sqlalchemy/orm/session.py", line 3444, in flush
    self._flush(objects)
  File "/home/newton/elarian/virtual/lib/python3.8/site-packages/sqlalchemy/orm/session.py", line 3584, in _flush
    transaction.rollback(_capture_exception=True)
  File "/home/newton/elarian/virtual/lib/python3.8/site-packages/sqlalchemy/util/langhelpers.py", line 70, in __exit__
    compat.raise_(
  File "/home/newton/elarian/virtual/lib/python3.8/site-packages/sqlalchemy/util/compat.py", line 211, in raise_
    raise exception
  File "/home/newton/elarian/virtual/lib/python3.8/site-packages/sqlalchemy/orm/session.py", line 3544, in _flush
    flush_context.execute()
  File "/home/newton/elarian/virtual/lib/python3.8/site-packages/sqlalchemy/orm/unitofwork.py", line 456, in execute
    rec.execute(self)
  File "/home/newton/elarian/virtual/lib/python3.8/site-packages/sqlalchemy/orm/unitofwork.py", line 630, in execute
    util.preloaded.orm_persistence.save_obj(
  File "/home/newton/elarian/virtual/lib/python3.8/site-packages/sqlalchemy/orm/persistence.py", line 245, in save_obj
    _emit_insert_statements(
  File "/home/newton/elarian/virtual/lib/python3.8/site-packages/sqlalchemy/orm/persistence.py", line 1238, in _emit_insert_statements
    result = connection._execute_20(
  File "/home/newton/elarian/virtual/lib/python3.8/site-packages/sqlalchemy/engine/base.py", line 1705, in _execute_20
    return meth(self, args_10style, kwargs_10style, execution_options)
  File "/home/newton/elarian/virtual/lib/python3.8/site-packages/sqlalchemy/sql/elements.py", line 334, in _execute_on_connection
    return connection._execute_clauseelement(
  File "/home/newton/elarian/virtual/lib/python3.8/site-packages/sqlalchemy/engine/base.py", line 1572, in _execute_clauseelement
    ret = self._execute_context(
  File "/home/newton/elarian/virtual/lib/python3.8/site-packages/sqlalchemy/engine/base.py", line 1943, in _execute_context
    self._handle_dbapi_exception(
  File "/home/newton/elarian/virtual/lib/python3.8/site-packages/sqlalchemy/engine/base.py", line 2124, in _handle_dbapi_exception
    util.raise_(
  File "/home/newton/elarian/virtual/lib/python3.8/site-packages/sqlalchemy/util/compat.py", line 211, in raise_
    raise exception
  File "/home/newton/elarian/virtual/lib/python3.8/site-packages/sqlalchemy/engine/base.py", line 1900, in _execute_context
    self.dialect.do_execute(
  File "/home/newton/elarian/virtual/lib/python3.8/site-packages/sqlalchemy/engine/default.py", line 736, in do_execute
    cursor.execute(statement, parameters)
sqlalchemy.exc.IntegrityError: (sqlite3.IntegrityError) UNIQUE constraint failed: incoming_request.message_id
[SQL: INSERT INTO incoming_request (status, timestamp, recipient_id, conversation_id, message_id, expiration_timestamp, origin, billable, pricing_model, processed) VALUES (?, ?, ?, ?, ?, ?, ?, ?, ?, ?)]
[parameters: ('sent', '1674657102', '254741590330', 'e8b7de634b650e9149030d9c6c01fe97', 'wamid.HBgMMjU0NzQxNTkwMzMwFQIAERgSNjNGRUNDNThFRDQyMUM1NDRFAA==', None, 'user_initiated', True, 'CBP', 0)]
(Background on this error at: https://sqlalche.me/e/14/gkpj)
2023-01-26 10:54:52,024 - log - ERROR - (sqlite3.IntegrityError) UNIQUE constraint failed: incoming_request.message_id
[SQL: INSERT INTO incoming_request (status, timestamp, recipient_id, conversation_id, message_id, expiration_timestamp, origin, billable, pricing_model, processed) VALUES (?, ?, ?, ?, ?, ?, ?, ?, ?, ?)]
[parameters: ('sent', '1674673006', '254741590330', 'e8b7de634b650e9149030d9c6c01fe97', 'wamid.HBgMMjU0NzQxNTkwMzMwFQIAERgSMTU0RTc0NEUwOTFBNTQyOEMwAA==', None, 'user_initiated', True, 'CBP', 0)]
(Background on this error at: https://sqlalche.me/e/14/gkpj)
Traceback (most recent call last):
  File "/home/newton/elarian/virtual/lib/python3.8/site-packages/sqlalchemy/engine/base.py", line 1900, in _execute_context
    self.dialect.do_execute(
  File "/home/newton/elarian/virtual/lib/python3.8/site-packages/sqlalchemy/engine/default.py", line 736, in do_execute
    cursor.execute(statement, parameters)
sqlite3.IntegrityError: UNIQUE constraint failed: incoming_request.message_id

The above exception was the direct cause of the following exception:

Traceback (most recent call last):
  File "application.py", line 76, in save_request
    db.session.commit()
  File "<string>", line 2, in commit
  File "/home/newton/elarian/virtual/lib/python3.8/site-packages/sqlalchemy/orm/session.py", line 1451, in commit
    self._transaction.commit(_to_root=self.future)
  File "/home/newton/elarian/virtual/lib/python3.8/site-packages/sqlalchemy/orm/session.py", line 829, in commit
    self._prepare_impl()
  File "/home/newton/elarian/virtual/lib/python3.8/site-packages/sqlalchemy/orm/session.py", line 808, in _prepare_impl
    self.session.flush()
  File "/home/newton/elarian/virtual/lib/python3.8/site-packages/sqlalchemy/orm/session.py", line 3444, in flush
    self._flush(objects)
  File "/home/newton/elarian/virtual/lib/python3.8/site-packages/sqlalchemy/orm/session.py", line 3584, in _flush
    transaction.rollback(_capture_exception=True)
  File "/home/newton/elarian/virtual/lib/python3.8/site-packages/sqlalchemy/util/langhelpers.py", line 70, in __exit__
    compat.raise_(
  File "/home/newton/elarian/virtual/lib/python3.8/site-packages/sqlalchemy/util/compat.py", line 211, in raise_
    raise exception
  File "/home/newton/elarian/virtual/lib/python3.8/site-packages/sqlalchemy/orm/session.py", line 3544, in _flush
    flush_context.execute()
  File "/home/newton/elarian/virtual/lib/python3.8/site-packages/sqlalchemy/orm/unitofwork.py", line 456, in execute
    rec.execute(self)
  File "/home/newton/elarian/virtual/lib/python3.8/site-packages/sqlalchemy/orm/unitofwork.py", line 630, in execute
    util.preloaded.orm_persistence.save_obj(
  File "/home/newton/elarian/virtual/lib/python3.8/site-packages/sqlalchemy/orm/persistence.py", line 245, in save_obj
    _emit_insert_statements(
  File "/home/newton/elarian/virtual/lib/python3.8/site-packages/sqlalchemy/orm/persistence.py", line 1238, in _emit_insert_statements
    result = connection._execute_20(
  File "/home/newton/elarian/virtual/lib/python3.8/site-packages/sqlalchemy/engine/base.py", line 1705, in _execute_20
    return meth(self, args_10style, kwargs_10style, execution_options)
  File "/home/newton/elarian/virtual/lib/python3.8/site-packages/sqlalchemy/sql/elements.py", line 334, in _execute_on_connection
    return connection._execute_clauseelement(
  File "/home/newton/elarian/virtual/lib/python3.8/site-packages/sqlalchemy/engine/base.py", line 1572, in _execute_clauseelement
    ret = self._execute_context(
  File "/home/newton/elarian/virtual/lib/python3.8/site-packages/sqlalchemy/engine/base.py", line 1943, in _execute_context
    self._handle_dbapi_exception(
  File "/home/newton/elarian/virtual/lib/python3.8/site-packages/sqlalchemy/engine/base.py", line 2124, in _handle_dbapi_exception
    util.raise_(
  File "/home/newton/elarian/virtual/lib/python3.8/site-packages/sqlalchemy/util/compat.py", line 211, in raise_
    raise exception
  File "/home/newton/elarian/virtual/lib/python3.8/site-packages/sqlalchemy/engine/base.py", line 1900, in _execute_context
    self.dialect.do_execute(
  File "/home/newton/elarian/virtual/lib/python3.8/site-packages/sqlalchemy/engine/default.py", line 736, in do_execute
    cursor.execute(statement, parameters)
sqlalchemy.exc.IntegrityError: (sqlite3.IntegrityError) UNIQUE constraint failed: incoming_request.message_id
[SQL: INSERT INTO incoming_request (status, timestamp, recipient_id, conversation_id, message_id, expiration_timestamp, origin, billable, pricing_model, processed) VALUES (?, ?, ?, ?, ?, ?, ?, ?, ?, ?)]
[parameters: ('sent', '1674673006', '254741590330', 'e8b7de634b650e9149030d9c6c01fe97', 'wamid.HBgMMjU0NzQxNTkwMzMwFQIAERgSMTU0RTc0NEUwOTFBNTQyOEMwAA==', None, 'user_initiated', True, 'CBP', 0)]
(Background on this error at: https://sqlalche.me/e/14/gkpj)
2023-01-26 10:55:11,007 - log - ERROR - (sqlite3.IntegrityError) UNIQUE constraint failed: incoming_request.message_id
[SQL: INSERT INTO incoming_request (status, timestamp, recipient_id, conversation_id, message_id, expiration_timestamp, origin, billable, pricing_model, processed) VALUES (?, ?, ?, ?, ?, ?, ?, ?, ?, ?)]
[parameters: ('delivered', '1674658176', '254741590330', 'e8b7de634b650e9149030d9c6c01fe97', 'wamid.HBgMMjU0NzQxNTkwMzMwFQIAERgSNDQxNEFCNkM0N0Y1RTM1Nzg4AA==', None, 'user_initiated', True, 'CBP', 0)]
(Background on this error at: https://sqlalche.me/e/14/gkpj)
Traceback (most recent call last):
  File "/home/newton/elarian/virtual/lib/python3.8/site-packages/sqlalchemy/engine/base.py", line 1900, in _execute_context
    self.dialect.do_execute(
  File "/home/newton/elarian/virtual/lib/python3.8/site-packages/sqlalchemy/engine/default.py", line 736, in do_execute
    cursor.execute(statement, parameters)
sqlite3.IntegrityError: UNIQUE constraint failed: incoming_request.message_id

The above exception was the direct cause of the following exception:

Traceback (most recent call last):
  File "application.py", line 76, in save_request
    db.session.commit()
  File "<string>", line 2, in commit
  File "/home/newton/elarian/virtual/lib/python3.8/site-packages/sqlalchemy/orm/session.py", line 1451, in commit
    self._transaction.commit(_to_root=self.future)
  File "/home/newton/elarian/virtual/lib/python3.8/site-packages/sqlalchemy/orm/session.py", line 829, in commit
    self._prepare_impl()
  File "/home/newton/elarian/virtual/lib/python3.8/site-packages/sqlalchemy/orm/session.py", line 808, in _prepare_impl
    self.session.flush()
  File "/home/newton/elarian/virtual/lib/python3.8/site-packages/sqlalchemy/orm/session.py", line 3444, in flush
    self._flush(objects)
  File "/home/newton/elarian/virtual/lib/python3.8/site-packages/sqlalchemy/orm/session.py", line 3584, in _flush
    transaction.rollback(_capture_exception=True)
  File "/home/newton/elarian/virtual/lib/python3.8/site-packages/sqlalchemy/util/langhelpers.py", line 70, in __exit__
    compat.raise_(
  File "/home/newton/elarian/virtual/lib/python3.8/site-packages/sqlalchemy/util/compat.py", line 211, in raise_
    raise exception
  File "/home/newton/elarian/virtual/lib/python3.8/site-packages/sqlalchemy/orm/session.py", line 3544, in _flush
    flush_context.execute()
  File "/home/newton/elarian/virtual/lib/python3.8/site-packages/sqlalchemy/orm/unitofwork.py", line 456, in execute
    rec.execute(self)
  File "/home/newton/elarian/virtual/lib/python3.8/site-packages/sqlalchemy/orm/unitofwork.py", line 630, in execute
    util.preloaded.orm_persistence.save_obj(
  File "/home/newton/elarian/virtual/lib/python3.8/site-packages/sqlalchemy/orm/persistence.py", line 245, in save_obj
    _emit_insert_statements(
  File "/home/newton/elarian/virtual/lib/python3.8/site-packages/sqlalchemy/orm/persistence.py", line 1238, in _emit_insert_statements
    result = connection._execute_20(
  File "/home/newton/elarian/virtual/lib/python3.8/site-packages/sqlalchemy/engine/base.py", line 1705, in _execute_20
    return meth(self, args_10style, kwargs_10style, execution_options)
  File "/home/newton/elarian/virtual/lib/python3.8/site-packages/sqlalchemy/sql/elements.py", line 334, in _execute_on_connection
    return connection._execute_clauseelement(
  File "/home/newton/elarian/virtual/lib/python3.8/site-packages/sqlalchemy/engine/base.py", line 1572, in _execute_clauseelement
    ret = self._execute_context(
  File "/home/newton/elarian/virtual/lib/python3.8/site-packages/sqlalchemy/engine/base.py", line 1943, in _execute_context
    self._handle_dbapi_exception(
  File "/home/newton/elarian/virtual/lib/python3.8/site-packages/sqlalchemy/engine/base.py", line 2124, in _handle_dbapi_exception
    util.raise_(
  File "/home/newton/elarian/virtual/lib/python3.8/site-packages/sqlalchemy/util/compat.py", line 211, in raise_
    raise exception
  File "/home/newton/elarian/virtual/lib/python3.8/site-packages/sqlalchemy/engine/base.py", line 1900, in _execute_context
    self.dialect.do_execute(
  File "/home/newton/elarian/virtual/lib/python3.8/site-packages/sqlalchemy/engine/default.py", line 736, in do_execute
    cursor.execute(statement, parameters)
sqlalchemy.exc.IntegrityError: (sqlite3.IntegrityError) UNIQUE constraint failed: incoming_request.message_id
[SQL: INSERT INTO incoming_request (status, timestamp, recipient_id, conversation_id, message_id, expiration_timestamp, origin, billable, pricing_model, processed) VALUES (?, ?, ?, ?, ?, ?, ?, ?, ?, ?)]
[parameters: ('delivered', '1674658176', '254741590330', 'e8b7de634b650e9149030d9c6c01fe97', 'wamid.HBgMMjU0NzQxNTkwMzMwFQIAERgSNDQxNEFCNkM0N0Y1RTM1Nzg4AA==', None, 'user_initiated', True, 'CBP', 0)]
(Background on this error at: https://sqlalche.me/e/14/gkpj)
2023-01-26 10:55:17,413 - log - ERROR - (sqlite3.IntegrityError) UNIQUE constraint failed: incoming_request.message_id
[SQL: INSERT INTO incoming_request (status, timestamp, recipient_id, conversation_id, message_id, expiration_timestamp, origin, billable, pricing_model, processed) VALUES (?, ?, ?, ?, ?, ?, ?, ?, ?, ?)]
[parameters: ('sent', '1674673182', '254716434058', 'c1b63a1655a036852a22a89da7fb908a', 'wamid.HBgMMjU0NzE2NDM0MDU4FQIAERgSNTU3QjQwOEE1REY0NDU5MDc3AA==', None, 'user_initiated', True, 'CBP', 0)]
(Background on this error at: https://sqlalche.me/e/14/gkpj)
Traceback (most recent call last):
  File "/home/newton/elarian/virtual/lib/python3.8/site-packages/sqlalchemy/engine/base.py", line 1900, in _execute_context
    self.dialect.do_execute(
  File "/home/newton/elarian/virtual/lib/python3.8/site-packages/sqlalchemy/engine/default.py", line 736, in do_execute
    cursor.execute(statement, parameters)
sqlite3.IntegrityError: UNIQUE constraint failed: incoming_request.message_id

The above exception was the direct cause of the following exception:

Traceback (most recent call last):
  File "application.py", line 76, in save_request
    db.session.commit()
  File "<string>", line 2, in commit
  File "/home/newton/elarian/virtual/lib/python3.8/site-packages/sqlalchemy/orm/session.py", line 1451, in commit
    self._transaction.commit(_to_root=self.future)
  File "/home/newton/elarian/virtual/lib/python3.8/site-packages/sqlalchemy/orm/session.py", line 829, in commit
    self._prepare_impl()
  File "/home/newton/elarian/virtual/lib/python3.8/site-packages/sqlalchemy/orm/session.py", line 808, in _prepare_impl
    self.session.flush()
  File "/home/newton/elarian/virtual/lib/python3.8/site-packages/sqlalchemy/orm/session.py", line 3444, in flush
    self._flush(objects)
  File "/home/newton/elarian/virtual/lib/python3.8/site-packages/sqlalchemy/orm/session.py", line 3584, in _flush
    transaction.rollback(_capture_exception=True)
  File "/home/newton/elarian/virtual/lib/python3.8/site-packages/sqlalchemy/util/langhelpers.py", line 70, in __exit__
    compat.raise_(
  File "/home/newton/elarian/virtual/lib/python3.8/site-packages/sqlalchemy/util/compat.py", line 211, in raise_
    raise exception
  File "/home/newton/elarian/virtual/lib/python3.8/site-packages/sqlalchemy/orm/session.py", line 3544, in _flush
    flush_context.execute()
  File "/home/newton/elarian/virtual/lib/python3.8/site-packages/sqlalchemy/orm/unitofwork.py", line 456, in execute
    rec.execute(self)
  File "/home/newton/elarian/virtual/lib/python3.8/site-packages/sqlalchemy/orm/unitofwork.py", line 630, in execute
    util.preloaded.orm_persistence.save_obj(
  File "/home/newton/elarian/virtual/lib/python3.8/site-packages/sqlalchemy/orm/persistence.py", line 245, in save_obj
    _emit_insert_statements(
  File "/home/newton/elarian/virtual/lib/python3.8/site-packages/sqlalchemy/orm/persistence.py", line 1238, in _emit_insert_statements
    result = connection._execute_20(
  File "/home/newton/elarian/virtual/lib/python3.8/site-packages/sqlalchemy/engine/base.py", line 1705, in _execute_20
    return meth(self, args_10style, kwargs_10style, execution_options)
  File "/home/newton/elarian/virtual/lib/python3.8/site-packages/sqlalchemy/sql/elements.py", line 334, in _execute_on_connection
    return connection._execute_clauseelement(
  File "/home/newton/elarian/virtual/lib/python3.8/site-packages/sqlalchemy/engine/base.py", line 1572, in _execute_clauseelement
    ret = self._execute_context(
  File "/home/newton/elarian/virtual/lib/python3.8/site-packages/sqlalchemy/engine/base.py", line 1943, in _execute_context
    self._handle_dbapi_exception(
  File "/home/newton/elarian/virtual/lib/python3.8/site-packages/sqlalchemy/engine/base.py", line 2124, in _handle_dbapi_exception
    util.raise_(
  File "/home/newton/elarian/virtual/lib/python3.8/site-packages/sqlalchemy/util/compat.py", line 211, in raise_
    raise exception
  File "/home/newton/elarian/virtual/lib/python3.8/site-packages/sqlalchemy/engine/base.py", line 1900, in _execute_context
    self.dialect.do_execute(
  File "/home/newton/elarian/virtual/lib/python3.8/site-packages/sqlalchemy/engine/default.py", line 736, in do_execute
    cursor.execute(statement, parameters)
sqlalchemy.exc.IntegrityError: (sqlite3.IntegrityError) UNIQUE constraint failed: incoming_request.message_id
[SQL: INSERT INTO incoming_request (status, timestamp, recipient_id, conversation_id, message_id, expiration_timestamp, origin, billable, pricing_model, processed) VALUES (?, ?, ?, ?, ?, ?, ?, ?, ?, ?)]
[parameters: ('sent', '1674673182', '254716434058', 'c1b63a1655a036852a22a89da7fb908a', 'wamid.HBgMMjU0NzE2NDM0MDU4FQIAERgSNTU3QjQwOEE1REY0NDU5MDc3AA==', None, 'user_initiated', True, 'CBP', 0)]
(Background on this error at: https://sqlalche.me/e/14/gkpj)
